Workbook
Name Print_Area_MI: #REF!
Name Print_Area_MI: #REF!

Sheet MPR
A2: QUARTERLY REPORT ON TB CASES REGISTRATION
A3: INDIVIDUAL/CONSOLIDATED (TICK ONE) | Y3: TB - 07
A4: Name of TB Care Facility (BMU) : | E4: KMC Leprosy Hospital | I4: District : | K4: West | M4: Central : | O4: Manghopir | T4: Patients registered during | Y4: 1st Quarter | AB4: of Year 2024
A6: Name of TB Coodinator/Facility incharge : | H6: Dr. Hafeez | T6: Date of completion of this form :
A8: Block 1: | K8: New (N) | M8: Relapse ® | O8: Previous Treatment History Unknown (UK) | R8: N+R+UK | U8: Previously treated ( Excluding Relapse) | AB8: Total
A9: All TB Cases Registered | U9: Treatment after failure | X9: Treatment after lost to follow-up | Z9: Other previously treated
A11: Pulmonary, Bacteriologically Confermid | K11: 2 | M11: 0 | O11: 0 | R11: 2 | U11: 0 | X11: 0 | Z11: 1 | AB11: 3
A12: Pulmonary , Clinically Diagnosed | K12: 0 | M12: 0 | O12: 0 | R12: 0 | U12: 0 | X12: 0 | Z12: 0 | AB12: 0
A13: Extra Pulmonary, Bacteriologically Confermid | K13: 0 | M13: 0 | O13: 0 | R13: 0 | U13: 0 | X13: 0 | Z13: 0 | AB13: 0
A14: Extra Pulmonary , Clinically Diagnosed | K14: 1 | M14: 0 | O14: 0 | R14: 1 | U14: 0 | X14: 0 | Z14: 0 | AB14: 1
A15: Total | K15: 3 | M15: 0 | O15: 0 | R15: 3 | U15: 0 | X15: 0 | Z15: 1 | AB15: 4
A16: Block 2: All New, Relapse and previous treatment history unknown Cases registered during the period by Age Group and Gender
K17: 0-4 | M17: 5-14 | O17: 15-24 | Q17: 25-34 | S17: 35-44 | U17: 45-54 | W17: 55-64 | Y17: 65 & Above | AA17: Total | AC17: Grand Total
K18: M | L18: F | M18: M | N18: F | O18: M | P18: F | Q18: M | R18: F | S18: M | T18: F | U18: M | V18: F | W18: M | X18: F | Y18: M | Z18: F | AA18: M | AB18: F
A19: Pulmonary, Bacteriologically Confermid | K19: 0 | L19: 0 | M19: 0 | N19: 0 | O19: 1 | P19: 0 | Q19: 0 | R19: 0 | S19: 0 | T19: 0 | U19: 0 | V19: 0 | W19: 0 | X19: 0 | Y19: 0 | Z19: 1 | AA19: 1 | AB19: 1 | AC19: 2
A20: Pulmonary , Clinically Diagnosed | K20: 0 | L20: 0 | M20: 0 | N20: 0 | O20: 0 | P20: 0 | Q20: 0 | R20: 0 | S20: 0 | T20: 0 | U20: 0 | V20: 0 | W20: 0 | X20: 0 | Y20: 0 | Z20: 0 | AA20: 0 | AB20: 0 | AC20: 0
A21: Extra Pulmonary, Bacteriologically Confermid | K21: 0 | L21: 0 | M21: 0 | N21: 0 | O21: 0 | P21: 0 | Q21: 0 | R21: 0 | S21: 0 | T21: 0 | U21: 0 | V21: 0 | W21: 0 | X21: 0 | Y21: 0 | Z21: 0 | AA21: 0 | AB21: 0 | AC21: 0
A22: Extra Pulmonary , Clinically Diagnosed | K22: 0 | L22: 0 | M22: 0 | N22: 1 | O22: 0 | P22: 0 | Q22: 0 | R22: 0 | S22: 0 | T22: 0 | U22: 0 | V22: 0 | W22: 0 | X22: 0 | Y22: 0 | Z22: 0 | AA22: 0 | AB22: 1 | AC22: 1
A23: Total | K23: 0 | L23: 0 | M23: 0 | N23: 1 | O23: 1 | P23: 0 | Q23: 0 | R23: 0 | S23: 0 | T23: 0 | U23: 0 | V23: 0 | W23: 0 | X23: 0 | Y23: 0 | Z23: 1 | AA23: 1 | AB23: 2 | AC23: 3
A25: Block 3: Presumptive TB Cases Identified Laboratory Diagnosis and use of WRD | N25: Block 4 : TB HIV Activities
A26: Total New OPD in Quarter | B26: No. of presumptive TB cases identified | D26: No. of Presumptive TB Patients tested Using | G26: Among Presumptive TB cases tested number reported B+ | K26: Among all registered number of B+ TB Cases | L26: Amoung All (N+R+UK) number tested by Gene Xpert | N26: No. of TB patients tested for HIV | Q26: TB Patients tested positive for HIV | T26: HIV positive TB Patients put on ART
B27: Total | C27: Through Community Referrals (LHWs) | D27: AFB | E27: Xp & AFB | F27: XP | G27: AFB | H27: AFB + Xpert | I27: Xpert | J27: G.Tot | N27: 0 | Q27: 0 | T27: 0
A28: 2080 | B28: 42 | C28: 0 | D28: 27 | E28: 1 | F28: 0 | G28: 1 | H28: 1 | I28: 1 | J28: 3 | K28: 3 | L28: 2 | N28: HIV patient tested for TB | Q28: HIV patients tested positive for TB | T28: TB positive HIV patients put on TB Tx | X28: HIV positive TB -Ve patients on TPT
N29: 0 | Q29: 0 | T29: 0 | Y29: 0-4 | AA29: 5-14 | AB29: 15 & above
X30: 6H | Y30: 0 | AA30: 0 | AB30: 0
X31: 3HR | Y31: 0 | AA31: 0 | AB31: 0
X32: 3 HP | Y32: 0 | AA32: 0 | AB32: 0
A34: Block 5 : Bacteriologically Confermid TB Cases with DST Result | N34: Block 6 : Contact Tracing HH *
G35: Rifampicin | I35: Isoniazid | K35: Fluoroquninolone | N35: Total No. of HH of B+ PTB | Q35: No. of HH contacts of B+ PTB Cases Screened | T35: Amoung HH contact screened, No. of TB Cases diagnosed | W35: No. of HH Contacts Initiated on TPT | AA35: HIV negative Immuno compromised on TPT
G36: Result | H36: Resistant | I36: Result | J36: Resistant | K36: Result | L36: Resistant | N36: 0-4 | O36: 5-14 | P36: 15 + | Q36: 0-4 | R36: 5-14 | S36: 15 + | T36: 0-4 | U36: 5-14 | V36: 15 + | X36: 0-4 | Y36: 5-14 | Z36: 15+ | AA36: 0-4 | AB36: 5-14 | AC36: 15+
A37: New + UK | G37: 0 | H37: 0 | I37: 0 | J37: 0 | K37: 0 | L37: 0 | N37: 1 | O37: 8 | P37: 0 | Q37: 0 | R37: 0 | S37: 0 | T37: 0 | U37: 0 | V37: 0 | W37: 6H | X37: 0 | Y37: 0 | Z37: 0 | AA37: 0 | AB37: 0 | AC37: 0
A38: Relapse | G38: 0 | H38: 0 | I38: 0 | J38: 0 | K38: 0 | L38: 0 | W38: 3HR | X38: 0 | Y38: 0 | Z38: 0 | AA38: 0 | AB38: 0 | AC38: 0
A39: Previously treated | G39: 0 | H39: 0 | I39: 0 | J39: 0 | K39: 0 | L39: 0 | W39: 3 HP | X39: 0 | Y39: 0 | Z39: 0 | AA39: 0 | AB39: 0 | AC39: 0
A40: Total | G40: 0 | H40: 0 | I40: 0 | J40: 0 | K40: 0 | L40: 0
A41: QUARTERLY REPORT ON TB CASES REGISTRATION
A42: INDIVIDUAL/CONSOLIDATED (TICK ONE) | Y42: TB - 07
A43: Name of TB Care Facility (BMU) : | E43: KMC Leprosy Hospital | I43: District : | K43: West | M43: Central : | O43: Manghopir | T43: Patients registered during | Y43: 2nd Quarter | AB43: of Year 2024
A45: Name of TB Coodinator/Facility incharge : | H45: Dr. Hafeez | T45: Date of completion of this form : | Z45: _______________________
A47: Block 1: | K47: New (N) | M47: Relapse ® | O47: Previous Treatment History Unknown (UK) | R47: N+R+UK | U47: Previously treated ( Excluding Relapse) | AB47: Total
A48: All TB Cases Registered | U48: Treatment after failure | X48: Treatment after lost to follow-up | Z48: Other previously treated
...

Sheet KARACHI
A2: QUARTERLY REPORT ON TB CASES REGISTRATION
A3: INDIVIDUAL/CONSOLIDATED (TICK ONE) | Y3: TB - 07
A4: Name of TB Care Facility (BMU) : | E4: KARACHI CONSOLIDATED | I4: District : | K4: __________________ | M4: Central : | O4: KARACHI | T4: Patients registered during | Y4: 1st Quarter | AB4: of Year 2024
A6: Name of TB Coodinator/Facility incharge : | H6: ___________________________________________________ | T6: Date of completion of this form : | Z6: _______________________
A8: Block 1: | K8: New (N) | M8: Relapse ® | O8: Previous Treatment History Unknown (UK) | R8: N+R+UK | U8: Previously treated ( Excluding Relapse) | AB8: Total
A9: All TB Cases Registered | U9: Treatment after failure | X9: Treatment after lost to follow-up | Z9: Other previously treated
A11: Pulmonary, Bacteriologically Confermid | K11: 124 | M11: 24 | O11: 3 | R11: 151 | U11: 0 | X11: 3 | Z11: 2 | AB11: 156
A12: Pulmonary , Clinically Diagnosed | K12: 139 | M12: 40 | O12: 1 | R12: 180 | U12: 0 | X12: 0 | Z12: 3 | AB12: 183
A13: Extra Pulmonary, Bacteriologically Confermid | K13: 2 | M13: 0 | O13: 0 | R13: 2 | U13: 0 | X13: 0 | Z13: 0 | AB13: 2
A14: Extra Pulmonary , Clinically Diagnosed | K14: 77 | M14: 5 | O14: 1 | R14: 83 | U14: 0 | X14: 0 | Z14: 9 | AB14: 92
A15: Total | K15: 342 | M15: 69 | O15: 5 | R15: 416 | U15: 0 | X15: 3 | Z15: 14 | AB15: 433
A16: Block 2: All New, Relapse and previous treatment history unknown Cases registered during the period by Age Group and Gender
K17: 0-4 | M17: 5-14 | O17: 15-24 | Q17: 25-34 | S17: 35-44 | U17: 45-54 | W17: 55-64 | Y17: 65 & Above | AA17: Total | AC17: Grand Total
K18: M | L18: F | M18: M | N18: F | O18: M | P18: F | Q18: M | R18: F | S18: M | T18: F | U18: M | V18: F | W18: M | X18: F | Y18: M | Z18: F | AA18: M | AB18: F
A19: Pulmonary, Bacteriologically Confermid | K19: 0 | L19: 0 | M19: 3 | N19: 12 | O19: 23 | P19: 24 | Q19: 13 | R19: 13 | S19: 10 | T19: 9 | U19: 12 | V19: 10 | W19: 5 | X19: 7 | Y19: 6 | Z19: 4 | AA19: 72 | AB19: 79 | AC19: 151
A20: Pulmonary , Clinically Diagnosed | K20: 0 | L20: 2 | M20: 4 | N20: 8 | O20: 11 | P20: 33 | Q20: 13 | R20: 27 | S20: 17 | T20: 7 | U20: 13 | V20: 11 | W20: 13 | X20: 6 | Y20: 9 | Z20: 6 | AA20: 80 | AB20: 100 | AC20: 180
A21: Extra Pulmonary, Bacteriologically Confermid | K21: 0 | L21: 0 | M21: 0 | N21: 0 | O21: 0 | P21: 1 | Q21: 0 | R21: 0 | S21: 0 | T21: 1 | U21: 0 | V21: 0 | W21: 0 | X21: 0 | Y21: 0 | Z21: 0 | AA21: 0 | AB21: 2 | AC21: 2
A22: Extra Pulmonary , Clinically Diagnosed | K22: 0 | L22: 0 | M22: 4 | N22: 6 | O22: 7 | P22: 14 | Q22: 7 | R22: 10 | S22: 8 | T22: 11 | U22: 2 | V22: 6 | W22: 2 | X22: 2 | Y22: 4 | Z22: 0 | AA22: 34 | AB22: 49 | AC22: 83
A23: Total | K23: 0 | L23: 2 | M23: 11 | N23: 26 | O23: 41 | P23: 72 | Q23: 33 | R23: 50 | S23: 35 | T23: 28 | U23: 27 | V23: 27 | W23: 20 | X23: 15 | Y23: 19 | Z23: 10 | AA23: 186 | AB23: 230 | AC23: 416
A25: Block 3: Presumptive TB Cases Identified Laboratory Diagnosis and use of WRD | N25: Block 4 : TB HIV Activities
A26: Total New OPD in Quarter | B26: No. of presumptive TB cases identified | D26: No. of Presumptive TB Patients tested Using | G26: Among Presumptive TB cases tested number reported B+ | K26: Among all registered number of B+ TB Cases | L26: Amoung All (N+R+UK) number tested by Gene Xpert | N26: No. of TB patients tested for HIV | Q26: TB Patients tested positive for HIV | T26: HIV positive TB Patients put on ART
B27: Total | C27: Through Community Referrals (LHWs) | D27: AFB | E27: Xp & AFB | F27: XP | G27: AFB | H27: AFB + Xpert | I27: Xpert | J27: G.Tot | N27: 219 | Q27: 3 | T27: 3
A28: 5801 | B28: 982 | C28: 11 | D28: 165 | E28: 385 | F28: 275 | G28: 24 | H28: 52 | I28: 71 | J28: 147 | K28: 135 | L28: 172 | N28: HIV patient tested for TB | Q28: HIV patients tested positive for TB | T28: TB positive HIV patients put on TB Tx | X28: HIV positive TB -Ve patients on TPT
N29: 0 | Q29: 0 | T29: 0 | Y29: 0-4 | AA29: 5-14 | AB29: 15 & above
X30: 6H | Y30: 0 | AA30: 0 | AB30: 0
X31: 3HR | Y31: 0 | AA31: 0 | AB31: 0
X32: 3 HP | Y32: 0 | AA32: 0 | AB32: 0
A34: Block 5 : Bacteriologically Confermid TB Cases with DST Result | N34: Block 6 : Contact Tracing HH *
G35: Rifampicin | I35: Isoniazid | K35: Fluoroquninolone | N35: Total No. of HH of B+ PTB | Q35: No. of HH contacts of B+ PTB Cases Screened | T35: Amoung HH contact screened, No. of TB Cases diagnosed | W35: No. of HH Contacts Initiated on TPT | AA35: HIV negative Immuno compromised on TPT
G36: Result | H36: Resistant | I36: Result | J36: Resistant | K36: Result | L36: Resistant | N36: 0-4 | O36: 5-14 | P36: 15 + | Q36: 0-4 | R36: 5-14 | S36: 15 + | T36: 0-4 | U36: 5-14 | V36: 15 + | X36: 0-4 | Y36: 5-14 | Z36: 15+ | AA36: 0-4 | AB36: 5-14 | AC36: 15+
A37: New + UK | G37: 113 | H37: 1 | I37: 0 | J37: 0 | K37: 0 | L37: 0 | N37: 78 | O37: 151 | P37: 865 | Q37: 28 | R37: 59 | S37: 270 | T37: 1 | U37: 3 | V37: 8 | W37: 6H | X37: 0 | Y37: 8 | Z37: 13 | AA37: 0 | AB37: 0 | AC37: 0
A38: Relapse | G38: 23 | H38: 0 | I38: 0 | J38: 0 | K38: 0 | L38: 0 | W38: 3HR | X38: 0 | Y38: 0 | Z38: 11 | AA38: 0 | AB38: 0 | AC38: 0
A39: Previously treated | G39: 1 | H39: 1 | I39: 0 | J39: 0 | K39: 0 | L39: 0 | W39: 3 HP | X39: 0 | Y39: 8 | Z39: 37 | AA39: 0 | AB39: 0 | AC39: 0
A40: Total | G40: 137 | H40: 2 | I40: 0 | J40: 0 | K40: 0 | L40: 0
A41: QUARTERLY REPORT ON TB CASES REGISTRATION
A42: INDIVIDUAL/CONSOLIDATED (TICK ONE) | Y42: TB - 07
A43: Name of TB Care Facility (BMU) : | E43: KARACHI CONSOLIDATED | I43: District : | K43: __________________ | M43: Central : | O43: ________________ | T43: Patients registered during | Y43: 2nd Quarter | AB43: of Year 2024
A45: Name of TB Coodinator/Facility incharge : | H45: ___________________________________________________ | T45: Date of completion of this form : | Z45: _______________________
A47: Block 1: | K47: New (N) | M47: Relapse ® | O47: Previous Treatment History Unknown (UK) | R47: N+R+UK | U47: Previously treated ( Excluding Relapse) | AB47: Total
A48: All TB Cases Registered | U48: Treatment after failure | X48: Treatment after lost to follow-up | Z48: Other previously treated
...

Sheet SINDH
A2: QUARTERLY REPORT ON TB CASES REGISTRATION
A3: INDIVIDUAL/CONSOLIDATED (TICK ONE) | Y3: TB - 07
A4: Name of TB Care Facility (BMU) : | E4: SINDH CONSOLIDATED | I4: District : | K4: __________________ | M4: Central : | O4: ________________ | T4: Patients registered during | Y4: 1st Quarter | AB4: of Year 2024
A6: Name of TB Coodinator/Facility incharge : | H6: ___________________________________________________ | T6: Date of completion of this form : | Z6: _______________________
A8: Block 1: | K8: New (N) | M8: Relapse ® | O8: Previous Treatment History Unknown (UK) | R8: N+R+UK | U8: Previously treated ( Excluding Relapse) | AB8: Total
A9: All TB Cases Registered | U9: Treatment after failure | X9: Treatment after lost to follow-up | Z9: Other previously treated
A11: Pulmonary, Bacteriologically Confermid | K11: 44 | M11: 10 | O11: 0 | R11: 54 | U11: 0 | X11: 0 | Z11: 0 | AB11: 54
A12: Pulmonary , Clinically Diagnosed | K12: 13 | M12: 1 | O12: 0 | R12: 14 | U12: 0 | X12: 0 | Z12: 0 | AB12: 14
A13: Extra Pulmonary, Bacteriologically Confermid | K13: 0 | M13: 0 | O13: 0 | R13: 0 | U13: 0 | X13: 0 | Z13: 0 | AB13: 0
A14: Extra Pulmonary , Clinically Diagnosed | K14: 4 | M14: 0 | O14: 0 | R14: 4 | U14: 0 | X14: 0 | Z14: 0 | AB14: 4
A15: Total | K15: 61 | M15: 11 | O15: 0 | R15: 72 | U15: 0 | X15: 0 | Z15: 0 | AB15: 72
A16: Block 2: All New, Relapse and previous treatment history unknown Cases registered during the period by Age Group and Gender
K17: 0-4 | M17: 5-14 | O17: 15-24 | Q17: 25-34 | S17: 35-44 | U17: 45-54 | W17: 55-64 | Y17: 65 & Above | AA17: Total | AC17: Grand Total
K18: M | L18: F | M18: M | N18: F | O18: M | P18: F | Q18: M | R18: F | S18: M | T18: F | U18: M | V18: F | W18: M | X18: F | Y18: M | Z18: F | AA18: M | AB18: F
A19: Pulmonary, Bacteriologically Confermid | K19: 0 | L19: 0 | M19: 0 | N19: 0 | O19: 4 | P19: 16 | Q19: 5 | R19: 7 | S19: 4 | T19: 6 | U19: 4 | V19: 4 | W19: 1 | X19: 1 | Y19: 1 | Z19: 1 | AA19: 19 | AB19: 35 | AC19: 54
A20: Pulmonary , Clinically Diagnosed | K20: 0 | L20: 0 | M20: 0 | N20: 0 | O20: 1 | P20: 1 | Q20: 0 | R20: 2 | S20: 5 | T20: 1 | U20: 1 | V20: 0 | W20: 0 | X20: 2 | Y20: 0 | Z20: 1 | AA20: 7 | AB20: 7 | AC20: 14
A21: Extra Pulmonary, Bacteriologically Confermid | K21: 0 | L21: 0 | M21: 0 | N21: 0 | O21: 0 | P21: 0 | Q21: 0 | R21: 0 | S21: 0 | T21: 0 | U21: 0 | V21: 0 | W21: 0 | X21: 0 | Y21: 0 | Z21: 0 | AA21: 0 | AB21: 0 | AC21: 0
A22: Extra Pulmonary , Clinically Diagnosed | K22: 0 | L22: 0 | M22: 0 | N22: 0 | O22: 1 | P22: 1 | Q22: 1 | R22: 0 | S22: 0 | T22: 0 | U22: 1 | V22: 0 | W22: 0 | X22: 0 | Y22: 0 | Z22: 0 | AA22: 3 | AB22: 1 | AC22: 4
A23: Total | K23: 0 | L23: 0 | M23: 0 | N23: 0 | O23: 6 | P23: 18 | Q23: 6 | R23: 9 | S23: 9 | T23: 7 | U23: 6 | V23: 4 | W23: 1 | X23: 3 | Y23: 1 | Z23: 2 | AA23: 29 | AB23: 43 | AC23: 72
A25: Block 3: Presumptive TB Cases Identified Laboratory Diagnosis and use of WRD | N25: Block 4 : TB HIV Activities
A26: Total New OPD in Quarter | B26: No. of presumptive TB cases identified | D26: No. of Presumptive TB Patients tested Using | G26: Among Presumptive TB cases tested number reported B+ | K26: Among all registered number of B+ TB Cases | L26: Amoung All (N+R+UK) number tested by Gene Xpert | N26: No. of TB patients tested for HIV | Q26: TB Patients tested positive for HIV | T26: HIV positive TB Patients put on ART
B27: Total | C27: Through Community Referrals (LHWs) | D27: AFB | E27: Xp & AFB | F27: XP | G27: AFB | H27: AFB + Xpert | I27: Xpert | J27: G.Tot | N27: 0 | Q27: 0 | T27: 0
A28: 14028 | B28: 338 | C28: 3 | D28: 89 | E28: 140 | F28: 94 | G28: 3 | H28: 37 | I28: 14 | J28: 54 | K28: 54 | L28: 65 | N28: HIV patient tested for TB | Q28: HIV patients tested positive for TB | T28: TB positive HIV patients put on TB Tx | X28: HIV positive TB -Ve patients on TPT
N29: 0 | Q29: 0 | T29: 0 | Y29: 0-4 | AA29: 5-14 | AB29: 15 & above
X30: 6H | Y30: 0 | AA30: 0 | AB30: 0
X31: 3HR | Y31: 0 | AA31: 0 | AB31: 0
X32: 3 HP | Y32: 0 | AA32: 0 | AB32: 0
A34: Block 5 : Bacteriologically Confermid TB Cases with DST Result | N34: Block 6 : Contact Tracing HH *
G35: Rifampicin | I35: Isoniazid | K35: Fluoroquninolone | N35: Total No. of HH of B+ PTB | Q35: No. of HH contacts of B+ PTB Cases Screened | T35: Amoung HH contact screened, No. of TB Cases diagnosed | W35: No. of HH Contacts Initiated on TPT | AA35: HIV negative Immuno compromised on TPT
G36: Result | H36: Resistant | I36: Result | J36: Resistant | K36: Result | L36: Resistant | N36: 0-4 | O36: 5-14 | P36: 15 + | Q36: 0-4 | R36: 5-14 | S36: 15 + | T36: 0-4 | U36: 5-14 | V36: 15 + | X36: 0-4 | Y36: 5-14 | Z36: 15+ | AA36: 0-4 | AB36: 5-14 | AC36: 15+
A37: New + UK | G37: 32 | H37: 0 | I37: 0 | J37: 0 | K37: 0 | L37: 0 | N37: 0 | O37: 0 | P37: 13 | Q37: 0 | R37: 7 | S37: 40 | T37: 0 | U37: 0 | V37: 5 | W37: 6H | X37: 0 | Y37: 0 | Z37: 0 | AA37: 0 | AB37: 0 | AC37: 0
A38: Relapse | G38: 5 | H38: 0 | I38: 0 | J38: 0 | K38: 0 | L38: 0 | W38: 3HR | X38: 0 | Y38: 0 | Z38: 0 | AA38: 0 | AB38: 0 | AC38: 0
A39: Previously treated | G39: 0 | H39: 0 | I39: 0 | J39: 0 | K39: 0 | L39: 0 | W39: 3 HP | X39: 0 | Y39: 0 | Z39: 0 | AA39: 0 | AB39: 0 | AC39: 0
A40: Total | G40: 37 | H40: 0 | I40: 0 | J40: 0 | K40: 0 | L40: 0
A41: QUARTERLY REPORT ON TB CASES REGISTRATION
A42: INDIVIDUAL/CONSOLIDATED (TICK ONE) | Y42: TB - 07
A43: Name of TB Care Facility (BMU) : | E43: SINDH CONSOLIDATED | I43: District : | K43: __________________ | M43: Central : | O43: ________________ | T43: Patients registered during | Y43: 2nd Quarter | AB43: of Year 2024
A45: Name of TB Coodinator/Facility incharge : | H45: ___________________________________________________ | T45: Date of completion of this form : | Z45: _______________________
A47: Block 1: | K47: New (N) | M47: Relapse ® | O47: Previous Treatment History Unknown (UK) | R47: N+R+UK | U47: Previously treated ( Excluding Relapse) | AB47: Total
A48: All TB Cases Registered | U48: Treatment after failure | X48: Treatment after lost to follow-up | Z48: Other previously treated
...

Sheet GILGIT BALTISTAN
A2: QUARTERLY REPORT ON TB CASES REGISTRATION
A3: INDIVIDUAL/CONSOLIDATED (TICK ONE) | Y3: TB - 07
A4: Name of TB Care Facility (BMU) : | E4: GB - CONSOLIDATED | I4: District : | K4: __________________ | M4: Central : | O4: Gilgit Baltistan | T4: Patients registered during | Y4: 1st Quarter | AB4: of Year 2024
A6: Name of TB Coodinator/Facility incharge : | H6: ___________________________________________________ | T6: Date of completion of this form : | Z6: _______________________
A8: Block 1: | K8: New (N) | M8: Relapse ® | O8: Previous Treatment History Unknown (UK) | R8: N+R+UK | U8: Previously treated ( Excluding Relapse) | AB8: Total
A9: All TB Cases Registered | U9: Treatment after failure | X9: Treatment after lost to follow-up | Z9: Other previously treated
A11: Pulmonary, Bacteriologically Confermid | K11: 80 | M11: 0 | O11: 0 | R11: 80 | U11: 0 | X11: 0 | Z11: 0 | AB11: 80
A12: Pulmonary , Clinically Diagnosed | K12: 474 | M12: 1 | O12: 0 | R12: 475 | U12: 0 | X12: 0 | Z12: 1 | AB12: 476
A13: Extra Pulmonary, Bacteriologically Confermid | K13: 1 | M13: 0 | O13: 0 | R13: 1 | U13: 0 | X13: 0 | Z13: 0 | AB13: 1
A14: Extra Pulmonary , Clinically Diagnosed | K14: 198 | M14: 0 | O14: 0 | R14: 198 | U14: 0 | X14: 0 | Z14: 0 | AB14: 198
A15: Total | K15: 753 | M15: 1 | O15: 0 | R15: 754 | U15: 0 | X15: 0 | Z15: 1 | AB15: 755
A16: Block 2: All New, Relapse and previous treatment history unknown Cases registered during the period by Age Group and Gender
K17: 0-4 | M17: 5-14 | O17: 15-24 | Q17: 25-34 | S17: 35-44 | U17: 45-54 | W17: 55-64 | Y17: 65 & Above | AA17: Total | AC17: Grand Total
K18: M | L18: F | M18: M | N18: F | O18: M | P18: F | Q18: M | R18: F | S18: M | T18: F | U18: M | V18: F | W18: M | X18: F | Y18: M | Z18: F | AA18: M | AB18: F
A19: Pulmonary, Bacteriologically Confermid | K19: 0 | L19: 0 | M19: 1 | N19: 1 | O19: 6 | P19: 12 | Q19: 7 | R19: 9 | S19: 4 | T19: 4 | U19: 3 | V19: 5 | W19: 3 | X19: 4 | Y19: 12 | Z19: 9 | AA19: 36 | AB19: 44 | AC19: 80
A20: Pulmonary , Clinically Diagnosed | K20: 138 | L20: 120 | M20: 31 | N20: 35 | O20: 21 | P20: 14 | Q20: 18 | R20: 18 | S20: 11 | T20: 16 | U20: 9 | V20: 7 | W20: 9 | X20: 4 | Y20: 14 | Z20: 10 | AA20: 251 | AB20: 224 | AC20: 475
A21: Extra Pulmonary, Bacteriologically Confermid | K21: 0 | L21: 0 | M21: 0 | N21: 0 | O21: 0 | P21: 0 | Q21: 0 | R21: 0 | S21: 0 | T21: 0 | U21: 0 | V21: 0 | W21: 0 | X21: 0 | Y21: 0 | Z21: 1 | AA21: 0 | AB21: 1 | AC21: 1
A22: Extra Pulmonary , Clinically Diagnosed | K22: 23 | L22: 15 | M22: 12 | N22: 11 | O22: 34 | P22: 18 | Q22: 14 | R22: 14 | S22: 14 | T22: 6 | U22: 11 | V22: 5 | W22: 5 | X22: 2 | Y22: 7 | Z22: 7 | AA22: 120 | AB22: 78 | AC22: 198
A23: Total | K23: 161 | L23: 135 | M23: 44 | N23: 47 | O23: 61 | P23: 44 | Q23: 39 | R23: 41 | S23: 29 | T23: 26 | U23: 23 | V23: 17 | W23: 17 | X23: 10 | Y23: 33 | Z23: 27 | AA23: 407 | AB23: 347 | AC23: 754
A25: Block 3: Presumptive TB Cases Identified Laboratory Diagnosis and use of WRD | N25: Block 4 : TB HIV Activities
A26: Total New OPD in Quarter | B26: No. of presumptive TB cases identified | D26: No. of Presumptive TB Patients tested Using | G26: Among Presumptive TB cases tested number reported B+ | K26: Among all registered number of B+ TB Cases | L26: Amoung All (N+R+UK) number tested by Gene Xpert | N26: No. of TB patients tested for HIV | Q26: TB Patients tested positive for HIV | T26: HIV positive TB Patients put on ART
B27: Total | C27: Through Community Referrals (LHWs) | D27: AFB | E27: Xp & AFB | F27: XP | G27: AFB | H27: AFB + Xpert | I27: Xpert | J27: G.Tot | N27: 0 | Q27: 0 | T27: 0
A28: 188323 | B28: 2077 | C28: 1144 | D28: 626 | E28: 542 | F28: 938 | G28: 72 | H28: 2 | I28: 27 | J28: 101 | K28: 78 | L28: 109 | N28: HIV patient tested for TB | Q28: HIV patients tested positive for TB | T28: TB positive HIV patients put on TB Tx | X28: HIV positive TB -Ve patients on TPT
N29: 0 | Q29: 0 | T29: 0 | Y29: 0-4 | AA29: 5-14 | AB29: 15 & above
X30: 6H | Y30: 0 | AA30: 0 | AB30: 0
X31: 3HR | Y31: 0 | AA31: 0 | AB31: 0
X32: 3 HP | Y32: 0 | AA32: 0 | AB32: 0
A34: Block 5 : Bacteriologically Confermid TB Cases with DST Result | N34: Block 6 : Contact Tracing HH *
G35: Rifampicin | I35: Isoniazid | K35: Fluoroquninolone | N35: Total No. of HH of B+ PTB | Q35: No. of HH contacts of B+ PTB Cases Screened | T35: Amoung HH contact screened, No. of TB Cases diagnosed | W35: No. of HH Contacts Initiated on TPT | AA35: HIV negative Immuno compromised on TPT
G36: Result | H36: Resistant | I36: Result | J36: Resistant | K36: Result | L36: Resistant | N36: 0-4 | O36: 5-14 | P36: 15 + | Q36: 0-4 | R36: 5-14 | S36: 15 + | T36: 0-4 | U36: 5-14 | V36: 15 + | X36: 0-4 | Y36: 5-14 | Z36: 15+ | AA36: 0-4 | AB36: 5-14 | AC36: 15+
A37: New + UK | G37: 73 | H37: 0 | I37: 0 | J37: 0 | K37: 0 | L37: 0 | N37: 1 | O37: 3 | P37: 52 | Q37: 1 | R37: 29 | S37: 132 | T37: 0 | U37: 0 | V37: 1 | W37: 6H | X37: 0 | Y37: 0 | Z37: 0 | AA37: 0 | AB37: 0 | AC37: 0
A38: Relapse | G38: 0 | H38: 0 | I38: 0 | J38: 0 | K38: 0 | L38: 0 | W38: 3HR | X38: 0 | Y38: 0 | Z38: 0 | AA38: 0 | AB38: 0 | AC38: 0
A39: Previously treated | G39: 1 | H39: 0 | I39: 0 | J39: 0 | K39: 0 | L39: 0 | W39: 3 HP | X39: 0 | Y39: 0 | Z39: 3 | AA39: 0 | AB39: 0 | AC39: 0
A40: Total | G40: 74 | H40: 0 | I40: 0 | J40: 0 | K40: 0 | L40: 0
A41: QUARTERLY REPORT ON TB CASES REGISTRATION
A42: INDIVIDUAL/CONSOLIDATED (TICK ONE) | Y42: TB - 07
A43: Name of TB Care Facility (BMU) : | E43: GB - CONSOLIDATED | I43: District : | K43: __________________ | M43: Central : | O43: Gilgit Baltistan | T43: Patients registered during | Y43: 2nd Quarter | AB43: of Year 2024
A45: Name of TB Coodinator/Facility incharge : | H45: ___________________________________________________ | T45: Date of completion of this form : | Z45: _______________________
A47: Block 1: | K47: New (N) | M47: Relapse ® | O47: Previous Treatment History Unknown (UK) | R47: N+R+UK | U47: Previously treated ( Excluding Relapse) | AB47: Total
A48: All TB Cases Registered | U48: Treatment after failure | X48: Treatment after lost to follow-up | Z48: Other previously treated
...

Sheet AZAD KHASHMIR
A2: QUARTERLY REPORT ON TB CASES REGISTRATION
A3: INDIVIDUAL/CONSOLIDATED (TICK ONE) | Y3: TB - 07
A4: Name of TB Care Facility (BMU) : | E4: Consolidated | I4: District : | M4: Central : | O4: Azad Kashmir | T4: Patients registered during | Y4: 1st Quarter | AB4: of Year 2024
A6: Name of TB Coodinator/Facility incharge : | H6: ___________________________________________________ | T6: Date of completion of this form : | Z6: _______________________
A8: Block 1: | K8: New (N) | M8: Relapse ® | O8: Previous Treatment History Unknown (UK) | R8: N+R+UK | U8: Previously treated ( Excluding Relapse) | AB8: Total
A9: All TB Cases Registered | U9: Treatment after failure | X9: Treatment after lost to follow-up | Z9: Other previously treated
A11: Pulmonary, Bacteriologically Confermid | K11: 681 | M11: 52 | O11: 1 | R11: 734 | U11: 1 | X11: 0 | Z11: 1 | AB11: 736
A12: Pulmonary , Clinically Diagnosed | K12: 438 | M12: 9 | O12: 4 | R12: 451 | U12: 0 | X12: 1 | Z12: 4 | AB12: 456
A13: Extra Pulmonary, Bacteriologically Confermid | K13: 0 | M13: 0 | O13: 0 | R13: 0 | U13: 0 | X13: 0 | Z13: 0 | AB13: 0
A14: Extra Pulmonary , Clinically Diagnosed | K14: 323 | M14: 3 | O14: 0 | R14: 326 | U14: 0 | X14: 0 | Z14: 3 | AB14: 329
A15: Total | K15: 1442 | M15: 64 | O15: 5 | R15: 1511 | U15: 1 | X15: 1 | Z15: 8 | AB15: 1521
A16: Block 2: All New, Relapse and previous treatment history unknown Cases registered during the period by Age Group and Gender
K17: 0-4 | M17: 5-14 | O17: 15-24 | Q17: 25-34 | S17: 35-44 | U17: 45-54 | W17: 55-64 | Y17: 65 & Above | AA17: Total | AC17: Grand Total
K18: M | L18: F | M18: M | N18: F | O18: M | P18: F | Q18: M | R18: F | S18: M | T18: F | U18: M | V18: F | W18: M | X18: F | Y18: M | Z18: F | AA18: M | AB18: F
A19: Pulmonary, Bacteriologically Confermid | K19: 5 | L19: 2 | M19: 5 | N19: 15 | O19: 51 | P19: 75 | Q19: 55 | R19: 29 | S19: 46 | T19: 40 | U19: 52 | V19: 45 | W19: 75 | X19: 57 | Y19: 99 | Z19: 83 | AA19: 388 | AB19: 346 | AC19: 734
A20: Pulmonary , Clinically Diagnosed | K20: 8 | L20: 4 | M20: 8 | N20: 16 | O20: 27 | P20: 27 | Q20: 30 | R20: 29 | S20: 25 | T20: 22 | U20: 27 | V20: 26 | W20: 31 | X20: 47 | Y20: 71 | Z20: 53 | AA20: 227 | AB20: 224 | AC20: 451
A21: Extra Pulmonary, Bacteriologically Confermid | K21: 0 | L21: 0 | M21: 0 | N21: 0 | O21: 0 | P21: 0 | Q21: 0 | R21: 0 | S21: 0 | T21: 0 | U21: 0 | V21: 0 | W21: 0 | X21: 0 | Y21: 0 | Z21: 0 | AA21: 0 | AB21: 0 | AC21: 0
A22: Extra Pulmonary , Clinically Diagnosed | K22: 4 | L22: 2 | M22: 8 | N22: 8 | O22: 25 | P22: 34 | Q22: 35 | R22: 21 | S22: 20 | T22: 21 | U22: 26 | V22: 17 | W22: 24 | X22: 16 | Y22: 42 | Z22: 23 | AA22: 184 | AB22: 142 | AC22: 326
A23: Total | K23: 17 | L23: 8 | M23: 21 | N23: 39 | O23: 103 | P23: 136 | Q23: 120 | R23: 79 | S23: 91 | T23: 83 | U23: 105 | V23: 88 | W23: 130 | X23: 120 | Y23: 212 | Z23: 159 | AA23: 799 | AB23: 712 | AC23: 1511
A25: Block 3: Presumptive TB Cases Identified Laboratory Diagnosis and use of WRD | N25: Block 4 : TB HIV Activities
A26: Total New OPD in Quarter | B26: No. of presumptive TB cases identified | D26: No. of Presumptive TB Patients tested Using | G26: Among Presumptive TB cases tested number reported B+ | K26: Among all registered number of B+ TB Cases | L26: Amoung All (N+R+UK) number tested by Gene Xpert | N26: No. of TB patients tested for HIV | Q26: TB Patients tested positive for HIV | T26: HIV positive TB Patients put on ART
B27: Total | C27: Through Community Referrals (LHWs) | D27: AFB | E27: Xp & AFB | F27: XP | G27: AFB | H27: AFB + Xpert | I27: Xpert | J27: G.Tot | N27: 0 | Q27: 0 | T27: 0
A28: 259129 | B28: 10854 | C28: 1438 | D28: 5715 | E28: 0 | F28: 6116 | G28: 716 | H28: 0 | I28: 0 | J28: 716 | K28: 736 | L28: 1123 | N28: HIV patient tested for TB | Q28: HIV patients tested positive for TB | T28: TB positive HIV patients put on TB Tx | X28: HIV positive TB -Ve patients on TPT
N29: 0 | Q29: 0 | T29: 0 | Y29: 0-4 | AA29: 5-14 | AB29: 15 & above
X30: 6H | Y30: 0 | AA30: 0 | AB30: 0
X31: 3HR | Y31: 0 | AA31: 0 | AB31: 0
X32: 3 HP | Y32: 0 | AA32: 0 | AB32: 0
A34: Block 5 : Bacteriologically Confermid TB Cases with DST Result | N34: Block 6 : Contact Tracing HH *
G35: Rifampicin | I35: Isoniazid | K35: Fluoroquninolone | N35: Total No. of HH of B+ PTB | Q35: No. of HH contacts of B+ PTB Cases Screened | T35: Amoung HH contact screened, No. of TB Cases diagnosed | W35: No. of HH Contacts Initiated on TPT | AA35: HIV negative Immuno compromised on TPT
G36: Result | H36: Resistant | I36: Result | J36: Resistant | K36: Result | L36: Resistant | N36: 0-4 | O36: 5-14 | P36: 15 + | Q36: 0-4 | R36: 5-14 | S36: 15 + | T36: 0-4 | U36: 5-14 | V36: 15 + | X36: 0-4 | Y36: 5-14 | Z36: 15+ | AA36: 0-4 | AB36: 5-14 | AC36: 15+
A37: New + UK | G37: 688 | H37: 1 | I37: 0 | J37: 0 | K37: 0 | L37: 0 | N37: 0 | O37: 670 | P37: 4015 | Q37: 0 | R37: 592 | S37: 3560 | T37: 0 | U37: 30 | V37: 129 | W37: 6H | X37: 1 | Y37: 0 | Z37: 0 | AA37: 0 | AB37: 0 | AC37: 0
A38: Relapse | G38: 0 | H38: 0 | I38: 0 | J38: 0 | K38: 0 | L38: 0 | W38: 3HR | X38: 0 | Y38: 0 | Z38: 0 | AA38: 0 | AB38: 0 | AC38: 0
A39: Previously treated | G39: 1 | H39: 0 | I39: 0 | J39: 0 | K39: 0 | L39: 0 | W39: 3 HP | X39: 0 | Y39: 0 | Z39: 0 | AA39: 0 | AB39: 0 | AC39: 0
A40: Total | G40: 689 | H40: 1 | I40: 0 | J40: 0 | K40: 0 | L40: 0
A41: QUARTERLY REPORT ON TB CASES REGISTRATION
A42: INDIVIDUAL/CONSOLIDATED (TICK ONE) | Y42: TB - 07
A43: Name of TB Care Facility (BMU) : | E43: Consolidated | I43: District : | K43: 0 | M43: Central : | O43: Azad Kashmir | T43: Patients registered during | Y43: 2nd Quarter | AB43: of Year 2024
A45: Name of TB Coodinator/Facility incharge : | H45: ___________________________________________________ | T45: Date of completion of this form : | Z45: _______________________
A47: Block 1: | K47: New (N) | M47: Relapse ® | O47: Previous Treatment History Unknown (UK) | R47: N+R+UK | U47: Previously treated ( Excluding Relapse) | AB47: Total
A48: All TB Cases Registered | U48: Treatment after failure | X48: Treatment after lost to follow-up | Z48: Other previously treated
...

Sheet KHYBER PAKHTUNKHWA
A2: QUARTERLY REPORT ON TB CASES REGISTRATION
A3: INDIVIDUAL/CONSOLIDATED (TICK ONE) | Y3: TB - 07
A4: Name of TB Care Facility (BMU) : | E4: KHYBER PAKHTHUNKHWA | I4: District : | K4: __________________ | M4: Central : | O4: ________________ | T4: Patients registered during | Y4: 1st Quarter | AB4: of Year 2024
A6: Name of TB Coodinator/Facility incharge : | H6: ___________________________________________________ | T6: Date of completion of this form : | Z6: _______________________
A8: Block 1: | K8: New (N) | M8: Relapse ® | O8: Previous Treatment History Unknown (UK) | R8: N+R+UK | U8: Previously treated ( Excluding Relapse) | AB8: Total
A9: All TB Cases Registered | U9: Treatment after failure | X9: Treatment after lost to follow-up | Z9: Other previously treated
A11: Pulmonary, Bacteriologically Confermid | K11: 24 | M11: 2 | O11: 0 | R11: 26 | U11: 0 | X11: 0 | Z11: 0 | AB11: 26
A12: Pulmonary , Clinically Diagnosed | K12: 21 | M12: 0 | O12: 0 | R12: 21 | U12: 0 | X12: 0 | Z12: 0 | AB12: 21
A13: Extra Pulmonary, Bacteriologically Confermid | K13: 0 | M13: 0 | O13: 0 | R13: 0 | U13: 0 | X13: 0 | Z13: 0 | AB13: 0
A14: Extra Pulmonary , Clinically Diagnosed | K14: 43 | M14: 1 | O14: 0 | R14: 44 | U14: 0 | X14: 0 | Z14: 0 | AB14: 44
A15: Total | K15: 88 | M15: 3 | O15: 0 | R15: 91 | U15: 0 | X15: 0 | Z15: 0 | AB15: 91
A16: Block 2: All New, Relapse and previous treatment history unknown Cases registered during the period by Age Group and Gender
K17: 0-4 | M17: 5-14 | O17: 15-24 | Q17: 25-34 | S17: 35-44 | U17: 45-54 | W17: 55-64 | Y17: 65 & Above | AA17: Total | AC17: Grand Total
K18: M | L18: F | M18: M | N18: F | O18: M | P18: F | Q18: M | R18: F | S18: M | T18: F | U18: M | V18: F | W18: M | X18: F | Y18: M | Z18: F | AA18: M | AB18: F
A19: Pulmonary, Bacteriologically Confermid | K19: 0 | L19: 0 | M19: 0 | N19: 0 | O19: 6 | P19: 5 | Q19: 4 | R19: 3 | S19: 2 | T19: 1 | U19: 2 | V19: 1 | W19: 0 | X19: 0 | Y19: 2 | Z19: 0 | AA19: 16 | AB19: 10 | AC19: 26
A20: Pulmonary , Clinically Diagnosed | K20: 0 | L20: 0 | M20: 0 | N20: 0 | O20: 3 | P20: 2 | Q20: 3 | R20: 2 | S20: 5 | T20: 0 | U20: 1 | V20: 1 | W20: 1 | X20: 1 | Y20: 1 | Z20: 1 | AA20: 14 | AB20: 7 | AC20: 21
A21: Extra Pulmonary, Bacteriologically Confermid | K21: 0 | L21: 0 | M21: 0 | N21: 0 | O21: 0 | P21: 0 | Q21: 0 | R21: 0 | S21: 0 | T21: 0 | U21: 0 | V21: 0 | W21: 0 | X21: 0 | Y21: 0 | Z21: 0 | AA21: 0 | AB21: 0 | AC21: 0
A22: Extra Pulmonary , Clinically Diagnosed | K22: 1 | L22: 0 | M22: 2 | N22: 7 | O22: 5 | P22: 1 | Q22: 3 | R22: 5 | S22: 2 | T22: 4 | U22: 4 | V22: 1 | W22: 1 | X22: 3 | Y22: 4 | Z22: 1 | AA22: 22 | AB22: 22 | AC22: 44
A23: Total | K23: 1 | L23: 0 | M23: 2 | N23: 7 | O23: 14 | P23: 8 | Q23: 10 | R23: 10 | S23: 9 | T23: 5 | U23: 7 | V23: 3 | W23: 2 | X23: 4 | Y23: 7 | Z23: 2 | AA23: 52 | AB23: 39 | AC23: 91
A25: Block 3: Presumptive TB Cases Identified Laboratory Diagnosis and use of WRD | N25: Block 4 : TB HIV Activities
A26: Total New OPD in Quarter | B26: No. of presumptive TB cases identified | D26: No. of Presumptive TB Patients tested Using | G26: Among Presumptive TB cases tested number reported B+ | K26: Among all registered number of B+ TB Cases | L26: Amoung All (N+R+UK) number tested by Gene Xpert | N26: No. of TB patients tested for HIV | Q26: TB Patients tested positive for HIV | T26: HIV positive TB Patients put on ART
B27: Total | C27: Through Community Referrals (LHWs) | D27: AFB | E27: Xp & AFB | F27: XP | G27: AFB | H27: AFB + Xpert | I27: Xpert | J27: G.Tot | N27: 0 | Q27: 0 | T27: 0
A28: 765 | B28: 170 | C28: 9 | D28: 127 | E28: 0 | F28: 0 | G28: 14 | H28: 2 | I28: 10 | J28: 26 | K28: 16 | L28: 34 | N28: HIV patient tested for TB | Q28: HIV patients tested positive for TB | T28: TB positive HIV patients put on TB Tx | X28: HIV positive TB -Ve patients on TPT
N29: 0 | Q29: 0 | T29: 0 | Y29: 0-4 | AA29: 5-14 | AB29: 15 & above
X30: 6H | Y30: 0 | AA30: 0 | AB30: 0
X31: 3HR | Y31: 0 | AA31: 0 | AB31: 0
X32: 3 HP | Y32: 0 | AA32: 0 | AB32: 0
A34: Block 5 : Bacteriologically Confermid TB Cases with DST Result | N34: Block 6 : Contact Tracing HH *
G35: Rifampicin | I35: Isoniazid | K35: Fluoroquninolone | N35: Total No. of HH of B+ PTB | Q35: No. of HH contacts of B+ PTB Cases Screened | T35: Amoung HH contact screened, No. of TB Cases diagnosed | W35: No. of HH Contacts Initiated on TPT | AA35: HIV negative Immuno compromised on TPT
G36: Result | H36: Resistant | I36: Result | J36: Resistant | K36: Result | L36: Resistant | N36: 0-4 | O36: 5-14 | P36: 15 + | Q36: 0-4 | R36: 5-14 | S36: 15 + | T36: 0-4 | U36: 5-14 | V36: 15 + | X36: 0-4 | Y36: 5-14 | Z36: 15+ | AA36: 0-4 | AB36: 5-14 | AC36: 15+
A37: New + UK | G37: 19 | H37: 0 | I37: 0 | J37: 0 | K37: 0 | L37: 0 | N37: 0 | O37: 500 | P37: 97 | Q37: 0 | R37: 40 | S37: 33 | T37: 0 | U37: 11 | V37: 1 | W37: 6H | X37: 0 | Y37: 0 | Z37: 0 | AA37: 0 | AB37: 0 | AC37: 0
A38: Relapse | G38: 2 | H38: 0 | I38: 0 | J38: 0 | K38: 0 | L38: 0 | W38: 3HR | X38: 0 | Y38: 0 | Z38: 0 | AA38: 0 | AB38: 0 | AC38: 0
A39: Previously treated | G39: 0 | H39: 0 | I39: 0 | J39: 0 | K39: 0 | L39: 0 | W39: 3 HP | X39: 0 | Y39: 0 | Z39: 0 | AA39: 0 | AB39: 0 | AC39: 0
A40: Total | G40: 21 | H40: 0 | I40: 0 | J40: 0 | K40: 0 | L40: 0
A41: QUARTERLY REPORT ON TB CASES REGISTRATION
A42: INDIVIDUAL/CONSOLIDATED (TICK ONE) | Y42: TB - 07
A43: Name of TB Care Facility (BMU) : | E43: KHYBER PAKHTHUNKHWA | I43: District : | K43: __________________ | M43: Central : | O43: ________________ | T43: Patients registered during | Y43: 2nd Quarter | AB43: of Year 2024
A45: Name of TB Coodinator/Facility incharge : | H45: ___________________________________________________ | T45: Date of completion of this form : | Z45: _______________________
A47: Block 1: | K47: New (N) | M47: Relapse ® | O47: Previous Treatment History Unknown (UK) | R47: N+R+UK | U47: Previously treated ( Excluding Relapse) | AB47: Total
A48: All TB Cases Registered | U48: Treatment after failure | X48: Treatment after lost to follow-up | Z48: Other previously treated
...

Sheet All Project Total - 2024
A2: QUARTERLY REPORT ON TB CASES REGISTRATION
A3: INDIVIDUAL/CONSOLIDATED (TICK ONE) | Y3: TB - 07
A4: Name of TB Care Facility (BMU) : | E4: All Project Total | I4: District : | K4: __________________ | M4: Central : | O4: CONSOLIDATED | T4: Patients registered during | Y4: 1st Quarter | AB4: of Year 2024
A6: Name of TB Coodinator/Facility incharge : | H6: ___________________________________________________ | T6: Date of completion of this form : | Z6: _______________________
A8: Block 1: | K8: New (N) | M8: Relapse ® | O8: Previous Treatment History Unknown (UK) | R8: N+R+UK | U8: Previously treated ( Excluding Relapse) | AB8: Total
A9: All TB Cases Registered | U9: Treatment after failure | X9: Treatment after lost to follow-up | Z9: Other previously treated
A11: Pulmonary, Bacteriologically Confermid | K11: =SUM(MPR!K11+KARACHI!K11+SINDH!K11+'GILGIT BALTISTAN'!K11+'AZAD KHASHMIR'!K11+'KHYBER PAKHTUNKHWA'!K11) -> 955 | M11: =SUM(MPR!M11+KARACHI!M11+SINDH!M11+'GILGIT BALTISTAN'!M11+'AZAD KHASHMIR'!M11+'KHYBER PAKHTUNKHWA'!M11) -> 88 | O11: =MPR!O11+KARACHI!O11+SINDH!O11+'GILGIT BALTISTAN'!O11:Q11+'AZAD KHASHMIR'!O11:Q11+'KHYBER PAKHTUNKHWA'!O11:Q11 -> 4 | R11: =SUM(K11+M11+O11) -> 1047 | U11: =MPR!U11+KARACHI!U11+SINDH!U11+'GILGIT BALTISTAN'!U11:W11+'AZAD KHASHMIR'!U11:W11+'KHYBER PAKHTUNKHWA'!U11:W11 -> 1 | X11: =MPR!X11+KARACHI!X11+SINDH!X11+'GILGIT BALTISTAN'!X11:Y11+'AZAD KHASHMIR'!X11:Y11+'KHYBER PAKHTUNKHWA'!X11:Y11 -> 3 | Z11: =MPR!Z11+KARACHI!Z11+SINDH!Z11+'GILGIT BALTISTAN'!Z11:AA11+'AZAD KHASHMIR'!Z11:AA11+'KHYBER PAKHTUNKHWA'!Z11:AA11 -> 4 | AB11: =SUM(K11+M11+O11+U11+X11+Z11) -> 1055
A12: Pulmonary , Clinically Diagnosed | K12: =SUM(MPR!K12+KARACHI!K12+SINDH!K12+'GILGIT BALTISTAN'!K12+'AZAD KHASHMIR'!K12+'KHYBER PAKHTUNKHWA'!K12) -> 1085 | M12: =SUM(MPR!M12+KARACHI!M12+SINDH!M12+'GILGIT BALTISTAN'!M12+'AZAD KHASHMIR'!M12+'KHYBER PAKHTUNKHWA'!M12) -> 51 | O12: =MPR!O12+KARACHI!O12+SINDH!O12+'GILGIT BALTISTAN'!O12:Q12+'AZAD KHASHMIR'!O12:Q12+'KHYBER PAKHTUNKHWA'!O12:Q12 -> 5 | R12: =SUM(K12+M12+O12) -> 1141 | U12: =MPR!U12+KARACHI!U12+SINDH!U12+'GILGIT BALTISTAN'!U12:W12+'AZAD KHASHMIR'!U12:W12+'KHYBER PAKHTUNKHWA'!U12:W12 -> 0 | X12: =MPR!X12+KARACHI!X12+SINDH!X12+'GILGIT BALTISTAN'!X12:Y12+'AZAD KHASHMIR'!X12:Y12+'KHYBER PAKHTUNKHWA'!X12:Y12 -> 1 | Z12: =MPR!Z12+KARACHI!Z12+SINDH!Z12+'GILGIT BALTISTAN'!Z12:AA12+'AZAD KHASHMIR'!Z12:AA12+'KHYBER PAKHTUNKHWA'!Z12:AA12 -> 8 | AB12: =SUM(K12+M12+O12+U12+X12+Z12) -> 1150
A13: Extra Pulmonary, Bacteriologically Confermid | K13: =SUM(MPR!K13+KARACHI!K13+SINDH!K13+'GILGIT BALTISTAN'!K13+'AZAD KHASHMIR'!K13+'KHYBER PAKHTUNKHWA'!K13) -> 3 | M13: =SUM(MPR!M13+KARACHI!M13+SINDH!M13+'GILGIT BALTISTAN'!M13+'AZAD KHASHMIR'!M13+'KHYBER PAKHTUNKHWA'!M13) -> 0 | O13: =MPR!O13+KARACHI!O13+SINDH!O13+'GILGIT BALTISTAN'!O13:Q13+'AZAD KHASHMIR'!O13:Q13+'KHYBER PAKHTUNKHWA'!O13:Q13 -> 0 | R13: =SUM(K13+M13+O13) -> 3 | U13: =MPR!U13+KARACHI!U13+SINDH!U13+'GILGIT BALTISTAN'!U13:W13+'AZAD KHASHMIR'!U13:W13+'KHYBER PAKHTUNKHWA'!U13:W13 -> 0 | X13: =MPR!X13+KARACHI!X13+SINDH!X13+'GILGIT BALTISTAN'!X13:Y13+'AZAD KHASHMIR'!X13:Y13+'KHYBER PAKHTUNKHWA'!X13:Y13 -> 0 | Z13: =MPR!Z13+KARACHI!Z13+SINDH!Z13+'GILGIT BALTISTAN'!Z13:AA13+'AZAD KHASHMIR'!Z13:AA13+'KHYBER PAKHTUNKHWA'!Z13:AA13 -> 0 | AB13: =SUM(K13+M13+O13+U13+X13+Z13) -> 3
A14: Extra Pulmonary , Clinically Diagnosed | K14: =SUM(MPR!K14+KARACHI!K14+SINDH!K14+'GILGIT BALTISTAN'!K14+'AZAD KHASHMIR'!K14+'KHYBER PAKHTUNKHWA'!K14) -> 646 | M14: =SUM(MPR!M14+KARACHI!M14+SINDH!M14+'GILGIT BALTISTAN'!M14+'AZAD KHASHMIR'!M14+'KHYBER PAKHTUNKHWA'!M14) -> 9 | O14: =MPR!O14+KARACHI!O14+SINDH!O14+'GILGIT BALTISTAN'!O14:Q14+'AZAD KHASHMIR'!O14:Q14+'KHYBER PAKHTUNKHWA'!O14:Q14 -> 1 | R14: =SUM(K14+M14+O14) -> 656 | U14: =MPR!U14+KARACHI!U14+SINDH!U14+'GILGIT BALTISTAN'!U14:W14+'AZAD KHASHMIR'!U14:W14+'KHYBER PAKHTUNKHWA'!U14:W14 -> 0 | X14: =MPR!X14+KARACHI!X14+SINDH!X14+'GILGIT BALTISTAN'!X14:Y14+'AZAD KHASHMIR'!X14:Y14+'KHYBER PAKHTUNKHWA'!X14:Y14 -> 0 | Z14: =MPR!Z14+KARACHI!Z14+SINDH!Z14+'GILGIT BALTISTAN'!Z14:AA14+'AZAD KHASHMIR'!Z14:AA14+'KHYBER PAKHTUNKHWA'!Z14:AA14 -> 12 | AB14: =SUM(K14+M14+O14+U14+X14+Z14) -> 668
A15: Total | K15: =SUM(K11:L14) -> 2689 | M15: =SUM(M11:N14) -> 148 | O15: =SUM(O11:Q14) -> 10 | R15: =SUM(K15+M15+O15) -> 2847 | U15: =SUM(U11:W14) -> 1 | X15: =SUM(X11:Y14) -> 4 | Z15: =SUM(Z11:AA14) -> 24 | AB15: =SUM(K15+M15+O15+U15+X15+Z15) -> 2876
A16: Block 2: All New, Relapse and previous treatment history unknown Cases registered during the period by Age Group and Gender
K17: 0-4 | M17: 5-14 | O17: 15-24 | Q17: 25-34 | S17: 35-44 | U17: 45-54 | W17: 55-64 | Y17: 65 & Above | AA17: Total | AC17: Grand Total
K18: M | L18: F | M18: M | N18: F | O18: M | P18: F | Q18: M | R18: F | S18: M | T18: F | U18: M | V18: F | W18: M | X18: F | Y18: M | Z18: F | AA18: M | AB18: F
A19: Pulmonary, Bacteriologically Confermid | K19: =MPR!K19+KARACHI!K19+SINDH!K19+'GILGIT BALTISTAN'!K19+'AZAD KHASHMIR'!K19+'KHYBER PAKHTUNKHWA'!K19 -> 5 | L19: =MPR!L19+KARACHI!L19+SINDH!L19+'GILGIT BALTISTAN'!L19+'AZAD KHASHMIR'!L19+'KHYBER PAKHTUNKHWA'!L19 -> 2 | M19: =MPR!M19+KARACHI!M19+SINDH!M19+'GILGIT BALTISTAN'!M19+'AZAD KHASHMIR'!M19+'KHYBER PAKHTUNKHWA'!M19 -> 9 | N19: =MPR!N19+KARACHI!N19+SINDH!N19+'GILGIT BALTISTAN'!N19+'AZAD KHASHMIR'!N19+'KHYBER PAKHTUNKHWA'!N19 -> 28 | O19: =MPR!O19+KARACHI!O19+SINDH!O19+'GILGIT BALTISTAN'!O19+'AZAD KHASHMIR'!O19+'KHYBER PAKHTUNKHWA'!O19 -> 91 | P19: =MPR!P19+KARACHI!P19+SINDH!P19+'GILGIT BALTISTAN'!P19+'AZAD KHASHMIR'!P19+'KHYBER PAKHTUNKHWA'!P19 -> 132 | Q19: =MPR!Q19+KARACHI!Q19+SINDH!Q19+'GILGIT BALTISTAN'!Q19+'AZAD KHASHMIR'!Q19+'KHYBER PAKHTUNKHWA'!Q19 -> 84 | R19: =MPR!R19+KARACHI!R19+SINDH!R19+'GILGIT BALTISTAN'!R19+'AZAD KHASHMIR'!R19+'KHYBER PAKHTUNKHWA'!R19 -> 61 | ... Z19: =MPR!Z19+KARACHI!Z19+SINDH!Z19+'GILGIT BALTISTAN'!Z19+'AZAD KHASHMIR'!Z19+'KHYBER PAKHTUNKHWA'!Z19 -> 98 | AA19: =SUM(K19+M19+O19+Q19+S19+U19+W19+Y19) -> 532 | AB19: =SUM(L19+N19+P19+R19+T19+V19+X19+Z19) -> 515 | AC19: =SUM(AA19:AB19) -> 1047
A20: Pulmonary , Clinically Diagnosed | K20: =MPR!K20+KARACHI!K20+SINDH!K20+'GILGIT BALTISTAN'!K20+'AZAD KHASHMIR'!K20+'KHYBER PAKHTUNKHWA'!K20 -> 146 | L20: =MPR!L20+KARACHI!L20+SINDH!L20+'GILGIT BALTISTAN'!L20+'AZAD KHASHMIR'!L20+'KHYBER PAKHTUNKHWA'!L20 -> 126 | M20: =MPR!M20+KARACHI!M20+SINDH!M20+'GILGIT BALTISTAN'!M20+'AZAD KHASHMIR'!M20+'KHYBER PAKHTUNKHWA'!M20 -> 43 | N20: =MPR!N20+KARACHI!N20+SINDH!N20+'GILGIT BALTISTAN'!N20+'AZAD KHASHMIR'!N20+'KHYBER PAKHTUNKHWA'!N20 -> 59 | O20: =MPR!O20+KARACHI!O20+SINDH!O20+'GILGIT BALTISTAN'!O20+'AZAD KHASHMIR'!O20+'KHYBER PAKHTUNKHWA'!O20 -> 63 | P20: =MPR!P20+KARACHI!P20+SINDH!P20+'GILGIT BALTISTAN'!P20+'AZAD KHASHMIR'!P20+'KHYBER PAKHTUNKHWA'!P20 -> 77 | Q20: =MPR!Q20+KARACHI!Q20+SINDH!Q20+'GILGIT BALTISTAN'!Q20+'AZAD KHASHMIR'!Q20+'KHYBER PAKHTUNKHWA'!Q20 -> 64 | R20: =MPR!R20+KARACHI!R20+SINDH!R20+'GILGIT BALTISTAN'!R20+'AZAD KHASHMIR'!R20+'KHYBER PAKHTUNKHWA'!R20 -> 78 | ... Z20: =MPR!Z20+KARACHI!Z20+SINDH!Z20+'GILGIT BALTISTAN'!Z20+'AZAD KHASHMIR'!Z20+'KHYBER PAKHTUNKHWA'!Z20 -> 71 | AA20: =SUM(K20+M20+O20+Q20+S20+U20+W20+Y20) -> 579 | AB20: =SUM(L20+N20+P20+R20+T20+V20+X20+Z20) -> 562 | AC20: =SUM(AA20:AB20) -> 1141
A21: Extra Pulmonary, Bacteriologically Confermid | K21: =MPR!K21+KARACHI!K21+SINDH!K21+'GILGIT BALTISTAN'!K21+'AZAD KHASHMIR'!K21+'KHYBER PAKHTUNKHWA'!K21 -> 0 | L21: =MPR!L21+KARACHI!L21+SINDH!L21+'GILGIT BALTISTAN'!L21+'AZAD KHASHMIR'!L21+'KHYBER PAKHTUNKHWA'!L21 -> 0 | M21: =MPR!M21+KARACHI!M21+SINDH!M21+'GILGIT BALTISTAN'!M21+'AZAD KHASHMIR'!M21+'KHYBER PAKHTUNKHWA'!M21 -> 0 | N21: =MPR!N21+KARACHI!N21+SINDH!N21+'GILGIT BALTISTAN'!N21+'AZAD KHASHMIR'!N21+'KHYBER PAKHTUNKHWA'!N21 -> 0 | O21: =MPR!O21+KARACHI!O21+SINDH!O21+'GILGIT BALTISTAN'!O21+'AZAD KHASHMIR'!O21+'KHYBER PAKHTUNKHWA'!O21 -> 0 | P21: =MPR!P21+KARACHI!P21+SINDH!P21+'GILGIT BALTISTAN'!P21+'AZAD KHASHMIR'!P21+'KHYBER PAKHTUNKHWA'!P21 -> 1 | Q21: =MPR!Q21+KARACHI!Q21+SINDH!Q21+'GILGIT BALTISTAN'!Q21+'AZAD KHASHMIR'!Q21+'KHYBER PAKHTUNKHWA'!Q21 -> 0 | R21: =MPR!R21+KARACHI!R21+SINDH!R21+'GILGIT BALTISTAN'!R21+'AZAD KHASHMIR'!R21+'KHYBER PAKHTUNKHWA'!R21 -> 0 | ... Z21: =MPR!Z21+KARACHI!Z21+SINDH!Z21+'GILGIT BALTISTAN'!Z21+'AZAD KHASHMIR'!Z21+'KHYBER PAKHTUNKHWA'!Z21 -> 1 | AA21: =SUM(K21+M21+O21+Q21+S21+U21+W21+Y21) -> 0 | AB21: =SUM(L21+N21+P21+R21+T21+V21+X21+Z21) -> 3 | AC21: =SUM(AA21:AB21) -> 3
A22: Extra Pulmonary , Clinically Diagnosed | K22: =MPR!K22+KARACHI!K22+SINDH!K22+'GILGIT BALTISTAN'!K22+'AZAD KHASHMIR'!K22+'KHYBER PAKHTUNKHWA'!K22 -> 28 | L22: =MPR!L22+KARACHI!L22+SINDH!L22+'GILGIT BALTISTAN'!L22+'AZAD KHASHMIR'!L22+'KHYBER PAKHTUNKHWA'!L22 -> 17 | M22: =MPR!M22+KARACHI!M22+SINDH!M22+'GILGIT BALTISTAN'!M22+'AZAD KHASHMIR'!M22+'KHYBER PAKHTUNKHWA'!M22 -> 26 | N22: =MPR!N22+KARACHI!N22+SINDH!N22+'GILGIT BALTISTAN'!N22+'AZAD KHASHMIR'!N22+'KHYBER PAKHTUNKHWA'!N22 -> 33 | O22: =MPR!O22+KARACHI!O22+SINDH!O22+'GILGIT BALTISTAN'!O22+'AZAD KHASHMIR'!O22+'KHYBER PAKHTUNKHWA'!O22 -> 72 | P22: =MPR!P22+KARACHI!P22+SINDH!P22+'GILGIT BALTISTAN'!P22+'AZAD KHASHMIR'!P22+'KHYBER PAKHTUNKHWA'!P22 -> 68 | Q22: =MPR!Q22+KARACHI!Q22+SINDH!Q22+'GILGIT BALTISTAN'!Q22+'AZAD KHASHMIR'!Q22+'KHYBER PAKHTUNKHWA'!Q22 -> 60 | R22: =MPR!R22+KARACHI!R22+SINDH!R22+'GILGIT BALTISTAN'!R22+'AZAD KHASHMIR'!R22+'KHYBER PAKHTUNKHWA'!R22 -> 50 | ... Z22: =MPR!Z22+KARACHI!Z22+SINDH!Z22+'GILGIT BALTISTAN'!Z22+'AZAD KHASHMIR'!Z22+'KHYBER PAKHTUNKHWA'!Z22 -> 31 | AA22: =SUM(K22+M22+O22+Q22+S22+U22+W22+Y22) -> 363 | AB22: =SUM(L22+N22+P22+R22+T22+V22+X22+Z22) -> 293 | AC22: =SUM(AA22:AB22) -> 656
A23: Total | K23: =SUM(K19:K22) -> 179 | L23: =SUM(L19:L22) -> 145 | M23: =SUM(M19:M22) -> 78 | N23: =SUM(N19:N22) -> 120 | O23: =SUM(O19:O22) -> 226 | P23: =SUM(P19:P22) -> 278 | Q23: =SUM(Q19:Q22) -> 208 | R23: =SUM(R19:R22) -> 189 | ... AB23: =SUM(AB19:AB22) -> 1373 | AC23: =SUM(AA23:AB23) -> 2847
A25: Block 3: Presumptive TB Cases Identified Laboratory Diagnosis and use of WRD | N25: Block 4 : TB HIV Activities
A26: Total New OPD in Quarter | B26: No. of presumptive TB cases identified | D26: No. of Presumptive TB Patients tested Using | G26: Among Presumptive TB cases tested number reported B+ | K26: Among all registered number of B+ TB Cases | L26: Amoung All (N+R+UK) number tested by Gene Xpert | N26: No. of TB patients tested for HIV | Q26: TB Patients tested positive for HIV | T26: HIV positive TB Patients put on ART
B27: Total | C27: Through Community Referrals (LHWs) | D27: AFB | E27: Xp & AFB | F27: XP | G27: AFB | H27: AFB + Xpert | I27: Xpert | J27: G.Tot | N27: =MPR!N27+KARACHI!N27+SINDH!N27+'GILGIT BALTISTAN'!N27:P27+'AZAD KHASHMIR'!N27:P27+'KHYBER PAKHTUNKHWA'!N27:P27 -> 219 | Q27: =MPR!Q27+KARACHI!Q27+SINDH!Q27+'GILGIT BALTISTAN'!Q27:S27+'AZAD KHASHMIR'!Q27:S27+'KHYBER PAKHTUNKHWA'!Q27:S27 -> 3 | T27: =MPR!T27+KARACHI!T27+SINDH!T27+'GILGIT BALTISTAN'!T27:AC27+'AZAD KHASHMIR'!T27:AC27+'KHYBER PAKHTUNKHWA'!T27:AC27 -> 3
A28: =MPR!A28+KARACHI!A28+SINDH!A28+'GILGIT BALTISTAN'!A28:A32+'AZAD KHASHMIR'!A28:A32+'KHYBER PAKHTUNKHWA'!A28:A32 -> 470126 | B28: =MPR!B28+KARACHI!B28+SINDH!B28+'GILGIT BALTISTAN'!B28:B32+'AZAD KHASHMIR'!B28:B32+'KHYBER PAKHTUNKHWA'!B28:B32 -> 14463 | C28: =MPR!C28+KARACHI!C28+SINDH!C28+'GILGIT BALTISTAN'!C28:C32+'AZAD KHASHMIR'!C28:C32+'KHYBER PAKHTUNKHWA'!C28:C32 -> 2605 | D28: =MPR!D28+KARACHI!D28+SINDH!D28+'GILGIT BALTISTAN'!D28:D32+'AZAD KHASHMIR'!D28:D32+'KHYBER PAKHTUNKHWA'!D28:D32 -> 6749 | E28: =MPR!E28+KARACHI!E28+SINDH!E28+'GILGIT BALTISTAN'!E28:E32+'AZAD KHASHMIR'!E28:E32+'KHYBER PAKHTUNKHWA'!E28:E32 -> 1068 | F28: =MPR!F28+KARACHI!F28+SINDH!F28+'GILGIT BALTISTAN'!F28:F32+'AZAD KHASHMIR'!F28:F32+'KHYBER PAKHTUNKHWA'!F28:F32 -> 7423 | G28: =MPR!G28+KARACHI!G28+SINDH!G28+'GILGIT BALTISTAN'!G28:G32+'AZAD KHASHMIR'!G28:G32+'KHYBER PAKHTUNKHWA'!G28:G32 -> 830 | H28: =MPR!H28+KARACHI!H28+SINDH!H28+'GILGIT BALTISTAN'!H28:H32+'AZAD KHASHMIR'!H28:H32+'KHYBER PAKHTUNKHWA'!H28:H32 -> 94 | I28: =MPR!I28+KARACHI!I28+SINDH!I28+'GILGIT BALTISTAN'!I28:I32+'AZAD KHASHMIR'!I28:I32+'KHYBER PAKHTUNKHWA'!I28:I32 -> 123 | J28: =SUM(G28:I32) -> 1047 | K28: =MPR!K28+KARACHI!K28+SINDH!K28+'GILGIT BALTISTAN'!K28:K32+'AZAD KHASHMIR'!K28:K32+'KHYBER PAKHTUNKHWA'!K28:K32 -> 1022 | L28: =MPR!L28+KARACHI!L28+SINDH!L28+'GILGIT BALTISTAN'!L28:L32+'AZAD KHASHMIR'!L28:L32+'KHYBER PAKHTUNKHWA'!L28:L32 -> 1505 | N28: HIV patient tested for TB | Q28: HIV patients tested positive for TB | T28: TB positive HIV patients put on TB Tx | X28: HIV positive TB -Ve patients on TPT
N29: =MPR!N29+KARACHI!N29+SINDH!N29+'GILGIT BALTISTAN'!N29:P32+'AZAD KHASHMIR'!N29:P32+'KHYBER PAKHTUNKHWA'!N29:P32 -> 0 | Q29: =MPR!Q29+KARACHI!Q29+SINDH!Q29+'GILGIT BALTISTAN'!Q29:S32+'AZAD KHASHMIR'!Q29:S32+'KHYBER PAKHTUNKHWA'!Q29:S32 -> 0 | T29: =MPR!T29+KARACHI!T29+SINDH!T29+'GILGIT BALTISTAN'!T29:W32+'AZAD KHASHMIR'!T29:W32+'KHYBER PAKHTUNKHWA'!T29:W32 -> 0 | Y29: 0-4 | AA29: 5-14 | AB29: 15 & above
X30: 6H | Y30: =MPR!Y30+KARACHI!Y30+SINDH!Y30+'GILGIT BALTISTAN'!Y30:Z30+'AZAD KHASHMIR'!Y30:Z30+'KHYBER PAKHTUNKHWA'!Y30:Z30 -> 0 | AA30: =MPR!AA30+KARACHI!AA30+SINDH!AA30+'GILGIT BALTISTAN'!AA30+'AZAD KHASHMIR'!AA30+'KHYBER PAKHTUNKHWA'!AA30 -> 0 | AB30: =MPR!AB30+KARACHI!AB30+SINDH!AB30+'GILGIT BALTISTAN'!AB30:AC30+'AZAD KHASHMIR'!AB30:AC30+'KHYBER PAKHTUNKHWA'!AB30:AC30 -> 0
X31: 3HR | Y31: =MPR!Y31+KARACHI!Y31+SINDH!Y31+'GILGIT BALTISTAN'!Y31:Z31+'AZAD KHASHMIR'!Y31:Z31+'KHYBER PAKHTUNKHWA'!Y31:Z31 -> 0 | AA31: =MPR!AA31+KARACHI!AA31+SINDH!AA31+'GILGIT BALTISTAN'!AA31+'AZAD KHASHMIR'!AA31+'KHYBER PAKHTUNKHWA'!AA31 -> 0 | AB31: =MPR!AB31+KARACHI!AB31+SINDH!AB31+'GILGIT BALTISTAN'!AB31:AC31+'AZAD KHASHMIR'!AB31:AC31+'KHYBER PAKHTUNKHWA'!AB31:AC31 -> 0
X32: 3 HP | Y32: =MPR!Y32+KARACHI!Y32+SINDH!Y32+'GILGIT BALTISTAN'!Y32:Z32+'AZAD KHASHMIR'!Y32:Z32+'KHYBER PAKHTUNKHWA'!Y32:Z32 -> 0 | AA32: =MPR!AA32+KARACHI!AA32+SINDH!AA32+'GILGIT BALTISTAN'!AA32+'AZAD KHASHMIR'!AA32+'KHYBER PAKHTUNKHWA'!AA32 -> 0 | AB32: =MPR!AB32+KARACHI!AB32+SINDH!AB32+'GILGIT BALTISTAN'!AB32:AC32+'AZAD KHASHMIR'!AB32:AC32+'KHYBER PAKHTUNKHWA'!AB32:AC32 -> 0
A34: Block 5 : Bacteriologically Confermid TB Cases with DST Result | N34: Block 6 : Contact Tracing HH *
G35: Rifampicin | I35: Isoniazid | K35: Fluoroquninolone | N35: Total No. of HH of B+ PTB | Q35: No. of HH contacts of B+ PTB Cases Screened | T35: Amoung HH contact screened, No. of TB Cases diagnosed | W35: No. of HH Contacts Initiated on TPT | AA35: HIV negative Immuno compromised on TPT
G36: Result | H36: Resistant | I36: Result | J36: Resistant | K36: Result | L36: Resistant | N36: 0-4 | O36: 5-14 | P36: 15 + | Q36: 0-4 | R36: 5-14 | S36: 15 + | T36: 0-4 | U36: 5-14 | V36: 15 + | X36: 0-4 | Y36: 5-14 | Z36: 15+ | AA36: 0-4 | AB36: 5-14 | AC36: 15+
A37: New + UK | G37: =MPR!G37+KARACHI!G37+SINDH!G37+'GILGIT BALTISTAN'!G37+'AZAD KHASHMIR'!G37+'KHYBER PAKHTUNKHWA'!G37 -> 925 | H37: =MPR!H37+KARACHI!H37+SINDH!H37+'GILGIT BALTISTAN'!H37+'AZAD KHASHMIR'!H37+'KHYBER PAKHTUNKHWA'!H37 -> 2 | I37: =MPR!I37+KARACHI!I37+SINDH!I37+'GILGIT BALTISTAN'!I37+'AZAD KHASHMIR'!I37+'KHYBER PAKHTUNKHWA'!I37 -> 0 | J37: =MPR!J37+KARACHI!J37+SINDH!J37+'GILGIT BALTISTAN'!J37+'AZAD KHASHMIR'!J37+'KHYBER PAKHTUNKHWA'!J37 -> 0 | K37: =MPR!K37+KARACHI!K37+SINDH!K37+'GILGIT BALTISTAN'!K37+'AZAD KHASHMIR'!K37+'KHYBER PAKHTUNKHWA'!K37 -> 0 | L37: =MPR!L37+KARACHI!L37+SINDH!L37+'GILGIT BALTISTAN'!L37+'AZAD KHASHMIR'!L37+'KHYBER PAKHTUNKHWA'!L37 -> 0 | N37: =MPR!N37+KARACHI!N37+SINDH!N37+'GILGIT BALTISTAN'!N37:N40+'AZAD KHASHMIR'!N37:N40+'KHYBER PAKHTUNKHWA'!N37:N40 -> 80 | O37: =MPR!O37+KARACHI!O37+SINDH!O37+'GILGIT BALTISTAN'!O37:O40+'AZAD KHASHMIR'!O37:O40+'KHYBER PAKHTUNKHWA'!O37:O40 -> 1332 | P37: =MPR!P37+KARACHI!P37+SINDH!P37+'GILGIT BALTISTAN'!P37:P40+'AZAD KHASHMIR'!P37:P40+'KHYBER PAKHTUNKHWA'!P37:P40 -> 5042 | Q37: =MPR!Q37+KARACHI!Q37+SINDH!Q37+'GILGIT BALTISTAN'!Q37:Q40+'AZAD KHASHMIR'!Q37:Q40+'KHYBER PAKHTUNKHWA'!Q37:Q40 -> 29 | R37: =MPR!R37+KARACHI!R37+SINDH!R37+'GILGIT BALTISTAN'!R37:R40+'AZAD KHASHMIR'!R37:R40+'KHYBER PAKHTUNKHWA'!R37:R40 -> 727 | S37: =MPR!S37+KARACHI!S37+SINDH!S37+'GILGIT BALTISTAN'!S37:S40+'AZAD KHASHMIR'!S37:S40+'KHYBER PAKHTUNKHWA'!S37:S40 -> 4035 | T37: =MPR!T37+KARACHI!T37+SINDH!T37+'GILGIT BALTISTAN'!T37:T40+'AZAD KHASHMIR'!T37:T40+'KHYBER PAKHTUNKHWA'!T37:T40 -> 1 | U37: =MPR!U37+KARACHI!U37+SINDH!U37+'GILGIT BALTISTAN'!U37:U40+'AZAD KHASHMIR'!U37:U40+'KHYBER PAKHTUNKHWA'!U37:U40 -> 44 | V37: =MPR!V37+KARACHI!V37+SINDH!V37+'GILGIT BALTISTAN'!V37:V40+'AZAD KHASHMIR'!V37:V40+'KHYBER PAKHTUNKHWA'!V37:V40 -> 144 | W37: 6H | X37: =MPR!X37+KARACHI!X37+SINDH!X37+'GILGIT BALTISTAN'!X37+'AZAD KHASHMIR'!X37+'KHYBER PAKHTUNKHWA'!X37 -> 1 | Y37: =MPR!Y37+KARACHI!Y37+SINDH!Y37+'GILGIT BALTISTAN'!Y37+'AZAD KHASHMIR'!Y37+'KHYBER PAKHTUNKHWA'!Y37 -> 8 | Z37: =MPR!Z37+KARACHI!Z37+SINDH!Z37+'GILGIT BALTISTAN'!Z37+'AZAD KHASHMIR'!Z37+'KHYBER PAKHTUNKHWA'!Z37 -> 13 | AA37: =MPR!AA37+KARACHI!AA37+SINDH!AA37+'GILGIT BALTISTAN'!AA37+'AZAD KHASHMIR'!AA37+'KHYBER PAKHTUNKHWA'!AA37 -> 0 | AB37: =MPR!AB37+KARACHI!AB37+SINDH!AB37+'GILGIT BALTISTAN'!AB37+'AZAD KHASHMIR'!AB37+'KHYBER PAKHTUNKHWA'!AB37 -> 0 | AC37: =MPR!AC37+KARACHI!AC37+SINDH!AC37+'GILGIT BALTISTAN'!AC37+'AZAD KHASHMIR'!AC37+'KHYBER PAKHTUNKHWA'!AC37 -> 0
A38: Relapse | G38: =MPR!G38+KARACHI!G38+SINDH!G38+'GILGIT BALTISTAN'!G38+'AZAD KHASHMIR'!G38+'KHYBER PAKHTUNKHWA'!G38 -> 30 | H38: =MPR!H38+KARACHI!H38+SINDH!H38+'GILGIT BALTISTAN'!H38+'AZAD KHASHMIR'!H38+'KHYBER PAKHTUNKHWA'!H38 -> 0 | I38: =MPR!I38+KARACHI!I38+SINDH!I38+'GILGIT BALTISTAN'!I38+'AZAD KHASHMIR'!I38+'KHYBER PAKHTUNKHWA'!I38 -> 0 | J38: =MPR!J38+KARACHI!J38+SINDH!J38+'GILGIT BALTISTAN'!J38+'AZAD KHASHMIR'!J38+'KHYBER PAKHTUNKHWA'!J38 -> 0 | K38: =MPR!K38+KARACHI!K38+SINDH!K38+'GILGIT BALTISTAN'!K38+'AZAD KHASHMIR'!K38+'KHYBER PAKHTUNKHWA'!K38 -> 0 | L38: =MPR!L38+KARACHI!L38+SINDH!L38+'GILGIT BALTISTAN'!L38+'AZAD KHASHMIR'!L38+'KHYBER PAKHTUNKHWA'!L38 -> 0 | W38: 3HR | X38: =MPR!X38+KARACHI!X38+SINDH!X38+'GILGIT BALTISTAN'!X38+'AZAD KHASHMIR'!X38+'KHYBER PAKHTUNKHWA'!X38 -> 0 | Y38: =MPR!Y38+KARACHI!Y38+SINDH!Y38+'GILGIT BALTISTAN'!Y38+'AZAD KHASHMIR'!Y38+'KHYBER PAKHTUNKHWA'!Y38 -> 0 | Z38: =MPR!Z38+KARACHI!Z38+SINDH!Z38+'GILGIT BALTISTAN'!Z38+'AZAD KHASHMIR'!Z38+'KHYBER PAKHTUNKHWA'!Z38 -> 11 | AA38: =MPR!AA38+KARACHI!AA38+SINDH!AA38+'GILGIT BALTISTAN'!AA38+'AZAD KHASHMIR'!AA38+'KHYBER PAKHTUNKHWA'!AA38 -> 0 | AB38: =MPR!AB38+KARACHI!AB38+SINDH!AB38+'GILGIT BALTISTAN'!AB38+'AZAD KHASHMIR'!AB38+'KHYBER PAKHTUNKHWA'!AB38 -> 0 | AC38: =MPR!AC38+KARACHI!AC38+SINDH!AC38+'GILGIT BALTISTAN'!AC38+'AZAD KHASHMIR'!AC38+'KHYBER PAKHTUNKHWA'!AC38 -> 0
A39: Previously treated | G39: =MPR!G39+KARACHI!G39+SINDH!G39+'GILGIT BALTISTAN'!G39+'AZAD KHASHMIR'!G39+'KHYBER PAKHTUNKHWA'!G39 -> 3 | H39: =MPR!H39+KARACHI!H39+SINDH!H39+'GILGIT BALTISTAN'!H39+'AZAD KHASHMIR'!H39+'KHYBER PAKHTUNKHWA'!H39 -> 1 | I39: =MPR!I39+KARACHI!I39+SINDH!I39+'GILGIT BALTISTAN'!I39+'AZAD KHASHMIR'!I39+'KHYBER PAKHTUNKHWA'!I39 -> 0 | J39: =MPR!J39+KARACHI!J39+SINDH!J39+'GILGIT BALTISTAN'!J39+'AZAD KHASHMIR'!J39+'KHYBER PAKHTUNKHWA'!J39 -> 0 | K39: =MPR!K39+KARACHI!K39+SINDH!K39+'GILGIT BALTISTAN'!K39+'AZAD KHASHMIR'!K39+'KHYBER PAKHTUNKHWA'!K39 -> 0 | L39: =MPR!L39+KARACHI!L39+SINDH!L39+'GILGIT BALTISTAN'!L39+'AZAD KHASHMIR'!L39+'KHYBER PAKHTUNKHWA'!L39 -> 0 | W39: 3 HP | X39: =MPR!X39+KARACHI!X39+SINDH!X39+'GILGIT BALTISTAN'!X39:X40+'AZAD KHASHMIR'!X39:X40+'KHYBER PAKHTUNKHWA'!X39:X40 -> 0 | Y39: =MPR!Y39+KARACHI!Y39+SINDH!Y39+'GILGIT BALTISTAN'!Y39:Y40+'AZAD KHASHMIR'!Y39:Y40+'KHYBER PAKHTUNKHWA'!Y39:Y40 -> 8 | Z39: =MPR!Z39+KARACHI!Z39+SINDH!Z39+'GILGIT BALTISTAN'!Z39:Z40+'AZAD KHASHMIR'!Z39:Z40+'KHYBER PAKHTUNKHWA'!Z39:Z40 -> 40 | AA39: =MPR!AA39+KARACHI!AA39+SINDH!AA39+'GILGIT BALTISTAN'!AA39:AA40+'AZAD KHASHMIR'!AA39:AA40+'KHYBER PAKHTUNKHWA'!AA39:AA40 -> 0 | AB39: =MPR!AB39+KARACHI!AB39+SINDH!AB39+'GILGIT BALTISTAN'!AB39:AB40+'AZAD KHASHMIR'!AB39:AB40+'KHYBER PAKHTUNKHWA'!AB39:AB40 -> 0 | AC39: =MPR!AC39+KARACHI!AC39+SINDH!AC39+'GILGIT BALTISTAN'!AC39:AC40+'AZAD KHASHMIR'!AC39:AC40+'KHYBER PAKHTUNKHWA'!AC39:AC40 -> 0
A40: Total | G40: =SUM(G37:G39) -> 958 | H40: =SUM(H37:H39) -> 3 | I40: =SUM(I37:I39) -> 0 | J40: =SUM(J37:J39) -> 0 | K40: =SUM(K37:K39) -> 0 | L40: =SUM(L37:L39) -> 0
A41: QUARTERLY REPORT ON TB CASES REGISTRATION
A42: INDIVIDUAL/CONSOLIDATED (TICK ONE) | Y42: TB - 07
A43: Name of TB Care Facility (BMU) : | E43: =E4 -> All Project Total | I43: District : | K43: __________________ | M43: Central : | O43: CONSOLIDATED | T43: Patients registered during | Y43: 2nd Quarter | AB43: =AB4 -> of Year 2024
A45: Name of TB Coodinator/Facility incharge : | H45: ___________________________________________________ | T45: Date of completion of this form : | Z45: _______________________
A47: Block 1: | K47: New (N) | M47: Relapse ® | O47: Previous Treatment History Unknown (UK) | R47: N+R+UK | U47: Previously treated ( Excluding Relapse) | AB47: Total
A48: All TB Cases Registered | U48: Treatment after failure | X48: Treatment after lost to follow-up | Z48: Other previously treated
...
