Workbook
Name Print_Area_MI: #REF!
Name Print_Area_MI: #REF!

Sheet MPR
A2: QUARTERLY REPORT ON TB CASES REGISTRATION
A3: INDIVIDUAL/CONSOLIDATED (TICK ONE) | Z3: TB - 07
A4: Name of TB Care Facility (BMU) : | E4: KMC Leprosy Hospital | I4: District : | M4: Central : | O4: Manghopir | U4: Patients registered during | Z4: 1st Quarter | AC4: of Year 2026
A6: Name of TB Coodinator/Facility incharge : | I6: ___________________________________________________ | U6: Date of completion of this form : | AA6: _______________________
A8: Block 1: | L8: New (N) | N8: Relapse ® | P8: Previous Treatment History Unknown (UK) | S8: New episode (N+R+UK) | V8: Re - registered Cases ( Excluding Recurrent cases) | AC8: Total
A9: All TB Cases Registered | V9: Treatment after failure | Y9: Treatment after lost to follow-up | AA9: Other
A11: Pulmonary, Bacteriologically Confermid | L11: 0 | N11: 0 | P11: 0 | S11: 0 | V11: 0 | Y11: 0 | AA11: 0 | AC11: 0
A12: Pulmonary , Clinically Diagnosed | L12: 0 | N12: 0 | P12: 0 | S12: 0 | V12: 0 | Y12: 0 | AA12: 0 | AC12: 0
A13: Extra Pulmonary, Bacteriologically Confermid | L13: 0 | N13: 0 | P13: 0 | S13: 0 | V13: 0 | Y13: 0 | AA13: 0 | AC13: 0
A14: Extra Pulmonary , Clinically Diagnosed | L14: 0 | N14: 0 | P14: 0 | S14: 0 | V14: 0 | Y14: 0 | AA14: 0 | AC14: 0
A15: Total | L15: 0 | N15: 0 | P15: 0 | S15: 0 | V15: 0 | Y15: 0 | AA15: 0 | AC15: 0
A16: Block 2: All New, Relapse and previous treatment history unknown Cases registered during the period by Age Group and Gender
L17: 0-4 | N17: 5-14 | P17: 15-24 | R17: 25-34 | T17: 35-44 | V17: 45-54 | X17: 55-64 | Z17: 65 & Above | AB17: Total | AD17: Grand Total
L18: M | M18: F | N18: M | O18: F | P18: M | Q18: F | R18: M | S18: F | T18: M | U18: F | V18: M | W18: F | X18: M | Y18: F | Z18: M | AA18: F | AB18: M | AC18: F
A19: Pulmonary, Bacteriologically Confermid | L19: 0 | M19: 0 | N19: 0 | O19: 0 | P19: 0 | Q19: 0 | R19: 0 | S19: 0 | T19: 0 | U19: 0 | V19: 0 | W19: 0 | X19: 0 | Y19: 0 | Z19: 0 | AA19: 0 | AB19: 0 | AC19: 0 | AD19: 0
A20: Pulmonary , Clinically Diagnosed | L20: 0 | M20: 0 | N20: 0 | O20: 0 | P20: 0 | Q20: 0 | R20: 0 | S20: 0 | T20: 0 | U20: 0 | V20: 0 | W20: 0 | X20: 0 | Y20: 0 | Z20: 0 | AA20: 0 | AB20: 0 | AC20: 0 | AD20: 0
A21: Extra Pulmonary, Bacteriologically Confermid | L21: 0 | M21: 0 | N21: 0 | O21: 0 | P21: 0 | Q21: 0 | R21: 0 | S21: 0 | T21: 0 | U21: 0 | V21: 0 | W21: 0 | X21: 0 | Y21: 0 | Z21: 0 | AA21: 0 | AB21: 0 | AC21: 0 | AD21: 0
A22: Extra Pulmonary , Clinically Diagnosed | L22: 0 | M22: 0 | N22: 0 | O22: 0 | P22: 0 | Q22: 0 | R22: 0 | S22: 0 | T22: 0 | U22: 0 | V22: 0 | W22: 0 | X22: 0 | Y22: 0 | Z22: 0 | AA22: 0 | AB22: 0 | AC22: 0 | AD22: 0
A23: Total | L23: 0 | M23: 0 | N23: 0 | O23: 0 | P23: 0 | Q23: 0 | R23: 0 | S23: 0 | T23: 0 | U23: 0 | V23: 0 | W23: 0 | X23: 0 | Y23: 0 | Z23: 0 | AA23: 0 | AB23: 0 | AC23: 0 | AD23: 0
A25: Block 3: Presumptive TB Cases Identified Laboratory Diagnosis and use of WRD | O25: Block 4 : TB HIV Activities
A26: Total New OPD in Quarter | B26: No. of presumptive TB cases identified | D26: No. of Presumptive TB Patients tested Using | H26: Among Presumptive TB cases tested number reported B+ | L26: Among all registered number of B+ TB Cases | M26: Amoung All (N+R+UK) number tested by Gene Xpert | O26: No. of TB patients tested for HIV | S26: HIV Reactive | W26: TB Patients confirmed positive for HIV | AA26: HIV positive TB Patients put on ART
B27: Total | C27: Through Community Referrals (LHWs) | D27: AFB | E27: Xp & AFB | F27: XP | G27: G.Tot | H27: AFB | I27: AFB + Xpert | J27: Xpert | K27: G.Tot | O27: 0 | S27: 0 | W27: 0 | AA27: 0
A28: 0 | B28: 0 | C28: 0 | D28: 0 | E28: 0 | F28: 0 | G28: 0 | H28: 0 | I28: 0 | J28: 0 | K28: 0 | L28: 0 | M28: 0 | O28: HIV patient tested for TB | S28: HIV patients diagnosed for TB | W28: TB HIV patients put on TB Tx | AA28: HIV positive TB negative patients on TPT
O29: 0 | S29: 0 | W29: 0 | AB29: 0-4 | AC29: 5-14 | AD29: 15 +
AA30: 6H | AB30: 0 | AC30: 0 | AD30: 0
AA31: 3HR | AB31: 0 | AC31: 0 | AD31: 0
AA32: 3 HP | AB32: 0 | AC32: 0 | AD32: 0
A34: Block 5 : Bacteriologically Confermid TB Cases with DST Result | O34: Block 6 : Contact Tracing HH *
A35: Sensitive =S Resistance = R | B35: PTB | H35: EPTB | O35: Total No. of HH of B+ PTB | R35: No. of HH contacts of B+ PTB Cases Screened | U35: No. of TB Cases diagnosed Amoung HH contact screened | X35: No. of HH Contacts Initiated on TPT | AB35: HIV negative Immuno - compromised on TPT
B36: Rifampicin | D36: Isoniazid | F36: Fluoroquninolone | H36: Rifampicin | J36: Isoniazid | L36: Fluoroquninolone
B37: S | C37: R | D37: S | E37: R | F37: S | G37: R | H37: S | I37: R | J37: S | K37: R | L37: S | M37: R
A38: New + UK | B38: 0 | C38: 0 | D38: 0 | E38: 0 | F38: 0 | G38: 0 | H38: 0 | I38: 0 | J38: 0 | K38: 0 | L38: 0 | M38: 0 | Y38: 0-4 | Z38: 5-14 | AA38: 15+ | AB38: 0-4 | AC38: 5-14 | AD38: 15+
A39: Relapse | B39: 0 | C39: 0 | D39: 0 | E39: 0 | F39: 0 | G39: 0 | H39: 0 | I39: 0 | J39: 0 | K39: 0 | L39: 0 | M39: 0 | O39: 0-4 | P39: 5-14 | Q39: 15 + | R39: 0-4 | S39: 5-14 | T39: 15 + | U39: 0-4 | V39: 5-14 | W39: 15 + | X39: 6H | Y39: 0 | Z39: 0 | AA39: 0 | AB39: 0 | AC39: 0 | AD39: 0
A40: Previously treated | B40: 0 | C40: 0 | D40: 0 | E40: 0 | F40: 0 | G40: 0 | H40: 0 | I40: 0 | J40: 0 | K40: 0 | L40: 0 | M40: 0 | O40: 0 | P40: 0 | Q40: 0 | R40: 0 | S40: 0 | T40: 0 | U40: 0 | V40: 0 | W40: 0 | X40: 3HR | Y40: 0 | Z40: 0 | AA40: 0 | AB40: 0 | AC40: 0 | AD40: 0
A41: Total | B41: 0 | C41: 0 | D41: 0 | E41: 0 | F41: 0 | G41: 0 | H41: 0 | I41: 0 | J41: 0 | K41: 0 | L41: 0 | M41: 0 | X41: 3 HP | Y41: 0 | Z41: 0 | AA41: 0 | AB41: 0 | AC41: 0 | AD41: 0
A42: QUARTERLY REPORT ON TB CASES REGISTRATION
A43: INDIVIDUAL/CONSOLIDATED (TICK ONE) | Z43: TB - 07
A44: Name of TB Care Facility (BMU) : | E44: KMC Leprosy Hospital | I44: District : | K44: 0 | M44: Central : | O44: Manghopir | U44: Patients registered during | Z44: 2nd Quarter | AC44: of Year 2026
A46: Name of TB Coodinator/Facility incharge : | I46: ___________________________________________________ | U46: Date of completion of this form : | AA46: _______________________
A47: Block 1: | L47: New (N) | N47: Relapse ® | P47: Previous Treatment History Unknown (UK) | S47: New episode (N+R+UK) | V47: Re - registered Cases ( Excluding Recurrent cases) | AC47: Total
...

Sheet KARACHI
A2: QUARTERLY REPORT ON TB CASES REGISTRATION
A3: INDIVIDUAL/CONSOLIDATED (TICK ONE) | Z3: TB - 07
A4: Name of TB Care Facility (BMU) : | E4: KARACHI COMPLIED | I4: District : | M4: Central : | U4: Patients registered during | Z4: 1st Quarter | AC4: of Year 2026
A6: Name of TB Coodinator/Facility incharge : | I6: ___________________________________________________ | U6: Date of completion of this form : | AA6: _______________________
A8: Block 1: | L8: New (N) | N8: Relapse ® | P8: Previous Treatment History Unknown (UK) | S8: New episode (N+R+UK) | V8: Re - registered Cases ( Excluding Recurrent cases) | AC8: Total
A9: All TB Cases Registered | V9: Treatment after failure | Y9: Treatment after lost to follow-up | AA9: Other
A11: Pulmonary, Bacteriologically Confermid | L11: 79 | N11: 20 | P11: 0 | S11: 99 | V11: 0 | Y11: 3 | AA11: 5 | AC11: 107
A12: Pulmonary , Clinically Diagnosed | L12: 133 | N12: 17 | P12: 0 | S12: 150 | V12: 0 | Y12: 3 | AA12: 2 | AC12: 155
A13: Extra Pulmonary, Bacteriologically Confermid | L13: 1 | N13: 0 | P13: 0 | S13: 1 | V13: 0 | Y13: 0 | AA13: 1 | AC13: 2
A14: Extra Pulmonary , Clinically Diagnosed | L14: 70 | N14: 7 | P14: 0 | S14: 77 | V14: 0 | Y14: 1 | AA14: 4 | AC14: 82
A15: Total | L15: 283 | N15: 44 | P15: 0 | S15: 327 | V15: 0 | Y15: 7 | AA15: 12 | AC15: 346
A16: Block 2: All New, Relapse and previous treatment history unknown Cases registered during the period by Age Group and Gender
L17: 0-4 | N17: 5-14 | P17: 15-24 | R17: 25-34 | T17: 35-44 | V17: 45-54 | X17: 55-64 | Z17: 65 & Above | AB17: Total | AD17: Grand Total
L18: M | M18: F | N18: M | O18: F | P18: M | Q18: F | R18: M | S18: F | T18: M | U18: F | V18: M | W18: F | X18: M | Y18: F | Z18: M | AA18: F | AB18: M | AC18: F
A19: Pulmonary, Bacteriologically Confermid | L19: 0 | M19: 0 | N19: 0 | O19: 5 | P19: 9 | Q19: 26 | R19: 9 | S19: 11 | T19: 7 | U19: 6 | V19: 4 | W19: 7 | X19: 4 | Y19: 4 | Z19: 5 | AA19: 2 | AB19: 38 | AC19: 61 | AD19: 99
A20: Pulmonary , Clinically Diagnosed | L20: 1 | M20: 1 | N20: 4 | O20: 14 | P20: 17 | Q20: 17 | R20: 11 | S20: 13 | T20: 11 | U20: 8 | V20: 14 | W20: 6 | X20: 12 | Y20: 5 | Z20: 14 | AA20: 2 | AB20: 84 | AC20: 66 | AD20: 150
A21: Extra Pulmonary, Bacteriologically Confermid | L21: 0 | M21: 0 | N21: 0 | O21: 0 | P21: 0 | Q21: 0 | R21: 1 | S21: 0 | T21: 0 | U21: 0 | V21: 0 | W21: 0 | X21: 0 | Y21: 0 | Z21: 0 | AA21: 0 | AB21: 1 | AC21: 0 | AD21: 1
A22: Extra Pulmonary , Clinically Diagnosed | L22: 0 | M22: 1 | N22: 2 | O22: 7 | P22: 10 | Q22: 13 | R22: 7 | S22: 6 | T22: 2 | U22: 13 | V22: 3 | W22: 2 | X22: 3 | Y22: 2 | Z22: 4 | AA22: 2 | AB22: 31 | AC22: 46 | AD22: 77
A23: Total | L23: 1 | M23: 2 | N23: 6 | O23: 26 | P23: 36 | Q23: 56 | R23: 28 | S23: 30 | T23: 20 | U23: 27 | V23: 21 | W23: 15 | X23: 19 | Y23: 11 | Z23: 23 | AA23: 6 | AB23: 154 | AC23: 173 | AD23: 327
A25: Block 3: Presumptive TB Cases Identified Laboratory Diagnosis and use of WRD | O25: Block 4 : TB HIV Activities
A26: Total New OPD in Quarter | B26: No. of presumptive TB cases identified | D26: No. of Presumptive TB Patients tested Using | H26: Among Presumptive TB cases tested number reported B+ | L26: Among all registered number of B+ TB Cases | M26: Amoung All (N+R+UK) number tested by Gene Xpert | O26: No. of TB patients tested for HIV | S26: HIV Reactive | W26: TB Patients confirmed positive for HIV | AA26: HIV positive TB Patients put on ART
B27: Total | C27: Through Community Referrals (LHWs) | D27: AFB | E27: Xp & AFB | F27: XP | G27: G.Tot | H27: AFB | I27: AFB + Xpert | J27: Xpert | K27: G.Tot | O27: 190 | S27: 0 | W27: 0 | AA27: 0
A28: 5585 | B28: 672 | C28: 8 | D28: 138 | E28: 97 | F28: 342 | G28: 577 | H28: 6 | I28: 6 | J28: 79 | K28: 91 | L28: 88 | M28: 156 | O28: HIV patient tested for TB | S28: HIV patients diagnosed for TB | W28: TB HIV patients put on TB Tx | AA28: HIV positive TB negative patients on TPT
O29: 0 | S29: 0 | W29: 0 | AB29: 0-4 | AC29: 5-14 | AD29: 15 +
AA30: 6H | AB30: 0 | AC30: 0 | AD30: 0
AA31: 3HR | AB31: 0 | AC31: 0 | AD31: 0
AA32: 3 HP | AB32: 0 | AC32: 0 | AD32: 0
A34: Block 5 : Bacteriologically Confermid TB Cases with DST Result | O34: Block 6 : Contact Tracing HH *
A35: Sensitive =S Resistance = R | B35: PTB | H35: EPTB | O35: Total No. of HH of B+ PTB | R35: No. of HH contacts of B+ PTB Cases Screened | U35: No. of TB Cases diagnosed Amoung HH contact screened | X35: No. of HH Contacts Initiated on TPT | AB35: HIV negative Immuno - compromised on TPT
B36: Rifampicin | D36: Isoniazid | F36: Fluoroquninolone | H36: Rifampicin | J36: Isoniazid | L36: Fluoroquninolone
B37: S | C37: R | D37: S | E37: R | F37: S | G37: R | H37: S | I37: R | J37: S | K37: R | L37: S | M37: R
A38: New + UK | B38: 71 | C38: 0 | D38: 9 | E38: 0 | F38: 0 | G38: 0 | H38: 0 | I38: 0 | J38: 0 | K38: 0 | L38: 0 | M38: 0 | Y38: 0-4 | Z38: 5-14 | AA38: 15+ | AB38: 0-4 | AC38: 5-14 | AD38: 15+
A39: Relapse | B39: 20 | C39: 0 | D39: 0 | E39: 0 | F39: 0 | G39: 0 | H39: 0 | I39: 0 | J39: 0 | K39: 0 | L39: 0 | M39: 0 | O39: 0-4 | P39: 5-14 | Q39: 15 + | R39: 0-4 | S39: 5-14 | T39: 15 + | U39: 0-4 | V39: 5-14 | W39: 15 + | X39: 6H | Y39: 26 | Z39: 17 | AA39: 0 | AB39: 0 | AC39: 0 | AD39: 0
A40: Previously treated | B40: 2 | C40: 0 | D40: 0 | E40: 0 | F40: 0 | G40: 0 | H40: 0 | I40: 0 | J40: 0 | K40: 0 | L40: 0 | M40: 0 | O40: 49 | P40: 98 | Q40: 353 | R40: 38 | S40: 81 | T40: 247 | U40: 0 | V40: 1 | W40: 3 | X40: 3HR | Y40: 0 | Z40: 2 | AA40: 10 | AB40: 0 | AC40: 0 | AD40: 0
A41: Total | B41: 93 | C41: 0 | D41: 9 | E41: 0 | F41: 0 | G41: 0 | H41: 0 | I41: 0 | J41: 0 | K41: 0 | L41: 0 | M41: 0 | X41: 3 HP | Y41: 0 | Z41: 39 | AA41: 113 | AB41: 0 | AC41: 0 | AD41: 0
A42: QUARTERLY REPORT ON TB CASES REGISTRATION
A43: INDIVIDUAL/CONSOLIDATED (TICK ONE) | Z43: TB - 07
A44: Name of TB Care Facility (BMU) : | E44: KARACHI COMPLIED | I44: District : | K44: 0 | M44: Central : | O44: 0 | U44: Patients registered during | Z44: 2nd Quarter | AC44: of Year 2026
A46: Name of TB Coodinator/Facility incharge : | I46: ___________________________________________________ | U46: Date of completion of this form : | AA46: _______________________
A48: Block 1: | L48: New (N) | N48: Relapse ® | P48: Previous Treatment History Unknown (UK) | S48: New episode (N+R+UK) | V48: Re - registered Cases ( Excluding Recurrent cases) | AC48: Total
...

Sheet SINDH
A2: QUARTERLY REPORT ON TB CASES REGISTRATION
A3: INDIVIDUAL/CONSOLIDATED (TICK ONE) | Z3: TB - 07
A4: Name of TB Care Facility (BMU) : | E4: Consolidated | I4: District : | M4: Central : | O4: SINDH | U4: Patients registered during | Z4: 1st Quarter | AC4: of Year 2026
A6: Name of TB Coodinator/Facility incharge : | I6: ___________________________________________________ | U6: Date of completion of this form : | AA6: _______________________
A8: Block 1: | L8: New (N) | N8: Relapse ® | P8: Previous Treatment History Unknown (UK) | S8: New episode (N+R+UK) | V8: Re - registered Cases ( Excluding Recurrent cases) | AC8: Total
A9: All TB Cases Registered | V9: Treatment after failure | Y9: Treatment after lost to follow-up | AA9: Other
A11: Pulmonary, Bacteriologically Confermid | L11: 39 | N11: 9 | P11: 0 | S11: 48 | V11: 0 | Y11: 0 | AA11: 0 | AC11: 48
A12: Pulmonary , Clinically Diagnosed | L12: 3 | N12: 0 | P12: 0 | S12: 3 | V12: 0 | Y12: 0 | AA12: 0 | AC12: 3
A13: Extra Pulmonary, Bacteriologically Confermid | L13: 0 | N13: 0 | P13: 0 | S13: 0 | V13: 0 | Y13: 0 | AA13: 0 | AC13: 0
A14: Extra Pulmonary , Clinically Diagnosed | L14: 8 | N14: 0 | P14: 0 | S14: 8 | V14: 0 | Y14: 0 | AA14: 0 | AC14: 8
A15: Total | L15: 50 | N15: 9 | P15: 0 | S15: 59 | V15: 0 | Y15: 0 | AA15: 0 | AC15: 59
A16: Block 2: All New, Relapse and previous treatment history unknown Cases registered during the period by Age Group and Gender
L17: 0-4 | N17: 5-14 | P17: 15-24 | R17: 25-34 | T17: 35-44 | V17: 45-54 | X17: 55-64 | Z17: 65 & Above | AB17: Total | AD17: Grand Total
L18: M | M18: F | N18: M | O18: F | P18: M | Q18: F | R18: M | S18: F | T18: M | U18: F | V18: M | W18: F | X18: M | Y18: F | Z18: M | AA18: F | AB18: M | AC18: F
A19: Pulmonary, Bacteriologically Confermid | L19: 0 | M19: 0 | N19: 0 | O19: 0 | P19: 4 | Q19: 5 | R19: 7 | S19: 11 | T19: 3 | U19: 4 | V19: 8 | W19: 5 | X19: 1 | Y19: 0 | Z19: 0 | AA19: 0 | AB19: 23 | AC19: 25 | AD19: 48
A20: Pulmonary , Clinically Diagnosed | L20: 0 | M20: 0 | N20: 0 | O20: 0 | P20: 0 | Q20: 0 | R20: 0 | S20: 0 | T20: 0 | U20: 0 | V20: 1 | W20: 0 | X20: 1 | Y20: 1 | Z20: 0 | AA20: 0 | AB20: 2 | AC20: 1 | AD20: 3
A21: Extra Pulmonary, Bacteriologically Confermid | L21: 0 | M21: 0 | N21: 0 | O21: 0 | P21: 0 | Q21: 0 | R21: 0 | S21: 0 | T21: 0 | U21: 0 | V21: 0 | W21: 0 | X21: 0 | Y21: 0 | Z21: 0 | AA21: 0 | AB21: 0 | AC21: 0 | AD21: 0
A22: Extra Pulmonary , Clinically Diagnosed | L22: 0 | M22: 0 | N22: 0 | O22: 0 | P22: 1 | Q22: 0 | R22: 0 | S22: 2 | T22: 0 | U22: 1 | V22: 3 | W22: 1 | X22: 0 | Y22: 0 | Z22: 0 | AA22: 0 | AB22: 4 | AC22: 4 | AD22: 8
A23: Total | L23: 0 | M23: 0 | N23: 0 | O23: 0 | P23: 5 | Q23: 5 | R23: 7 | S23: 13 | T23: 3 | U23: 5 | V23: 12 | W23: 6 | X23: 2 | Y23: 1 | Z23: 0 | AA23: 0 | AB23: 29 | AC23: 30 | AD23: 59
A25: Block 3: Presumptive TB Cases Identified Laboratory Diagnosis and use of WRD | O25: Block 4 : TB HIV Activities
A26: Total New OPD in Quarter | B26: No. of presumptive TB cases identified | D26: No. of Presumptive TB Patients tested Using | H26: Among Presumptive TB cases tested number reported B+ | L26: Among all registered number of B+ TB Cases | M26: Amoung All (N+R+UK) number tested by Gene Xpert | O26: No. of TB patients tested for HIV | S26: HIV Reactive | W26: TB Patients confirmed positive for HIV | AA26: HIV positive TB Patients put on ART
B27: Total | C27: Through Community Referrals (LHWs) | D27: AFB | E27: Xp & AFB | F27: XP | G27: G.Tot | H27: AFB | I27: AFB + Xpert | J27: Xpert | K27: G.Tot | O27: 0 | S27: 0 | W27: 0 | AA27: 0
A28: 38039 | B28: 262 | C28: 0 | D28: 173 | E28: 92 | F28: 41 | G28: 306 | H28: 7 | I28: 33 | J28: 8 | K28: 48 | L28: 48 | M28: 33 | O28: HIV patient tested for TB | S28: HIV patients diagnosed for TB | W28: TB HIV patients put on TB Tx | AA28: HIV positive TB negative patients on TPT
O29: 12 | S29: 0 | W29: 0 | AB29: 0-4 | AC29: 5-14 | AD29: 15 +
AA30: 6H | AB30: 0 | AC30: 0 | AD30: 0
AA31: 3HR | AB31: 0 | AC31: 0 | AD31: 0
AA32: 3 HP | AB32: 0 | AC32: 0 | AD32: 0
A34: Block 5 : Bacteriologically Confermid TB Cases with DST Result | O34: Block 6 : Contact Tracing HH *
A35: Sensitive =S Resistance = R | B35: PTB | H35: EPTB | O35: Total No. of HH of B+ PTB | R35: No. of HH contacts of B+ PTB Cases Screened | U35: No. of TB Cases diagnosed Amoung HH contact screened | X35: No. of HH Contacts Initiated on TPT | AB35: HIV negative Immuno - compromised on TPT
B36: Rifampicin | D36: Isoniazid | F36: Fluoroquninolone | H36: Rifampicin | J36: Isoniazid | L36: Fluoroquninolone
B37: S | C37: R | D37: S | E37: R | F37: S | G37: R | H37: S | I37: R | J37: S | K37: R | L37: S | M37: R
A38: New + UK | B38: 27 | C38: 2 | D38: 0 | E38: 0 | F38: 0 | G38: 0 | H38: 0 | I38: 0 | J38: 0 | K38: 0 | L38: 0 | M38: 0 | Y38: 0-4 | Z38: 5-14 | AA38: 15+ | AB38: 0-4 | AC38: 5-14 | AD38: 15+
A39: Relapse | B39: 6 | C39: 0 | D39: 0 | E39: 0 | F39: 0 | G39: 0 | H39: 0 | I39: 0 | J39: 0 | K39: 0 | L39: 0 | M39: 0 | O39: 0-4 | P39: 5-14 | Q39: 15 + | R39: 0-4 | S39: 5-14 | T39: 15 + | U39: 0-4 | V39: 5-14 | W39: 15 + | X39: 6H | Y39: 0 | Z39: 0 | AA39: 0 | AB39: 0 | AC39: 0 | AD39: 0
A40: Previously treated | B40: 0 | C40: 0 | D40: 0 | E40: 0 | F40: 0 | G40: 0 | H40: 0 | I40: 0 | J40: 0 | K40: 0 | L40: 0 | M40: 0 | O40: 0 | P40: 0 | Q40: 0 | R40: 0 | S40: 0 | T40: 0 | U40: 0 | V40: 0 | W40: 0 | X40: 3HR | Y40: 0 | Z40: 0 | AA40: 0 | AB40: 0 | AC40: 0 | AD40: 0
A41: Total | B41: 33 | C41: 2 | D41: 0 | E41: 0 | F41: 0 | G41: 0 | H41: 0 | I41: 0 | J41: 0 | K41: 0 | L41: 0 | M41: 0 | X41: 3 HP | Y41: 0 | Z41: 0 | AA41: 0 | AB41: 0 | AC41: 0 | AD41: 0
A42: QUARTERLY REPORT ON TB CASES REGISTRATION
A43: INDIVIDUAL/CONSOLIDATED (TICK ONE) | Z43: TB - 07
A44: Name of TB Care Facility (BMU) : | E44: Consolidated | I44: District : | K44: 0 | M44: Central : | O44: SINDH | U44: Patients registered during | Z44: 2nd Quarter | AC44: of Year 2026
A46: Name of TB Coodinator/Facility incharge : | I46: ___________________________________________________ | U46: Date of completion of this form : | AA46: _______________________
A48: Block 1: | L48: New (N) | N48: Relapse ® | P48: Previous Treatment History Unknown (UK) | S48: New episode (N+R+UK) | V48: Re - registered Cases ( Excluding Recurrent cases) | AC48: Total
...

Sheet GILGIT BALTISTAN
A2: QUARTERLY REPORT ON TB CASES REGISTRATION
A3: INDIVIDUAL/CONSOLIDATED (TICK ONE) | Z3: TB - 07
A4: Name of TB Care Facility (BMU) : | E4: GB - Consolidated | I4: District : | M4: Central : | O4: Gilgit Baltistan | U4: Patients registered during | Z4: 1st Quarter | AC4: of Year 2026
A6: Name of TB Coodinator/Facility incharge : | I6: ___________________________________________________ | U6: Date of completion of this form : | AA6: _______________________
A8: Block 1: | L8: New (N) | N8: Relapse ® | P8: Previous Treatment History Unknown (UK) | S8: New episode (N+R+UK) | V8: Re - registered Cases ( Excluding Recurrent cases) | AC8: Total
A9: All TB Cases Registered | V9: Treatment after failure | Y9: Treatment after lost to follow-up | AA9: Other
A11: Pulmonary, Bacteriologically Confermid | L11: 149 | N11: 2 | P11: 0 | S11: 151 | V11: 0 | Y11: 0 | AA11: 0 | AC11: 151
A12: Pulmonary , Clinically Diagnosed | L12: 626 | N12: 2 | P12: 2 | S12: 630 | V12: 0 | Y12: 0 | AA12: 0 | AC12: 630
A13: Extra Pulmonary, Bacteriologically Confermid | L13: 1 | N13: 0 | P13: 0 | S13: 1 | V13: 0 | Y13: 0 | AA13: 0 | AC13: 1
A14: Extra Pulmonary , Clinically Diagnosed | L14: 323 | N14: 0 | P14: 0 | S14: 323 | V14: 0 | Y14: 0 | AA14: 0 | AC14: 323
A15: Total | L15: 1099 | N15: 4 | P15: 2 | S15: 1105 | V15: 0 | Y15: 0 | AA15: 0 | AC15: 1105
A16: Block 2: All New, Relapse and previous treatment history unknown Cases registered during the period by Age Group and Gender
L17: 0-4 | N17: 5-14 | P17: 15-24 | R17: 25-34 | T17: 35-44 | V17: 45-54 | X17: 55-64 | Z17: 65 & Above | AB17: Total | AD17: Grand Total
L18: M | M18: F | N18: M | O18: F | P18: M | Q18: F | R18: M | S18: F | T18: M | U18: F | V18: M | W18: F | X18: M | Y18: F | Z18: M | AA18: F | AB18: M | AC18: F
A19: Pulmonary, Bacteriologically Confermid | L19: 0 | M19: 0 | N19: 3 | O19: 3 | P19: 13 | Q19: 22 | R19: 19 | S19: 12 | T19: 4 | U19: 10 | V19: 6 | W19: 11 | X19: 9 | Y19: 14 | Z19: 16 | AA19: 9 | AB19: 70 | AC19: 81 | AD19: 151
A20: Pulmonary , Clinically Diagnosed | L20: 184 | M20: 151 | N20: 54 | O20: 36 | P20: 24 | Q20: 25 | R20: 16 | S20: 26 | T20: 19 | U20: 21 | V20: 12 | W20: 18 | X20: 12 | Y20: 8 | Z20: 14 | AA20: 10 | AB20: 335 | AC20: 295 | AD20: 630
A21: Extra Pulmonary, Bacteriologically Confermid | L21: 0 | M21: 0 | N21: 0 | O21: 0 | P21: 0 | Q21: 0 | R21: 0 | S21: 0 | T21: 0 | U21: 0 | V21: 0 | W21: 1 | X21: 0 | Y21: 0 | Z21: 0 | AA21: 0 | AB21: 0 | AC21: 1 | AD21: 1
A22: Extra Pulmonary , Clinically Diagnosed | L22: 72 | M22: 77 | N22: 22 | O22: 11 | P22: 20 | Q22: 19 | R22: 16 | S22: 12 | T22: 10 | U22: 9 | V22: 11 | W22: 10 | X22: 13 | Y22: 5 | Z22: 10 | AA22: 6 | AB22: 174 | AC22: 149 | AD22: 323
A23: Total | L23: 256 | M23: 228 | N23: 79 | O23: 50 | P23: 57 | Q23: 66 | R23: 51 | S23: 50 | T23: 33 | U23: 40 | V23: 29 | W23: 40 | X23: 34 | Y23: 27 | Z23: 40 | AA23: 25 | AB23: 579 | AC23: 526 | AD23: 1105
A25: Block 3: Presumptive TB Cases Identified Laboratory Diagnosis and use of WRD | O25: Block 4 : TB HIV Activities
A26: Total New OPD in Quarter | B26: No. of presumptive TB cases identified | D26: No. of Presumptive TB Patients tested Using | H26: Among Presumptive TB cases tested number reported B+ | L26: Among all registered number of B+ TB Cases | M26: Amoung All (N+R+UK) number tested by Gene Xpert | O26: No. of TB patients tested for HIV | S26: HIV Reactive | W26: TB Patients confirmed positive for HIV | AA26: HIV positive TB Patients put on ART
B27: Total | C27: Through Community Referrals (LHWs) | D27: AFB | E27: Xp & AFB | F27: XP | G27: G.Tot | H27: AFB | I27: AFB + Xpert | J27: Xpert | K27: G.Tot | O27: 413 | S27: 4 | W27: 0 | AA27: 0
A28: 327076 | B28: 3820 | C28: 495 | D28: 482 | E28: 185 | F28: 2317 | G28: 2984 | H28: 21 | I28: 12 | J28: 145 | K28: 178 | L28: 146 | M28: 170 | O28: HIV patient tested for TB | S28: HIV patients diagnosed for TB | W28: TB HIV patients put on TB Tx | AA28: HIV positive TB negative patients on TPT
O29: 15 | S29: 0 | W29: 0 | AB29: 0-4 | AC29: 5-14 | AD29: 15 +
AA30: 6H | AB30: 0 | AC30: 0 | AD30: 0
AA31: 3HR | AB31: 0 | AC31: 0 | AD31: 0
AA32: 3 HP | AB32: 0 | AC32: 0 | AD32: 0
A34: Block 5 : Bacteriologically Confermid TB Cases with DST Result | O34: Block 6 : Contact Tracing HH *
A35: Sensitive =S Resistance = R | B35: PTB | H35: EPTB | O35: Total No. of HH of B+ PTB | R35: No. of HH contacts of B+ PTB Cases Screened | U35: No. of TB Cases diagnosed Amoung HH contact screened | X35: No. of HH Contacts Initiated on TPT | AB35: HIV negative Immuno - compromised on TPT
B36: Rifampicin | D36: Isoniazid | F36: Fluoroquninolone | H36: Rifampicin | J36: Isoniazid | L36: Fluoroquninolone
B37: S | C37: R | D37: S | E37: R | F37: S | G37: R | H37: S | I37: R | J37: S | K37: R | L37: S | M37: R
A38: New + UK | B38: 87 | C38: 1 | D38: 0 | E38: 0 | F38: 0 | G38: 0 | H38: 0 | I38: 0 | J38: 0 | K38: 0 | L38: 0 | M38: 0 | Y38: 0-4 | Z38: 5-14 | AA38: 15+ | AB38: 0-4 | AC38: 5-14 | AD38: 15+
A39: Relapse | B39: 2 | C39: 0 | D39: 0 | E39: 0 | F39: 0 | G39: 0 | H39: 0 | I39: 0 | J39: 0 | K39: 0 | L39: 0 | M39: 0 | O39: 0-4 | P39: 5-14 | Q39: 15 + | R39: 0-4 | S39: 5-14 | T39: 15 + | U39: 0-4 | V39: 5-14 | W39: 15 + | X39: 6H | Y39: 2 | Z39: 0 | AA39: 0 | AB39: 0 | AC39: 0 | AD39: 0
A40: Previously treated | B40: 0 | C40: 0 | D40: 0 | E40: 0 | F40: 0 | G40: 0 | H40: 0 | I40: 0 | J40: 0 | K40: 0 | L40: 0 | M40: 0 | O40: 30 | P40: 133 | Q40: 481 | R40: 23 | S40: 101 | T40: 267 | U40: 0 | V40: 1 | W40: 2 | X40: 3HR | Y40: 0 | Z40: 0 | AA40: 0 | AB40: 0 | AC40: 0 | AD40: 0
A41: Total | B41: 89 | C41: 1 | D41: 0 | E41: 0 | F41: 0 | G41: 0 | H41: 0 | I41: 0 | J41: 0 | K41: 0 | L41: 0 | M41: 0 | X41: 3 HP | Y41: 0 | Z41: 9 | AA41: 78 | AB41: 0 | AC41: 0 | AD41: 0
A42: QUARTERLY REPORT ON TB CASES REGISTRATION
A43: INDIVIDUAL/CONSOLIDATED (TICK ONE) | Z43: TB - 07
A44: Name of TB Care Facility (BMU) : | E44: GB - Consolidated | I44: District : | K44: 0 | M44: Central : | O44: Gilgit Baltistan | U44: Patients registered during | Z44: 2nd Quarter | AC44: of Year 2026
A46: Name of TB Coodinator/Facility incharge : | I46: ___________________________________________________ | U46: Date of completion of this form : | AA46: _______________________
A48: Block 1: | L48: New (N) | N48: Relapse ® | P48: Previous Treatment History Unknown (UK) | S48: New episode (N+R+UK) | V48: Re - registered Cases ( Excluding Recurrent cases) | AC48: Total
...

Sheet AZAD KHASHMIR
A2: QUARTERLY REPORT ON TB CASES REGISTRATION
A3: INDIVIDUAL/CONSOLIDATED (TICK ONE) | Z3: TB - 07
A4: Name of TB Care Facility (BMU) : | E4: Consolidated | I4: District : | M4: Central : | O4: Azad Kashmir | U4: Patients registered during | Z4: 1st Quarter | AC4: of Year 2026
A6: Name of TB Coodinator/Facility incharge : | I6: ___________________________________________________ | U6: Date of completion of this form : | AA6: _______________________
A8: Block 1: | L8: New (N) | N8: Relapse ® | P8: Previous Treatment History Unknown (UK) | S8: New episode (N+R+UK) | V8: Re - registered Cases ( Excluding Recurrent cases) | AC8: Total
A9: All TB Cases Registered | V9: Treatment after failure | Y9: Treatment after lost to follow-up | AA9: Other
A11: Pulmonary, Bacteriologically Confermid | L11: 516 | N11: 63 | P11: 1 | S11: 580 | V11: 0 | Y11: 0 | AA11: 0 | AC11: 580
A12: Pulmonary , Clinically Diagnosed | L12: 419 | N12: 9 | P12: 0 | S12: 428 | V12: 0 | Y12: 0 | AA12: 0 | AC12: 428
A13: Extra Pulmonary, Bacteriologically Confermid | L13: 3 | N13: 0 | P13: 0 | S13: 3 | V13: 0 | Y13: 0 | AA13: 0 | AC13: 3
A14: Extra Pulmonary , Clinically Diagnosed | L14: 321 | N14: 3 | P14: 0 | S14: 324 | V14: 0 | Y14: 0 | AA14: 0 | AC14: 324
A15: Total | L15: 1259 | N15: 75 | P15: 1 | S15: 1335 | V15: 0 | Y15: 0 | AA15: 0 | AC15: 1335
A16: Block 2: All New, Relapse and previous treatment history unknown Cases registered during the period by Age Group and Gender
L17: 0-4 | N17: 5-14 | P17: 15-24 | R17: 25-34 | T17: 35-44 | V17: 45-54 | X17: 55-64 | Z17: 65 & Above | AB17: Total | AD17: Grand Total
L18: M | M18: F | N18: M | O18: F | P18: M | Q18: F | R18: M | S18: F | T18: M | U18: F | V18: M | W18: F | X18: M | Y18: F | Z18: M | AA18: F | AB18: M | AC18: F
A19: Pulmonary, Bacteriologically Confermid | L19: 0 | M19: 0 | N19: 5 | O19: 7 | P19: 31 | Q19: 50 | R19: 50 | S19: 37 | T19: 29 | U19: 29 | V19: 45 | W19: 34 | X19: 63 | Y19: 35 | Z19: 91 | AA19: 62 | AB19: 314 | AC19: 254 | AD19: 568
A20: Pulmonary , Clinically Diagnosed | L20: 4 | M20: 2 | N20: 7 | O20: 8 | P20: 35 | Q20: 23 | R20: 23 | S20: 28 | T20: 27 | U20: 20 | V20: 20 | W20: 18 | X20: 48 | Y20: 40 | Z20: 54 | AA20: 65 | AB20: 218 | AC20: 204 | AD20: 422
A21: Extra Pulmonary, Bacteriologically Confermid | L21: 0 | M21: 0 | N21: 0 | O21: 0 | P21: 0 | Q21: 1 | R21: 1 | S21: 2 | T21: 0 | U21: 1 | V21: 2 | W21: 0 | X21: 1 | Y21: 0 | Z21: 1 | AA21: 2 | AB21: 5 | AC21: 6 | AD21: 11
A22: Extra Pulmonary , Clinically Diagnosed | L22: 3 | M22: 2 | N22: 2 | O22: 10 | P22: 23 | Q22: 24 | R22: 34 | S22: 31 | T22: 22 | U22: 28 | V22: 35 | W22: 25 | X22: 29 | Y22: 26 | Z22: 35 | AA22: 29 | AB22: 183 | AC22: 175 | AD22: 358
A23: Total | L23: 7 | M23: 4 | N23: 14 | O23: 25 | P23: 89 | Q23: 98 | R23: 108 | S23: 98 | T23: 78 | U23: 78 | V23: 102 | W23: 77 | X23: 141 | Y23: 101 | Z23: 181 | AA23: 158 | AB23: 720 | AC23: 639 | AD23: 1359
A25: Block 3: Presumptive TB Cases Identified Laboratory Diagnosis and use of WRD | O25: Block 4 : TB HIV Activities
A26: Total New OPD in Quarter | B26: No. of presumptive TB cases identified | D26: No. of Presumptive TB Patients tested Using | H26: Among Presumptive TB cases tested number reported B+ | L26: Among all registered number of B+ TB Cases | M26: Amoung All (N+R+UK) number tested by Gene Xpert | O26: No. of TB patients tested for HIV | S26: HIV Reactive | W26: TB Patients confirmed positive for HIV | AA26: HIV positive TB Patients put on ART
B27: Total | C27: Through Community Referrals (LHWs) | D27: AFB | E27: Xp & AFB | F27: XP | G27: G.Tot | H27: AFB | I27: AFB + Xpert | J27: Xpert | K27: G.Tot | O27: 496 | S27: 0 | W27: 0 | AA27: 0
A28: 271305 | B28: 9915 | C28: 889 | D28: 2099 | E28: 1206 | F28: 5177 | G28: 8482 | H28: 30 | I28: 235 | J28: 328 | K28: 593 | L28: 579 | M28: 814 | O28: HIV patient tested for TB | S28: HIV patients diagnosed for TB | W28: TB HIV patients put on TB Tx | AA28: HIV positive TB negative patients on TPT
O29: 0 | S29: 0 | W29: 0 | AB29: 0-4 | AC29: 5-14 | AD29: 15 +
AA30: 6H | AB30: 0 | AC30: 0 | AD30: 0
AA31: 3HR | AB31: 0 | AC31: 0 | AD31: 0
AA32: 3 HP | AB32: 0 | AC32: 0 | AD32: 0
A34: Block 5 : Bacteriologically Confermid TB Cases with DST Result | O34: Block 6 : Contact Tracing HH *
A35: Sensitive =S Resistance = R | B35: PTB | H35: EPTB | O35: Total No. of HH of B+ PTB | R35: No. of HH contacts of B+ PTB Cases Screened | U35: No. of TB Cases diagnosed Amoung HH contact screened | X35: No. of HH Contacts Initiated on TPT | AB35: HIV negative Immuno - compromised on TPT
B36: Rifampicin | D36: Isoniazid | F36: Fluoroquninolone | H36: Rifampicin | J36: Isoniazid | L36: Fluoroquninolone
B37: S | C37: R | D37: S | E37: R | F37: S | G37: R | H37: S | I37: R | J37: S | K37: R | L37: S | M37: R
A38: New + UK | B38: 518 | C38: 0 | D38: 0 | E38: 0 | F38: 0 | G38: 0 | H38: 1 | I38: 0 | J38: 0 | K38: 0 | L38: 0 | M38: 0 | Y38: 0-4 | Z38: 5-14 | AA38: 15+ | AB38: 0-4 | AC38: 5-14 | AD38: 15+
A39: Relapse | B39: 43 | C39: 0 | D39: 0 | E39: 0 | F39: 0 | G39: 0 | H39: 0 | I39: 0 | J39: 0 | K39: 0 | L39: 0 | M39: 0 | O39: 0-4 | P39: 5-14 | Q39: 15 + | R39: 0-4 | S39: 5-14 | T39: 15 + | U39: 0-4 | V39: 5-14 | W39: 15 + | X39: 6H | Y39: 0 | Z39: 0 | AA39: 0 | AB39: 0 | AC39: 0 | AD39: 0
A40: Previously treated | B40: 0 | C40: 0 | D40: 0 | E40: 0 | F40: 0 | G40: 0 | H40: 0 | I40: 0 | J40: 0 | K40: 0 | L40: 0 | M40: 0 | O40: 320 | P40: 839 | Q40: 2428 | R40: 226 | S40: 717 | T40: 2270 | U40: 1 | V40: 3 | W40: 140 | X40: 3HR | Y40: 0 | Z40: 0 | AA40: 28 | AB40: 0 | AC40: 0 | AD40: 0
A41: Total | B41: 561 | C41: 0 | D41: 0 | E41: 0 | F41: 0 | G41: 0 | H41: 1 | I41: 0 | J41: 0 | K41: 0 | L41: 0 | M41: 0 | X41: 3 HP | Y41: 0 | Z41: 0 | AA41: 0 | AB41: 0 | AC41: 0 | AD41: 0
A42: QUARTERLY REPORT ON TB CASES REGISTRATION
A43: INDIVIDUAL/CONSOLIDATED (TICK ONE) | Z43: TB - 07
A44: Name of TB Care Facility (BMU) : | E44: Consolidated | I44: District : | K44: 0 | M44: Central : | O44: Azad Kashmir | U44: Patients registered during | Z44: 2nd Quarter | AC44: of Year 2026
A46: Name of TB Coodinator/Facility incharge : | I46: ___________________________________________________ | U46: Date of completion of this form : | AA46: _______________________
A48: Block 1: | L48: New (N) | N48: Relapse ® | P48: Previous Treatment History Unknown (UK) | S48: New episode (N+R+UK) | V48: Re - registered Cases ( Excluding Recurrent cases) | AC48: Total
...

Sheet KHYBER PAKHTUNKHWA
A2: QUARTERLY REPORT ON TB CASES REGISTRATION
A3: INDIVIDUAL/CONSOLIDATED (TICK ONE) | Z3: TB - 07
A4: Name of TB Care Facility (BMU) : | E4: Consolidated | I4: District : | M4: Central : | O4: Khyber Pakhtunkhwa | U4: Patients registered during | Z4: 1st Quarter | AC4: of Year 2026
A6: Name of TB Coodinator/Facility incharge : | I6: ___________________________________________________ | U6: Date of completion of this form : | AA6: _______________________
A8: Block 1: | L8: New (N) | N8: Relapse ® | P8: Previous Treatment History Unknown (UK) | S8: New episode (N+R+UK) | V8: Re - registered Cases ( Excluding Recurrent cases) | AC8: Total
A9: All TB Cases Registered | V9: Treatment after failure | Y9: Treatment after lost to follow-up | AA9: Other
A11: Pulmonary, Bacteriologically Confermid | L11: 29 | N11: 2 | P11: 0 | S11: 31 | V11: 0 | Y11: 0 | AA11: 0 | AC11: 31
A12: Pulmonary , Clinically Diagnosed | L12: 23 | N12: 0 | P12: 0 | S12: 23 | V12: 0 | Y12: 0 | AA12: 0 | AC12: 23
A13: Extra Pulmonary, Bacteriologically Confermid | L13: 0 | N13: 0 | P13: 0 | S13: 0 | V13: 0 | Y13: 0 | AA13: 0 | AC13: 0
A14: Extra Pulmonary , Clinically Diagnosed | L14: 46 | N14: 0 | P14: 0 | S14: 46 | V14: 0 | Y14: 0 | AA14: 0 | AC14: 46
A15: Total | L15: 98 | N15: 2 | P15: 0 | S15: 100 | V15: 0 | Y15: 0 | AA15: 0 | AC15: 100
A16: Block 2: All New, Relapse and previous treatment history unknown Cases registered during the period by Age Group and Gender
L17: 0-4 | N17: 5-14 | P17: 15-24 | R17: 25-34 | T17: 35-44 | V17: 45-54 | X17: 55-64 | Z17: 65 & Above | AB17: Total | AD17: Grand Total
L18: M | M18: F | N18: M | O18: F | P18: M | Q18: F | R18: M | S18: F | T18: M | U18: F | V18: M | W18: F | X18: M | Y18: F | Z18: M | AA18: F | AB18: M | AC18: F
A19: Pulmonary, Bacteriologically Confermid | L19: 0 | M19: 0 | N19: 1 | O19: 1 | P19: 2 | Q19: 5 | R19: 1 | S19: 1 | T19: 3 | U19: 0 | V19: 1 | W19: 5 | X19: 1 | Y19: 2 | Z19: 4 | AA19: 4 | AB19: 13 | AC19: 18 | AD19: 31
A20: Pulmonary , Clinically Diagnosed | L20: 0 | M20: 0 | N20: 0 | O20: 2 | P20: 3 | Q20: 1 | R20: 2 | S20: 3 | T20: 2 | U20: 1 | V20: 1 | W20: 2 | X20: 3 | Y20: 1 | Z20: 1 | AA20: 1 | AB20: 12 | AC20: 11 | AD20: 23
A21: Extra Pulmonary, Bacteriologically Confermid | L21: 0 | M21: 0 | N21: 0 | O21: 0 | P21: 0 | Q21: 0 | R21: 0 | S21: 0 | T21: 0 | U21: 0 | V21: 0 | W21: 0 | X21: 0 | Y21: 0 | Z21: 0 | AA21: 0 | AB21: 0 | AC21: 0 | AD21: 0
A22: Extra Pulmonary , Clinically Diagnosed | L22: 2 | M22: 0 | N22: 6 | O22: 6 | P22: 5 | Q22: 5 | R22: 3 | S22: 4 | T22: 2 | U22: 1 | V22: 6 | W22: 0 | X22: 2 | Y22: 1 | Z22: 1 | AA22: 2 | AB22: 27 | AC22: 19 | AD22: 46
A23: Total | L23: 2 | M23: 0 | N23: 7 | O23: 9 | P23: 10 | Q23: 11 | R23: 6 | S23: 8 | T23: 7 | U23: 2 | V23: 8 | W23: 7 | X23: 6 | Y23: 4 | Z23: 6 | AA23: 7 | AB23: 52 | AC23: 48 | AD23: 100
A25: Block 3: Presumptive TB Cases Identified Laboratory Diagnosis and use of WRD | O25: Block 4 : TB HIV Activities
A26: Total New OPD in Quarter | B26: No. of presumptive TB cases identified | D26: No. of Presumptive TB Patients tested Using | H26: Among Presumptive TB cases tested number reported B+ | L26: Among all registered number of B+ TB Cases | M26: Amoung All (N+R+UK) number tested by Gene Xpert | O26: No. of TB patients tested for HIV | S26: HIV Reactive | W26: TB Patients confirmed positive for HIV | AA26: HIV positive TB Patients put on ART
B27: Total | C27: Through Community Referrals (LHWs) | D27: AFB | E27: Xp & AFB | F27: XP | G27: G.Tot | H27: AFB | I27: AFB + Xpert | J27: Xpert | K27: G.Tot | O27: 0 | S27: 0 | W27: 0 | AA27: 0
A28: 1098 | B28: 151 | C28: 8 | D28: 49 | E28: 102 | F28: 0 | G28: 151 | H28: 2 | I28: 74 | J28: 9 | K28: 85 | L28: 31 | M28: 56 | O28: HIV patient tested for TB | S28: HIV patients diagnosed for TB | W28: TB HIV patients put on TB Tx | AA28: HIV positive TB negative patients on TPT
O29: 0 | S29: 0 | W29: 0 | AB29: 0-4 | AC29: 5-14 | AD29: 15 +
AA30: 6H | AB30: 0 | AC30: 0 | AD30: 0
AA31: 3HR | AB31: 0 | AC31: 0 | AD31: 0
AA32: 3 HP | AB32: 0 | AC32: 0 | AD32: 0
A34: Block 5 : Bacteriologically Confermid TB Cases with DST Result | O34: Block 6 : Contact Tracing HH *
A35: Sensitive =S Resistance = R | B35: PTB | H35: EPTB | O35: Total No. of HH of B+ PTB | R35: No. of HH contacts of B+ PTB Cases Screened | U35: No. of TB Cases diagnosed Amoung HH contact screened | X35: No. of HH Contacts Initiated on TPT | AB35: HIV negative Immuno - compromised on TPT
B36: Rifampicin | D36: Isoniazid | F36: Fluoroquninolone | H36: Rifampicin | J36: Isoniazid | L36: Fluoroquninolone
B37: S | C37: R | D37: S | E37: R | F37: S | G37: R | H37: S | I37: R | J37: S | K37: R | L37: S | M37: R
A38: New + UK | B38: 27 | C38: 0 | D38: 0 | E38: 0 | F38: 0 | G38: 0 | H38: 0 | I38: 0 | J38: 0 | K38: 0 | L38: 0 | M38: 0 | Y38: 0-4 | Z38: 5-14 | AA38: 15+ | AB38: 0-4 | AC38: 5-14 | AD38: 15+
A39: Relapse | B39: 2 | C39: 0 | D39: 0 | E39: 0 | F39: 0 | G39: 0 | H39: 0 | I39: 0 | J39: 0 | K39: 0 | L39: 0 | M39: 0 | O39: 0-4 | P39: 5-14 | Q39: 15 + | R39: 0-4 | S39: 5-14 | T39: 15 + | U39: 0-4 | V39: 5-14 | W39: 15 + | X39: 6H | Y39: 0 | Z39: 0 | AA39: 0 | AB39: 0 | AC39: 0 | AD39: 0
A40: Previously treated | B40: 0 | C40: 0 | D40: 0 | E40: 0 | F40: 0 | G40: 0 | H40: 0 | I40: 0 | J40: 0 | K40: 0 | L40: 0 | M40: 0 | O40: 37 | P40: 81 | Q40: 165 | R40: 2 | S40: 30 | T40: 86 | U40: 0 | V40: 2 | W40: 24 | X40: 3HR | Y40: 0 | Z40: 0 | AA40: 0 | AB40: 0 | AC40: 0 | AD40: 0
A41: Total | B41: 29 | C41: 0 | D41: 0 | E41: 0 | F41: 0 | G41: 0 | H41: 0 | I41: 0 | J41: 0 | K41: 0 | L41: 0 | M41: 0 | X41: 3 HP | Y41: 0 | Z41: 0 | AA41: 0 | AB41: 0 | AC41: 0 | AD41: 0
A42: QUARTERLY REPORT ON TB CASES REGISTRATION
A43: INDIVIDUAL/CONSOLIDATED (TICK ONE) | Z43: TB - 07
A44: Name of TB Care Facility (BMU) : | E44: Consolidated | I44: District : | K44: 0 | M44: Central : | O44: Khyber Pakhtunkhwa | U44: Patients registered during | Z44: 2nd Quarter | AC44: of Year 2026
A46: Name of TB Coodinator/Facility incharge : | I46: ___________________________________________________ | U46: Date of completion of this form : | AA46: _______________________
A48: Block 1: | L48: New (N) | N48: Relapse ® | P48: Previous Treatment History Unknown (UK) | S48: New episode (N+R+UK) | V48: Re - registered Cases ( Excluding Recurrent cases) | AC48: Total
...

Sheet All Project Total - 2026
A2: QUARTERLY REPORT ON TB CASES REGISTRATION
A3: INDIVIDUAL/CONSOLIDATED (TICK ONE) | Z3: TB - 07
A4: Name of TB Care Facility (BMU) : | E4: All Project Total | K4: Consolidated | U4: Patients registered during | Z4: 1st Quarter | AC4: of Year 2026
A6: Name of TB Coodinator/Facility incharge : | I6: ___________________________________________________ | U6: Date of completion of this form : | AA6: _______________________
A8: Block 1: | L8: New (N) | N8: Relapse ® | P8: Previous Treatment History Unknown (UK) | S8: New episode (N+R+UK) | V8: Re - registered Cases ( Excluding Recurrent cases) | AC8: Total
A9: All TB Cases Registered | V9: Treatment after failure | Y9: Treatment after lost to follow-up | AA9: Other
A11: Pulmonary, Bacteriologically Confermid | L11: =SUM(MPR!L11+KARACHI!L11+SINDH!L11+'GILGIT BALTISTAN'!L11:M11+'AZAD KHASHMIR'!L11:M11+'KHYBER PAKHTUNKHWA'!L11:M11) -> 812 | N11: =SUM(MPR!N11+KARACHI!N11+SINDH!N11+'GILGIT BALTISTAN'!N11:O11+'AZAD KHASHMIR'!N11:O11+'KHYBER PAKHTUNKHWA'!N11:O11) -> 96 | P11: =SUM(MPR!P11+KARACHI!P11+SINDH!P11+'GILGIT BALTISTAN'!P11:R11+'AZAD KHASHMIR'!P11:R11+'KHYBER PAKHTUNKHWA'!P11:R11) -> 1 | S11: =SUM(L11+N11+P11) -> 909 | V11: =SUM(MPR!V11+KARACHI!V11+SINDH!V11+'GILGIT BALTISTAN'!V11:X11+'AZAD KHASHMIR'!V11:X11+'KHYBER PAKHTUNKHWA'!V11:X11) -> 0 | Y11: =SUM(MPR!Y11+KARACHI!Y11+SINDH!Y11+'GILGIT BALTISTAN'!Y11:Z11+'AZAD KHASHMIR'!Y11:Z11+'KHYBER PAKHTUNKHWA'!Y11:Z11) -> 3 | AA11: =SUM(MPR!AA11+KARACHI!AA11+SINDH!AA11+'GILGIT BALTISTAN'!AA11:AB11+'AZAD KHASHMIR'!AA11:AB11+'KHYBER PAKHTUNKHWA'!AA11:AB11) -> 5 | AC11: =SUM(L11+N11+P11+V11+Y11+AA11) -> 917
A12: Pulmonary , Clinically Diagnosed | L12: =SUM(MPR!L12+KARACHI!L12+SINDH!L12+'GILGIT BALTISTAN'!L12:M12+'AZAD KHASHMIR'!L12:M12+'KHYBER PAKHTUNKHWA'!L12:M12) -> 1204 | N12: =SUM(MPR!N12+KARACHI!N12+SINDH!N12+'GILGIT BALTISTAN'!N12:O12+'AZAD KHASHMIR'!N12:O12+'KHYBER PAKHTUNKHWA'!N12:O12) -> 28 | P12: =SUM(MPR!P12+KARACHI!P12+SINDH!P12+'GILGIT BALTISTAN'!P12:R12+'AZAD KHASHMIR'!P12:R12+'KHYBER PAKHTUNKHWA'!P12:R12) -> 2 | S12: =SUM(L12+N12+P12) -> 1234 | V12: =SUM(MPR!V12+KARACHI!V12+SINDH!V12+'GILGIT BALTISTAN'!V12:X12+'AZAD KHASHMIR'!V12:X12+'KHYBER PAKHTUNKHWA'!V12:X12) -> 0 | Y12: =SUM(MPR!Y12+KARACHI!Y12+SINDH!Y12+'GILGIT BALTISTAN'!Y12:Z12+'AZAD KHASHMIR'!Y12:Z12+'KHYBER PAKHTUNKHWA'!Y12:Z12) -> 3 | AA12: =SUM(MPR!AA12+KARACHI!AA12+SINDH!AA12+'GILGIT BALTISTAN'!AA12:AB12+'AZAD KHASHMIR'!AA12:AB12+'KHYBER PAKHTUNKHWA'!AA12:AB12) -> 2 | AC12: =SUM(L12+N12+P12+V12+Y12+AA12) -> 1239
A13: Extra Pulmonary, Bacteriologically Confermid | L13: =SUM(MPR!L13+KARACHI!L13+SINDH!L13+'GILGIT BALTISTAN'!L13:M13+'AZAD KHASHMIR'!L13:M13+'KHYBER PAKHTUNKHWA'!L13:M13) -> 5 | N13: =SUM(MPR!N13+KARACHI!N13+SINDH!N13+'GILGIT BALTISTAN'!N13:O13+'AZAD KHASHMIR'!N13:O13+'KHYBER PAKHTUNKHWA'!N13:O13) -> 0 | P13: =SUM(MPR!P13+KARACHI!P13+SINDH!P13+'GILGIT BALTISTAN'!P13:R13+'AZAD KHASHMIR'!P13:R13+'KHYBER PAKHTUNKHWA'!P13:R13) -> 0 | S13: =SUM(L13+N13+P13) -> 5 | V13: =SUM(MPR!V13+KARACHI!V13+SINDH!V13+'GILGIT BALTISTAN'!V13:X13+'AZAD KHASHMIR'!V13:X13+'KHYBER PAKHTUNKHWA'!V13:X13) -> 0 | Y13: =SUM(MPR!Y13+KARACHI!Y13+SINDH!Y13+'GILGIT BALTISTAN'!Y13:Z13+'AZAD KHASHMIR'!Y13:Z13+'KHYBER PAKHTUNKHWA'!Y13:Z13) -> 0 | AA13: =SUM(MPR!AA13+KARACHI!AA13+SINDH!AA13+'GILGIT BALTISTAN'!AA13:AB13+'AZAD KHASHMIR'!AA13:AB13+'KHYBER PAKHTUNKHWA'!AA13:AB13) -> 1 | AC13: =SUM(L13+N13+P13+V13+Y13+AA13) -> 6
A14: Extra Pulmonary , Clinically Diagnosed | L14: =SUM(MPR!L14+KARACHI!L14+SINDH!L14+'GILGIT BALTISTAN'!L14:M14+'AZAD KHASHMIR'!L14:M14+'KHYBER PAKHTUNKHWA'!L14:M14) -> 768 | N14: =SUM(MPR!N14+KARACHI!N14+SINDH!N14+'GILGIT BALTISTAN'!N14:O14+'AZAD KHASHMIR'!N14:O14+'KHYBER PAKHTUNKHWA'!N14:O14) -> 10 | P14: =SUM(MPR!P14+KARACHI!P14+SINDH!P14+'GILGIT BALTISTAN'!P14:R14+'AZAD KHASHMIR'!P14:R14+'KHYBER PAKHTUNKHWA'!P14:R14) -> 0 | S14: =SUM(L14+N14+P14) -> 778 | V14: =SUM(MPR!V14+KARACHI!V14+SINDH!V14+'GILGIT BALTISTAN'!V14:X14+'AZAD KHASHMIR'!V14:X14+'KHYBER PAKHTUNKHWA'!V14:X14) -> 0 | Y14: =SUM(MPR!Y14+KARACHI!Y14+SINDH!Y14+'GILGIT BALTISTAN'!Y14:Z14+'AZAD KHASHMIR'!Y14:Z14+'KHYBER PAKHTUNKHWA'!Y14:Z14) -> 1 | AA14: =SUM(MPR!AA14+KARACHI!AA14+SINDH!AA14+'GILGIT BALTISTAN'!AA14:AB14+'AZAD KHASHMIR'!AA14:AB14+'KHYBER PAKHTUNKHWA'!AA14:AB14) -> 4 | AC14: =SUM(L14+N14+P14+V14+Y14+AA14) -> 783
A15: Total | L15: =SUM(L11:M14) -> 2789 | N15: =SUM(N11:O14) -> 134 | P15: =SUM(P11:R14) -> 3 | S15: =SUM(L15+N15+P15) -> 2926 | V15: =SUM(V11:X14) -> 0 | Y15: =SUM(Y11:Z14) -> 7 | AA15: =SUM(AA11:AB14) -> 12 | AC15: =SUM(L15+N15+P15+V15+Y15+AA15) -> 2945
A16: Block 2: All New, Relapse and previous treatment history unknown Cases registered during the period by Age Group and Gender
L17: 0-4 | N17: 5-14 | P17: 15-24 | R17: 25-34 | T17: 35-44 | V17: 45-54 | X17: 55-64 | Z17: 65 & Above | AB17: Total | AD17: Grand Total
L18: M | M18: F | N18: M | O18: F | P18: M | Q18: F | R18: M | S18: F | T18: M | U18: F | V18: M | W18: F | X18: M | Y18: F | Z18: M | AA18: F | AB18: M | AC18: F
A19: Pulmonary, Bacteriologically Confermid | L19: =SUM(MPR!L19+KARACHI!L19+SINDH!L19+'GILGIT BALTISTAN'!L19+'AZAD KHASHMIR'!L19+'KHYBER PAKHTUNKHWA'!L19) -> 0 | M19: =SUM(MPR!M19+KARACHI!M19+SINDH!M19+'GILGIT BALTISTAN'!M19+'AZAD KHASHMIR'!M19+'KHYBER PAKHTUNKHWA'!M19) -> 0 | N19: =SUM(MPR!N19+KARACHI!N19+SINDH!N19+'GILGIT BALTISTAN'!N19+'AZAD KHASHMIR'!N19+'KHYBER PAKHTUNKHWA'!N19) -> 9 | O19: =SUM(MPR!O19+KARACHI!O19+SINDH!O19+'GILGIT BALTISTAN'!O19+'AZAD KHASHMIR'!O19+'KHYBER PAKHTUNKHWA'!O19) -> 16 | P19: =SUM(MPR!P19+KARACHI!P19+SINDH!P19+'GILGIT BALTISTAN'!P19+'AZAD KHASHMIR'!P19+'KHYBER PAKHTUNKHWA'!P19) -> 59 | Q19: =SUM(MPR!Q19+KARACHI!Q19+SINDH!Q19+'GILGIT BALTISTAN'!Q19+'AZAD KHASHMIR'!Q19+'KHYBER PAKHTUNKHWA'!Q19) -> 108 | R19: =SUM(MPR!R19+KARACHI!R19+SINDH!R19+'GILGIT BALTISTAN'!R19+'AZAD KHASHMIR'!R19+'KHYBER PAKHTUNKHWA'!R19) -> 86 | S19: =SUM(MPR!S19+KARACHI!S19+SINDH!S19+'GILGIT BALTISTAN'!S19+'AZAD KHASHMIR'!S19+'KHYBER PAKHTUNKHWA'!S19) -> 72 | ... AA19: =SUM(MPR!AA19+KARACHI!AA19+SINDH!AA19+'GILGIT BALTISTAN'!AA19+'AZAD KHASHMIR'!AA19+'KHYBER PAKHTUNKHWA'!AA19) -> 77 | AB19: =SUM(L19+N19+P19+R19+T19+V19+X19+Z19) -> 458 | AC19: =SUM(M19+O19+Q19+S19+U19+W19+Y19+AA19) -> 439 | AD19: =SUM(AB19:AC19) -> 897
A20: Pulmonary , Clinically Diagnosed | L20: =SUM(MPR!L20+KARACHI!L20+SINDH!L20+'GILGIT BALTISTAN'!L20+'AZAD KHASHMIR'!L20+'KHYBER PAKHTUNKHWA'!L20) -> 189 | M20: =SUM(MPR!M20+KARACHI!M20+SINDH!M20+'GILGIT BALTISTAN'!M20+'AZAD KHASHMIR'!M20+'KHYBER PAKHTUNKHWA'!M20) -> 154 | N20: =SUM(MPR!N20+KARACHI!N20+SINDH!N20+'GILGIT BALTISTAN'!N20+'AZAD KHASHMIR'!N20+'KHYBER PAKHTUNKHWA'!N20) -> 65 | O20: =SUM(MPR!O20+KARACHI!O20+SINDH!O20+'GILGIT BALTISTAN'!O20+'AZAD KHASHMIR'!O20+'KHYBER PAKHTUNKHWA'!O20) -> 60 | P20: =SUM(MPR!P20+KARACHI!P20+SINDH!P20+'GILGIT BALTISTAN'!P20+'AZAD KHASHMIR'!P20+'KHYBER PAKHTUNKHWA'!P20) -> 79 | Q20: =SUM(MPR!Q20+KARACHI!Q20+SINDH!Q20+'GILGIT BALTISTAN'!Q20+'AZAD KHASHMIR'!Q20+'KHYBER PAKHTUNKHWA'!Q20) -> 66 | R20: =SUM(MPR!R20+KARACHI!R20+SINDH!R20+'GILGIT BALTISTAN'!R20+'AZAD KHASHMIR'!R20+'KHYBER PAKHTUNKHWA'!R20) -> 52 | S20: =SUM(MPR!S20+KARACHI!S20+SINDH!S20+'GILGIT BALTISTAN'!S20+'AZAD KHASHMIR'!S20+'KHYBER PAKHTUNKHWA'!S20) -> 70 | ... AA20: =SUM(MPR!AA20+KARACHI!AA20+SINDH!AA20+'GILGIT BALTISTAN'!AA20+'AZAD KHASHMIR'!AA20+'KHYBER PAKHTUNKHWA'!AA20) -> 78 | AB20: =SUM(L20+N20+P20+R20+T20+V20+X20+Z20) -> 651 | AC20: =SUM(M20+O20+Q20+S20+U20+W20+Y20+AA20) -> 577 | AD20: =SUM(AB20:AC20) -> 1228
A21: Extra Pulmonary, Bacteriologically Confermid | L21: =SUM(MPR!L21+KARACHI!L21+SINDH!L21+'GILGIT BALTISTAN'!L21+'AZAD KHASHMIR'!L21+'KHYBER PAKHTUNKHWA'!L21) -> 0 | M21: =SUM(MPR!M21+KARACHI!M21+SINDH!M21+'GILGIT BALTISTAN'!M21+'AZAD KHASHMIR'!M21+'KHYBER PAKHTUNKHWA'!M21) -> 0 | N21: =SUM(MPR!N21+KARACHI!N21+SINDH!N21+'GILGIT BALTISTAN'!N21+'AZAD KHASHMIR'!N21+'KHYBER PAKHTUNKHWA'!N21) -> 0 | O21: =SUM(MPR!O21+KARACHI!O21+SINDH!O21+'GILGIT BALTISTAN'!O21+'AZAD KHASHMIR'!O21+'KHYBER PAKHTUNKHWA'!O21) -> 0 | P21: =SUM(MPR!P21+KARACHI!P21+SINDH!P21+'GILGIT BALTISTAN'!P21+'AZAD KHASHMIR'!P21+'KHYBER PAKHTUNKHWA'!P21) -> 0 | Q21: =SUM(MPR!Q21+KARACHI!Q21+SINDH!Q21+'GILGIT BALTISTAN'!Q21+'AZAD KHASHMIR'!Q21+'KHYBER PAKHTUNKHWA'!Q21) -> 1 | R21: =SUM(MPR!R21+KARACHI!R21+SINDH!R21+'GILGIT BALTISTAN'!R21+'AZAD KHASHMIR'!R21+'KHYBER PAKHTUNKHWA'!R21) -> 2 | S21: =SUM(MPR!S21+KARACHI!S21+SINDH!S21+'GILGIT BALTISTAN'!S21+'AZAD KHASHMIR'!S21+'KHYBER PAKHTUNKHWA'!S21) -> 2 | ... AA21: =SUM(MPR!AA21+KARACHI!AA21+SINDH!AA21+'GILGIT BALTISTAN'!AA21+'AZAD KHASHMIR'!AA21+'KHYBER PAKHTUNKHWA'!AA21) -> 2 | AB21: =SUM(L21+N21+P21+R21+T21+V21+X21+Z21) -> 6 | AC21: =SUM(M21+O21+Q21+S21+U21+W21+Y21+AA21) -> 7 | AD21: =SUM(AB21:AC21) -> 13
A22: Extra Pulmonary , Clinically Diagnosed | L22: =SUM(MPR!L22+KARACHI!L22+SINDH!L22+'GILGIT BALTISTAN'!L22+'AZAD KHASHMIR'!L22+'KHYBER PAKHTUNKHWA'!L22) -> 77 | M22: =SUM(MPR!M22+KARACHI!M22+SINDH!M22+'GILGIT BALTISTAN'!M22+'AZAD KHASHMIR'!M22+'KHYBER PAKHTUNKHWA'!M22) -> 80 | N22: =SUM(MPR!N22+KARACHI!N22+SINDH!N22+'GILGIT BALTISTAN'!N22+'AZAD KHASHMIR'!N22+'KHYBER PAKHTUNKHWA'!N22) -> 32 | O22: =SUM(MPR!O22+KARACHI!O22+SINDH!O22+'GILGIT BALTISTAN'!O22+'AZAD KHASHMIR'!O22+'KHYBER PAKHTUNKHWA'!O22) -> 34 | P22: =SUM(MPR!P22+KARACHI!P22+SINDH!P22+'GILGIT BALTISTAN'!P22+'AZAD KHASHMIR'!P22+'KHYBER PAKHTUNKHWA'!P22) -> 59 | Q22: =SUM(MPR!Q22+KARACHI!Q22+SINDH!Q22+'GILGIT BALTISTAN'!Q22+'AZAD KHASHMIR'!Q22+'KHYBER PAKHTUNKHWA'!Q22) -> 61 | R22: =SUM(MPR!R22+KARACHI!R22+SINDH!R22+'GILGIT BALTISTAN'!R22+'AZAD KHASHMIR'!R22+'KHYBER PAKHTUNKHWA'!R22) -> 60 | S22: =SUM(MPR!S22+KARACHI!S22+SINDH!S22+'GILGIT BALTISTAN'!S22+'AZAD KHASHMIR'!S22+'KHYBER PAKHTUNKHWA'!S22) -> 55 | ... AA22: =SUM(MPR!AA22+KARACHI!AA22+SINDH!AA22+'GILGIT BALTISTAN'!AA22+'AZAD KHASHMIR'!AA22+'KHYBER PAKHTUNKHWA'!AA22) -> 39 | AB22: =SUM(L22+N22+P22+R22+T22+V22+X22+Z22) -> 419 | AC22: =SUM(M22+O22+Q22+S22+U22+W22+Y22+AA22) -> 393 | AD22: =SUM(AB22:AC22) -> 812
A23: Total | L23: =SUM(L19:L22) -> 266 | M23: =SUM(M19:M22) -> 234 | N23: =SUM(N19:N22) -> 106 | O23: =SUM(O19:O22) -> 110 | P23: =SUM(P19:P22) -> 197 | Q23: =SUM(Q19:Q22) -> 236 | R23: =SUM(R19:R22) -> 200 | S23: =SUM(S19:S22) -> 199 | ... AC23: =SUM(AC19:AC22) -> 1416 | AD23: =SUM(AB23:AC23) -> 2950
A25: Block 3: Presumptive TB Cases Identified Laboratory Diagnosis and use of WRD | O25: Block 4 : TB HIV Activities
A26: Total New OPD in Quarter | B26: No. of presumptive TB cases identified | D26: No. of Presumptive TB Patients tested Using | H26: Among Presumptive TB cases tested number reported B+ | L26: Among all registered number of B+ TB Cases | M26: Amoung All (N+R+UK) number tested by Gene Xpert | O26: No. of TB patients tested for HIV | S26: HIV Reactive | W26: TB Patients confirmed positive for HIV | AA26: HIV positive TB Patients put on ART
B27: Total | C27: Through Community Referrals (LHWs) | D27: AFB | E27: Xp & AFB | F27: XP | G27: G.Tot | H27: AFB | I27: AFB + Xpert | J27: Xpert | K27: G.Tot | O27: =SUM(MPR!O27+KARACHI!O27+SINDH!O27+'GILGIT BALTISTAN'!O27:R27+'AZAD KHASHMIR'!O27:R27+'KHYBER PAKHTUNKHWA'!O27:R27) -> 1099 | S27: =SUM(MPR!S27+KARACHI!S27+SINDH!S27+'GILGIT BALTISTAN'!S27:V27+'AZAD KHASHMIR'!S27:V27+'KHYBER PAKHTUNKHWA'!S27:V27) -> 4 | W27: =SUM(MPR!W27+KARACHI!W27+SINDH!W27+'GILGIT BALTISTAN'!W27:Z27+'AZAD KHASHMIR'!W27:Z27+'KHYBER PAKHTUNKHWA'!W27:Z27) -> 0 | AA27: =SUM(MPR!AA27+KARACHI!AA27+SINDH!AA27+'GILGIT BALTISTAN'!AA27:AD27+'AZAD KHASHMIR'!AA27:AD27+'KHYBER PAKHTUNKHWA'!AA27:AD27) -> 0
A28: =SUM(MPR!A28+KARACHI!A28+SINDH!A28+'GILGIT BALTISTAN'!A28:A32+'AZAD KHASHMIR'!A28:A32+'KHYBER PAKHTUNKHWA'!A28:A32) -> 643103 | B28: =SUM(MPR!B28+KARACHI!B28+SINDH!B28+'GILGIT BALTISTAN'!B28:B32+'AZAD KHASHMIR'!B28:B32+'KHYBER PAKHTUNKHWA'!B28:B32) -> 14820 | C28: =SUM(MPR!C28+KARACHI!C28+SINDH!C28+'GILGIT BALTISTAN'!C28:C32+'AZAD KHASHMIR'!C28:C32+'KHYBER PAKHTUNKHWA'!C28:C32) -> 1400 | D28: =SUM(MPR!D28+KARACHI!D28+SINDH!D28+'GILGIT BALTISTAN'!D28:D32+'AZAD KHASHMIR'!D28:D32+'KHYBER PAKHTUNKHWA'!D28:D32) -> 2941 | E28: =SUM(MPR!E28+KARACHI!E28+SINDH!E28+'GILGIT BALTISTAN'!E28:E32+'AZAD KHASHMIR'!E28:E32+'KHYBER PAKHTUNKHWA'!E28:E32) -> 1682 | F28: =SUM(MPR!F28+KARACHI!F28+SINDH!F28+'GILGIT BALTISTAN'!F28:F32+'AZAD KHASHMIR'!F28:F32+'KHYBER PAKHTUNKHWA'!F28:F32) -> 7877 | G28: =SUM(D28:F32) -> 12500 | H28: =SUM(MPR!H28+KARACHI!H28+SINDH!H28+'GILGIT BALTISTAN'!H28:H32+'AZAD KHASHMIR'!H28:H32+'KHYBER PAKHTUNKHWA'!H28:H32) -> 66 | I28: =SUM(MPR!I28+KARACHI!I28+SINDH!I28+'GILGIT BALTISTAN'!I28:I32+'AZAD KHASHMIR'!I28:I32+'KHYBER PAKHTUNKHWA'!I28:I32) -> 360 | J28: =SUM(MPR!J28+KARACHI!J28+SINDH!J28+'GILGIT BALTISTAN'!J28:J32+'AZAD KHASHMIR'!J28:J32+'KHYBER PAKHTUNKHWA'!J28:J32) -> 569 | K28: =SUM(H28:J32) -> 995 | L28: =SUM(MPR!L28+KARACHI!L28+SINDH!L28+'GILGIT BALTISTAN'!L28:L32+'AZAD KHASHMIR'!L28:L32+'KHYBER PAKHTUNKHWA'!L28:L32) -> 892 | M28: =SUM(MPR!M28+KARACHI!M28+SINDH!M28+'GILGIT BALTISTAN'!M28:M32+'AZAD KHASHMIR'!M28:M32+'KHYBER PAKHTUNKHWA'!M28:M32) -> 1229 | O28: HIV patient tested for TB | S28: HIV patients diagnosed for TB | W28: TB HIV patients put on TB Tx | AA28: HIV positive TB negative patients on TPT
O29: =SUM(MPR!O29+KARACHI!O29+SINDH!O29+'GILGIT BALTISTAN'!O29:R32+'AZAD KHASHMIR'!O29:R32+'KHYBER PAKHTUNKHWA'!O29:R32) -> 27 | S29: =SUM(MPR!S29+KARACHI!S29+SINDH!S29+'GILGIT BALTISTAN'!S29:V32+'AZAD KHASHMIR'!S29:V32+'KHYBER PAKHTUNKHWA'!S29:V32) -> 0 | W29: =SUM(MPR!W29+KARACHI!W29+SINDH!W29+'GILGIT BALTISTAN'!W29:Z32+'AZAD KHASHMIR'!W29:Z32+'KHYBER PAKHTUNKHWA'!W29:Z32) -> 0 | AB29: 0-4 | AC29: 5-14 | AD29: 15 +
AA30: 6H | AB30: =SUM(MPR!AB30+KARACHI!AB30+SINDH!AB30+'GILGIT BALTISTAN'!AB30+'AZAD KHASHMIR'!AB30+'KHYBER PAKHTUNKHWA'!AB30) -> 0 | AC30: =SUM(MPR!AC30+KARACHI!AC30+SINDH!AC30+'GILGIT BALTISTAN'!AC30+'AZAD KHASHMIR'!AC30+'KHYBER PAKHTUNKHWA'!AC30) -> 0 | AD30: =SUM(MPR!AD30+KARACHI!AD30+SINDH!AD30+'GILGIT BALTISTAN'!AD30+'AZAD KHASHMIR'!AD30+'KHYBER PAKHTUNKHWA'!AD30) -> 0
AA31: 3HR | AB31: =SUM(MPR!AB31+KARACHI!AB31+SINDH!AB31+'GILGIT BALTISTAN'!AB31+'AZAD KHASHMIR'!AB31+'KHYBER PAKHTUNKHWA'!AB31) -> 0 | AC31: =SUM(MPR!AC31+KARACHI!AC31+SINDH!AC31+'GILGIT BALTISTAN'!AC31+'AZAD KHASHMIR'!AC31+'KHYBER PAKHTUNKHWA'!AC31) -> 0 | AD31: =SUM(MPR!AD31+KARACHI!AD31+SINDH!AD31+'GILGIT BALTISTAN'!AD31+'AZAD KHASHMIR'!AD31+'KHYBER PAKHTUNKHWA'!AD31) -> 0
AA32: 3 HP | AB32: =SUM(MPR!AB32+KARACHI!AB32+SINDH!AB32+'GILGIT BALTISTAN'!AB32+'AZAD KHASHMIR'!AB32+'KHYBER PAKHTUNKHWA'!AB32) -> 0 | AC32: =SUM(MPR!AC32+KARACHI!AC32+SINDH!AC32+'GILGIT BALTISTAN'!AC32+'AZAD KHASHMIR'!AC32+'KHYBER PAKHTUNKHWA'!AC32) -> 0 | AD32: =SUM(MPR!AD32+KARACHI!AD32+SINDH!AD32+'GILGIT BALTISTAN'!AD32+'AZAD KHASHMIR'!AD32+'KHYBER PAKHTUNKHWA'!AD32) -> 0
A34: Block 5 : Bacteriologically Confermid TB Cases with DST Result | O34: Block 6 : Contact Tracing HH *
A35: Sensitive =S Resistance = R | B35: PTB | H35: EPTB | O35: Total No. of HH of B+ PTB | R35: No. of HH contacts of B+ PTB Cases Screened | U35: No. of TB Cases diagnosed Amoung HH contact screened | X35: No. of HH Contacts Initiated on TPT | AB35: HIV negative Immuno - compromised on TPT
B36: Rifampicin | D36: Isoniazid | F36: Fluoroquninolone | H36: Rifampicin | J36: Isoniazid | L36: Fluoroquninolone
B37: S | C37: R | D37: S | E37: R | F37: S | G37: R | H37: S | I37: R | J37: S | K37: R | L37: S | M37: R
A38: New + UK | B38: =SUM(MPR!B38+KARACHI!B38+SINDH!B38+'GILGIT BALTISTAN'!B38+'AZAD KHASHMIR'!B38+'KHYBER PAKHTUNKHWA'!B38) -> 730 | C38: =SUM(MPR!C38+KARACHI!C38+SINDH!C38+'GILGIT BALTISTAN'!C38+'AZAD KHASHMIR'!C38+'KHYBER PAKHTUNKHWA'!C38) -> 3 | D38: =SUM(MPR!D38+KARACHI!D38+SINDH!D38+'GILGIT BALTISTAN'!D38+'AZAD KHASHMIR'!D38+'KHYBER PAKHTUNKHWA'!D38) -> 9 | E38: =SUM(MPR!E38+KARACHI!E38+SINDH!E38+'GILGIT BALTISTAN'!E38+'AZAD KHASHMIR'!E38+'KHYBER PAKHTUNKHWA'!E38) -> 0 | F38: =SUM(MPR!F38+KARACHI!F38+SINDH!F38+'GILGIT BALTISTAN'!F38+'AZAD KHASHMIR'!F38+'KHYBER PAKHTUNKHWA'!F38) -> 0 | G38: =SUM(MPR!G38+KARACHI!G38+SINDH!G38+'GILGIT BALTISTAN'!G38+'AZAD KHASHMIR'!G38+'KHYBER PAKHTUNKHWA'!G38) -> 0 | H38: =SUM(MPR!H38+KARACHI!H38+SINDH!H38+'GILGIT BALTISTAN'!H38+'AZAD KHASHMIR'!H38+'KHYBER PAKHTUNKHWA'!H38) -> 1 | I38: =SUM(MPR!I38+KARACHI!I38+SINDH!I38+'GILGIT BALTISTAN'!I38+'AZAD KHASHMIR'!I38+'KHYBER PAKHTUNKHWA'!I38) -> 0 | ... M38: =SUM(MPR!M38+KARACHI!M38+SINDH!M38+'GILGIT BALTISTAN'!M38+'AZAD KHASHMIR'!M38+'KHYBER PAKHTUNKHWA'!M38) -> 0 | Y38: 0-4 | Z38: 5-14 | AA38: 15+ | AB38: 0-4 | AC38: 5-14 | AD38: 15+
A39: Relapse | B39: =SUM(MPR!B39+KARACHI!B39+SINDH!B39+'GILGIT BALTISTAN'!B39+'AZAD KHASHMIR'!B39+'KHYBER PAKHTUNKHWA'!B39) -> 73 | C39: =SUM(MPR!C39+KARACHI!C39+SINDH!C39+'GILGIT BALTISTAN'!C39+'AZAD KHASHMIR'!C39+'KHYBER PAKHTUNKHWA'!C39) -> 0 | D39: =SUM(MPR!D39+KARACHI!D39+SINDH!D39+'GILGIT BALTISTAN'!D39+'AZAD KHASHMIR'!D39+'KHYBER PAKHTUNKHWA'!D39) -> 0 | E39: =SUM(MPR!E39+KARACHI!E39+SINDH!E39+'GILGIT BALTISTAN'!E39+'AZAD KHASHMIR'!E39+'KHYBER PAKHTUNKHWA'!E39) -> 0 | F39: =SUM(MPR!F39+KARACHI!F39+SINDH!F39+'GILGIT BALTISTAN'!F39+'AZAD KHASHMIR'!F39+'KHYBER PAKHTUNKHWA'!F39) -> 0 | G39: =SUM(MPR!G39+KARACHI!G39+SINDH!G39+'GILGIT BALTISTAN'!G39+'AZAD KHASHMIR'!G39+'KHYBER PAKHTUNKHWA'!G39) -> 0 | H39: =SUM(MPR!H39+KARACHI!H39+SINDH!H39+'GILGIT BALTISTAN'!H39+'AZAD KHASHMIR'!H39+'KHYBER PAKHTUNKHWA'!H39) -> 0 | I39: =SUM(MPR!I39+KARACHI!I39+SINDH!I39+'GILGIT BALTISTAN'!I39+'AZAD KHASHMIR'!I39+'KHYBER PAKHTUNKHWA'!I39) -> 0 | ... M39: =SUM(MPR!M39+KARACHI!M39+SINDH!M39+'GILGIT BALTISTAN'!M39+'AZAD KHASHMIR'!M39+'KHYBER PAKHTUNKHWA'!M39) -> 0 | O39: 0-4 | P39: 5-14 | Q39: 15 + | R39: 0-4 | S39: 5-14 | T39: 15 + | U39: 0-4 | V39: 5-14 | W39: 15 + | X39: 6H | Y39: =SUM(MPR!Y39+KARACHI!Y39+SINDH!Y39+'GILGIT BALTISTAN'!Y39+'AZAD KHASHMIR'!Y39+'KHYBER PAKHTUNKHWA'!Y39) -> 28 | Z39: =SUM(MPR!Z39+KARACHI!Z39+SINDH!Z39+'GILGIT BALTISTAN'!Z39+'AZAD KHASHMIR'!Z39+'KHYBER PAKHTUNKHWA'!Z39) -> 17 | AA39: =SUM(MPR!AA39+KARACHI!AA39+SINDH!AA39+'GILGIT BALTISTAN'!AA39+'AZAD KHASHMIR'!AA39+'KHYBER PAKHTUNKHWA'!AA39) -> 0 | AB39: =SUM(MPR!AB39+KARACHI!AB39+SINDH!AB39+'GILGIT BALTISTAN'!AB39+'AZAD KHASHMIR'!AB39+'KHYBER PAKHTUNKHWA'!AB39) -> 0 | AC39: =SUM(MPR!AC39+KARACHI!AC39+SINDH!AC39+'GILGIT BALTISTAN'!AC39+'AZAD KHASHMIR'!AC39+'KHYBER PAKHTUNKHWA'!AC39) -> 0 | AD39: =SUM(MPR!AD39+KARACHI!AD39+SINDH!AD39+'GILGIT BALTISTAN'!AD39+'AZAD KHASHMIR'!AD39+'KHYBER PAKHTUNKHWA'!AD39) -> 0
A40: Previously treated | B40: =SUM(MPR!B40+KARACHI!B40+SINDH!B40+'GILGIT BALTISTAN'!B40+'AZAD KHASHMIR'!B40+'KHYBER PAKHTUNKHWA'!B40) -> 2 | C40: =SUM(MPR!C40+KARACHI!C40+SINDH!C40+'GILGIT BALTISTAN'!C40+'AZAD KHASHMIR'!C40+'KHYBER PAKHTUNKHWA'!C40) -> 0 | D40: =SUM(MPR!D40+KARACHI!D40+SINDH!D40+'GILGIT BALTISTAN'!D40+'AZAD KHASHMIR'!D40+'KHYBER PAKHTUNKHWA'!D40) -> 0 | E40: =SUM(MPR!E40+KARACHI!E40+SINDH!E40+'GILGIT BALTISTAN'!E40+'AZAD KHASHMIR'!E40+'KHYBER PAKHTUNKHWA'!E40) -> 0 | F40: =SUM(MPR!F40+KARACHI!F40+SINDH!F40+'GILGIT BALTISTAN'!F40+'AZAD KHASHMIR'!F40+'KHYBER PAKHTUNKHWA'!F40) -> 0 | G40: =SUM(MPR!G40+KARACHI!G40+SINDH!G40+'GILGIT BALTISTAN'!G40+'AZAD KHASHMIR'!G40+'KHYBER PAKHTUNKHWA'!G40) -> 0 | H40: =SUM(MPR!H40+KARACHI!H40+SINDH!H40+'GILGIT BALTISTAN'!H40+'AZAD KHASHMIR'!H40+'KHYBER PAKHTUNKHWA'!H40) -> 0 | I40: =SUM(MPR!I40+KARACHI!I40+SINDH!I40+'GILGIT BALTISTAN'!I40+'AZAD KHASHMIR'!I40+'KHYBER PAKHTUNKHWA'!I40) -> 0 | ... M40: =SUM(MPR!M40+KARACHI!M40+SINDH!M40+'GILGIT BALTISTAN'!M40+'AZAD KHASHMIR'!M40+'KHYBER PAKHTUNKHWA'!M40) -> 0 | O40: =SUM(MPR!O40+KARACHI!O40+SINDH!O40+'GILGIT BALTISTAN'!O40:O41+'AZAD KHASHMIR'!O40:O41+'KHYBER PAKHTUNKHWA'!O40:O41) -> 436 | P40: =SUM(MPR!P40+KARACHI!P40+SINDH!P40+'GILGIT BALTISTAN'!P40:P41+'AZAD KHASHMIR'!P40:P41+'KHYBER PAKHTUNKHWA'!P40:P41) -> 1151 | Q40: =SUM(MPR!Q40+KARACHI!Q40+SINDH!Q40+'GILGIT BALTISTAN'!Q40:Q41+'AZAD KHASHMIR'!Q40:Q41+'KHYBER PAKHTUNKHWA'!Q40:Q41) -> 3427 | R40: =SUM(MPR!R40+KARACHI!R40+SINDH!R40+'GILGIT BALTISTAN'!R40:R41+'AZAD KHASHMIR'!R40:R41+'KHYBER PAKHTUNKHWA'!R40:R41) -> 289 | S40: =SUM(MPR!S40+KARACHI!S40+SINDH!S40+'GILGIT BALTISTAN'!S40:S41+'AZAD KHASHMIR'!S40:S41+'KHYBER PAKHTUNKHWA'!S40:S41) -> 929 | T40: =SUM(MPR!T40+KARACHI!T40+SINDH!T40+'GILGIT BALTISTAN'!T40:T41+'AZAD KHASHMIR'!T40:T41+'KHYBER PAKHTUNKHWA'!T40:T41) -> 2870 | U40: =SUM(MPR!U40+KARACHI!U40+SINDH!U40+'GILGIT BALTISTAN'!U40:U41+'AZAD KHASHMIR'!U40:U41+'KHYBER PAKHTUNKHWA'!U40:U41) -> 1 | V40: =SUM(MPR!V40+KARACHI!V40+SINDH!V40+'GILGIT BALTISTAN'!V40:V41+'AZAD KHASHMIR'!V40:V41+'KHYBER PAKHTUNKHWA'!V40:V41) -> 7 | W40: =SUM(MPR!W40+KARACHI!W40+SINDH!W40+'GILGIT BALTISTAN'!W40:W41+'AZAD KHASHMIR'!W40:W41+'KHYBER PAKHTUNKHWA'!W40:W41) -> 169 | X40: 3HR | Y40: =SUM(MPR!Y40+KARACHI!Y40+SINDH!Y40+'GILGIT BALTISTAN'!Y40+'AZAD KHASHMIR'!Y40+'KHYBER PAKHTUNKHWA'!Y40) -> 0 | Z40: =SUM(MPR!Z40+KARACHI!Z40+SINDH!Z40+'GILGIT BALTISTAN'!Z40+'AZAD KHASHMIR'!Z40+'KHYBER PAKHTUNKHWA'!Z40) -> 2 | AA40: =SUM(MPR!AA40+KARACHI!AA40+SINDH!AA40+'GILGIT BALTISTAN'!AA40+'AZAD KHASHMIR'!AA40+'KHYBER PAKHTUNKHWA'!AA40) -> 38 | AB40: =SUM(MPR!AB40+KARACHI!AB40+SINDH!AB40+'GILGIT BALTISTAN'!AB40+'AZAD KHASHMIR'!AB40+'KHYBER PAKHTUNKHWA'!AB40) -> 0 | AC40: =SUM(MPR!AC40+KARACHI!AC40+SINDH!AC40+'GILGIT BALTISTAN'!AC40+'AZAD KHASHMIR'!AC40+'KHYBER PAKHTUNKHWA'!AC40) -> 0 | AD40: =SUM(MPR!AD40+KARACHI!AD40+SINDH!AD40+'GILGIT BALTISTAN'!AD40+'AZAD KHASHMIR'!AD40+'KHYBER PAKHTUNKHWA'!AD40) -> 0
