Workbook
Name Print_Area_MI: #REF!
Name Print_Area_MI: #REF!
Name Print_Area_MI: #REF!
Name Print_Area_MI: #REF!
Name Print_Area_MI: #REF!

Sheet MPR
A2: QUARTERLY REPORT ON TB CASES REGISTRATION
A3: INDIVIDUAL/CONSOLIDATED (TICK ONE) | U3: TB - 07
A4: Name of TB Care Facility (BMU) : | E4: MANGHOPIR | H4: District : | L4: Central : | Q4: Patients registered during | U4: 1st Quarter | X4: of Year 2023
A6: Name of TB Coodinator/Facility incharge : | G6: ___________________________________________________ | Q6: Date of completion of this form : | V6: _______________________
A8: Block 1: | J8: New (N) | L8: Relapse ® | N8: Previous Treatment History Unknown (UK) | P8: N+R+UK | R8: Previously treated ( Excluding Relapse) | X8: Total
A9: All TB Cases Registered | R9: Treatment after failure | T9: Treatment after lost to follow-up | V9: Other previously treated
A11: Pulmonary, Bacteriologically Confermid | J11: 6 | L11: 0 | N11: 0 | P11: 6 | R11: 0 | T11: 0 | V11: 0 | X11: 6
A12: Pulmonary , Clinically Diagnosed | J12: 1 | L12: 0 | N12: 0 | P12: 1 | R12: 0 | T12: 0 | V12: 0 | X12: 1
A13: Extra Pulmonary, Bacteriologically Confermid | J13: 0 | L13: 0 | N13: 0 | P13: 0 | R13: 0 | T13: 0 | V13: 0 | X13: 0
A14: Extra Pulmonary , Clinically Diagnosed | J14: 0 | L14: 0 | N14: 0 | P14: 0 | R14: 0 | T14: 0 | V14: 0 | X14: 0
A15: Total | J15: 7 | L15: 0 | N15: 0 | P15: 7 | R15: 0 | T15: 0 | V15: 0 | X15: 7
A16: Block 2: All New, Relapse and previous treatment history unknown Cases registered during the period by Age Group and Gender
H17: 0-4 | J17: 5-14 | L17: 15-24 | N17: 25-34 | P17: 35-44 | R17: 45-54 | T17: 55-64 | V17: 65 & Above | X17: Total
H18: M | I18: F | J18: M | K18: F | L18: M | M18: F | N18: M | O18: F | P18: M | Q18: F | R18: M | S18: F | T18: M | U18: F | V18: M | W18: F | X18: M | Y18: F
A19: Pulmonary, Bacteriologically Confermid | H19: 0 | I19: 0 | J19: 0 | K19: 2 | L19: 0 | M19: 0 | N19: 0 | O19: 0 | P19: 0 | Q19: 2 | R19: 0 | S19: 0 | T19: 1 | U19: 0 | V19: 1 | W19: 0 | X19: 2 | Y19: 4
A20: Pulmonary , Clinically Diagnosed | H20: 0 | I20: 0 | J20: 0 | K20: 0 | L20: 1 | M20: 0 | N20: 0 | O20: 0 | P20: 0 | Q20: 0 | R20: 0 | S20: 0 | T20: 0 | U20: 0 | V20: 0 | W20: 0 | X20: 1 | Y20: 0
A21: Extra Pulmonary, Bacteriologically Confermid | H21: 0 | I21: 0 | J21: 0 | K21: 0 | L21: 0 | M21: 0 | N21: 0 | O21: 0 | P21: 0 | Q21: 0 | R21: 0 | S21: 0 | T21: 0 | U21: 0 | V21: 0 | W21: 0 | X21: 0 | Y21: 0
A22: Extra Pulmonary , Clinically Diagnosed | H22: 0 | I22: 0 | J22: 0 | K22: 0 | L22: 0 | M22: 0 | N22: 0 | O22: 0 | P22: 0 | Q22: 0 | R22: 0 | S22: 0 | T22: 0 | U22: 0 | V22: 0 | W22: 0 | X22: 0 | Y22: 0
A23: Total | H23: 0 | I23: 0 | J23: 0 | K23: 2 | L23: 1 | M23: 0 | N23: 0 | O23: 0 | P23: 0 | Q23: 2 | R23: 0 | S23: 0 | T23: 1 | U23: 0 | V23: 1 | W23: 0 | X23: 3 | Y23: 4
A25: Block 3: Presumptive TB Cases Identified Laboratory Diagnosis and use of WRD | M25: Block 4 : TB HIV Activities
A26: Total New OPD in Quarter | B26: No. of presumptive TB cases identified | C26: Presumptive Identified through Community Referrals (LHWs) | D26: No. of Presumptive TB Patients tested Using | F26: Among Presumptive TB cases tested number reported B+ | J26: Among all registered number of B+ TB Cases | K26: Amoung All (N+R+UK) number tested by Gene Xpert | M26: No. of TB patients tested for HIV | O26: TB Patients tested positive for HIV | Q26: HIV positive TB Patients put on ART
D27: AFB | E27: Xpert | F27: AFB | G27: Xpert | H27: AFB + Xpert | I27: G.Tot | M27: 0 | O27: 0 | Q27: 0
A28: 2163 | B28: 43 | C28: 0 | D28: 29 | E28: 1 | F28: 6 | G28: 1 | H28: 7 | I28: 7 | J28: 3 | K28: 0 | M28: HIV patient tested for TB | O28: HIV patients tested positive for TB | Q28: TB positive HIV patients put on TB Tx | T28: HIV positive TB -Ve patients on TPT
M29: 0 | O29: 0 | Q29: 0 | U29: 0-4 | W29: 5-14 | X29: 15 & above
T30: 6H | U30: 0 | W30: 0 | X30: 0
T31: 3HR | U31: 0 | W31: 0 | X31: 0
T32: 3 HP | U32: 0 | W32: 0 | X32: 0
A34: Block 5 : Bacteriologically Confermid TB Cases with DST Result | M34: Block 6 : Contact Tracing HH *
F35: Rifampicin | H35: Isoniazid | J35: Fluoroquninolone | M35: Total No. of HH of B+ PTB | O35: No. of HH contacts of B+ PTB Cases Screened | Q35: Amoung HH contact screened, No. of TB Cases diagnosed | S35: No. of HH Contacts Initiated on TPT | W35: HIV negative Immuno compromised on TPT
F36: Result | G36: Resistant | H36: Result | I36: Resistant | J36: Result | K36: Resistant | M36: <=5yrs | N36: >5yrs | O36: <=5yrs | P36: >5yrs | Q36: <=5yrs | R36: >5yrs | T36: 0-4 | U36: 5-14 | V36: 15+ | W36: 0-4 | X36: 5-14 | Y36: 15+
A37: New + UK | F37: 0 | G37: 0 | H37: 0 | I37: 0 | J37: 0 | K37: 0 | M37: 0 | N37: 20 | O37: 0 | P37: 0 | Q37: 0 | R37: 0 | S37: 6H | T37: 0 | U37: 0 | V37: 0 | W37: 0 | X37: 0 | Y37: 0
A38: Relapse | F38: 0 | G38: 0 | H38: 0 | I38: 0 | J38: 0 | K38: 0 | S38: 3HR | T38: 0 | U38: 0 | V38: 0 | W38: 0 | X38: 0 | Y38: 0
A39: Previously treated | F39: 0 | G39: 0 | H39: 0 | I39: 0 | J39: 0 | K39: 0 | S39: 3 HP | T39: 0 | U39: 0 | V39: 0 | W39: 0 | X39: 0 | Y39: 0
A40: Total | F40: 0 | G40: 0 | H40: 0 | I40: 0 | J40: 0 | K40: 0
A41: QUARTERLY REPORT ON TB CASES REGISTRATION
A42: INDIVIDUAL/CONSOLIDATED (TICK ONE) | U42: TB - 07
A43: Name of TB Care Facility (BMU) : | E43: MANGHOPIR | H43: District : | J43: 0 | L43: Central : | N43: 0 | Q43: Patients registered during | U43: 2nd Quarter | X43: of Year 2023
A45: Name of TB Coodinator/Facility incharge : | G45: ___________________________________________________ | Q45: Date of completion of this form : | V45: _______________________
A47: Block 1: | J47: New (N) | L47: Relapse ® | N47: Previous Treatment History Unknown (UK) | P47: N+R+UK | R47: Previously treated ( Excluding Relapse) | X47: Total
A48: All TB Cases Registered | R48: Treatment after failure | T48: Treatment after lost to follow-up | V48: Other previously treated
...

Sheet KARACHI
A2: QUARTERLY REPORT ON TB CASES REGISTRATION
A3: INDIVIDUAL/CONSOLIDATED (TICK ONE) | U3: TB - 07
A4: Name of TB Care Facility (BMU) : | E4: KARACHI | H4: District : | L4: Central : | N4: CONSOLIDATED | Q4: Patients registered during | U4: 1st Quarter | X4: of Year 2023
A6: Name of TB Coodinator/Facility incharge : | G6: ___________________________________________________ | Q6: Date of completion of this form : | V6: _______________________
A8: Block 1: | J8: New (N) | L8: Relapse ® | N8: Previous Treatment History Unknown (UK) | P8: N+R+UK | R8: Previously treated ( Excluding Relapse) | X8: Total
A9: All TB Cases Registered | R9: Treatment after failure | T9: Treatment after lost to follow-up | V9: Other previously treated
A11: Pulmonary, Bacteriologically Confermid | J11: 110 | L11: 14 | N11: 0 | P11: 124 | R11: 0 | T11: 0 | V11: 2 | X11: 126
A12: Pulmonary , Clinically Diagnosed | J12: 97 | L12: 19 | N12: 1 | P12: 117 | R12: 0 | T12: 1 | V12: 2 | X12: 120
A13: Extra Pulmonary, Bacteriologically Confermid | J13: 0 | L13: 0 | N13: 0 | P13: 0 | R13: 0 | T13: 0 | V13: 0 | X13: 0
A14: Extra Pulmonary , Clinically Diagnosed | J14: 58 | L14: 4 | N14: 0 | P14: 62 | R14: 0 | T14: 0 | V14: 5 | X14: 67
A15: Total | J15: 265 | L15: 37 | N15: 1 | P15: 303 | R15: 0 | T15: 1 | V15: 9 | X15: 313
A16: Block 2: All New, Relapse and previous treatment history unknown Cases registered during the period by Age Group and Gender
H17: 0-4 | J17: 5-14 | L17: 15-24 | N17: 25-34 | P17: 35-44 | R17: 45-54 | T17: 55-64 | V17: 65 & Above | X17: Total
H18: M | I18: F | J18: M | K18: F | L18: M | M18: F | N18: M | O18: F | P18: M | Q18: F | R18: M | S18: F | T18: M | U18: F | V18: M | W18: F | X18: M | Y18: F
A19: Pulmonary, Bacteriologically Confermid | H19: 0 | I19: 0 | J19: 0 | K19: 4 | L19: 15 | M19: 28 | N19: 13 | O19: 12 | P19: 12 | Q19: 6 | R19: 9 | S19: 5 | T19: 9 | U19: 2 | V19: 7 | W19: 2 | X19: 65 | Y19: 59
A20: Pulmonary , Clinically Diagnosed | H20: 0 | I20: 0 | J20: 2 | K20: 2 | L20: 11 | M20: 15 | N20: 10 | O20: 9 | P20: 7 | Q20: 10 | R20: 11 | S20: 10 | T20: 9 | U20: 8 | V20: 10 | W20: 3 | X20: 60 | Y20: 57
A21: Extra Pulmonary, Bacteriologically Confermid | H21: 0 | I21: 0 | J21: 0 | K21: 0 | L21: 0 | M21: 0 | N21: 0 | O21: 0 | P21: 0 | Q21: 0 | R21: 0 | S21: 0 | T21: 0 | U21: 0 | V21: 0 | W21: 0 | X21: 0 | Y21: 0
A22: Extra Pulmonary , Clinically Diagnosed | H22: 0 | I22: 1 | J22: 4 | K22: 3 | L22: 8 | M22: 12 | N22: 5 | O22: 7 | P22: 5 | Q22: 7 | R22: 2 | S22: 1 | T22: 1 | U22: 2 | V22: 3 | W22: 1 | X22: 28 | Y22: 34
A23: Total | H23: 0 | I23: 1 | J23: 6 | K23: 9 | L23: 34 | M23: 55 | N23: 28 | O23: 28 | P23: 24 | Q23: 23 | R23: 22 | S23: 16 | T23: 19 | U23: 12 | V23: 20 | W23: 6 | X23: 153 | Y23: 150
A25: Block 3: Presumptive TB Cases Identified Laboratory Diagnosis and use of WRD | M25: Block 4 : TB HIV Activities
A26: Total New OPD in Quarter | B26: No. of presumptive TB cases identified | C26: Presumptive Identified through Community Referrals (LHWs) | D26: No. of Presumptive TB Patients tested Using | F26: Among Presumptive TB cases tested number reported B+ | J26: Among all registered number of B+ TB Cases | K26: Amoung All (N+R+UK) number tested by Gene Xpert | M26: No. of TB patients tested for HIV | O26: TB Patients tested positive for HIV | Q26: HIV positive TB Patients put on ART
D27: AFB | E27: Xpert | F27: AFB | G27: Xpert | H27: AFB + Xpert | I27: G.Tot | M27: 68 | O27: 0 | Q27: 0
A28: 5575 | B28: 914 | C28: 50 | D28: 443 | E28: 472 | F28: 20 | G28: 38 | H28: 28 | I28: 113 | J28: 122 | K28: 237 | M28: HIV patient tested for TB | O28: HIV patients tested positive for TB | Q28: TB positive HIV patients put on TB Tx | T28: HIV positive TB -Ve patients on TPT
M29: 1 | O29: 0 | Q29: 0 | U29: 0-4 | W29: 5-14 | X29: 15 & above
T30: 6H | U30: 0 | W30: 0 | X30: 0
T31: 3HR | U31: 0 | W31: 0 | X31: 0
T32: 3 HP | U32: 0 | W32: 0 | X32: 0
A34: Block 5 : Bacteriologically Confermid TB Cases with DST Result | M34: Block 6 : Contact Tracing HH *
F35: Rifampicin | H35: Isoniazid | J35: Fluoroquninolone | M35: Total No. of HH of B+ PTB | O35: No. of HH contacts of B+ PTB Cases Screened | Q35: Amoung HH contact screened, No. of TB Cases diagnosed | S35: No. of HH Contacts Initiated on TPT | W35: HIV negative Immuno compromised on TPT
F36: Result | G36: Resistant | H36: Result | I36: Resistant | J36: Result | K36: Resistant | M36: <=5yrs | N36: >5yrs | O36: <=5yrs | P36: >5yrs | Q36: <=5yrs | R36: >5yrs | T36: 0-4 | U36: 5-14 | V36: 15+ | W36: 0-4 | X36: 5-14 | Y36: 15+
A37: New + UK | F37: 105 | G37: 3 | H37: 0 | I37: 0 | J37: 0 | K37: 0 | M37: 122 | N37: 420 | O37: 42 | P37: 269 | Q37: 0 | R37: 13 | S37: 6H | T37: 0 | U37: 0 | V37: 0 | W37: 0 | X37: 0 | Y37: 0
A38: Relapse | F38: 12 | G38: 0 | H38: 0 | I38: 0 | J38: 0 | K38: 0 | S38: 3HR | T38: 0 | U38: 0 | V38: 0 | W38: 0 | X38: 0 | Y38: 0
A39: Previously treated | F39: 0 | G39: 0 | H39: 0 | I39: 0 | J39: 0 | K39: 0 | S39: 3 HP | T39: 0 | U39: 0 | V39: 0 | W39: 0 | X39: 0 | Y39: 0
A40: Total | F40: 117 | G40: 3 | H40: 0 | I40: 0 | J40: 0 | K40: 0
A41: QUARTERLY REPORT ON TB CASES REGISTRATION
A42: INDIVIDUAL/CONSOLIDATED (TICK ONE) | U42: TB - 07
A43: Name of TB Care Facility (BMU) : | E43: KARACHI | H43: District : | J43: 0 | L43: Central : | N43: CONSOLIDATED | Q43: Patients registered during | U43: 2nd Quarter | X43: of Year 2023
A45: Name of TB Coodinator/Facility incharge : | G45: ___________________________________________________ | Q45: Date of completion of this form : | V45: _______________________
A47: Block 1: | J47: New (N) | L47: Relapse ® | N47: Previous Treatment History Unknown (UK) | P47: N+R+UK | R47: Previously treated ( Excluding Relapse) | X47: Total
A48: All TB Cases Registered | R48: Treatment after failure | T48: Treatment after lost to follow-up | V48: Other previously treated
...

Sheet SINDH
A2: QUARTERLY REPORT ON TB CASES REGISTRATION
A3: INDIVIDUAL/CONSOLIDATED (TICK ONE) | U3: TB - 07
A4: Name of TB Care Facility (BMU) : | E4: SINDH | H4: District : | L4: Central : | N4: CONSOLIDATED | Q4: Patients registered during | U4: 1st Quarter | X4: of Year 2023
A6: Name of TB Coodinator/Facility incharge : | G6: ___________________________________________________ | Q6: Date of completion of this form : | V6: _______________________
A8: Block 1: | J8: New (N) | L8: Relapse ® | N8: Previous Treatment History Unknown (UK) | P8: N+R+UK | R8: Previously treated ( Excluding Relapse) | X8: Total
A9: All TB Cases Registered | R9: Treatment after failure | T9: Treatment after lost to follow-up | V9: Other previously treated
A11: Pulmonary, Bacteriologically Confermid | J11: 42 | L11: 7 | N11: 0 | P11: 49 | R11: 0 | T11: 0 | V11: 0 | X11: 49
A12: Pulmonary , Clinically Diagnosed | J12: 6 | L12: 3 | N12: 0 | P12: 9 | R12: 1 | T12: 0 | V12: 0 | X12: 10
A13: Extra Pulmonary, Bacteriologically Confermid | J13: 0 | L13: 0 | N13: 0 | P13: 0 | R13: 0 | T13: 0 | V13: 0 | X13: 0
A14: Extra Pulmonary , Clinically Diagnosed | J14: 4 | L14: 0 | N14: 0 | P14: 4 | R14: 0 | T14: 0 | V14: 0 | X14: 4
A15: Total | J15: 52 | L15: 10 | N15: 0 | P15: 62 | R15: 1 | T15: 0 | V15: 0 | X15: 63
A16: Block 2: All New, Relapse and previous treatment history unknown Cases registered during the period by Age Group and Gender
H17: 0-4 | J17: 5-14 | L17: 15-24 | N17: 25-34 | P17: 35-44 | R17: 45-54 | T17: 55-64 | V17: 65 & Above | X17: Total
H18: M | I18: F | J18: M | K18: F | L18: M | M18: F | N18: M | O18: F | P18: M | Q18: F | R18: M | S18: F | T18: M | U18: F | V18: M | W18: F | X18: M | Y18: F
A19: Pulmonary, Bacteriologically Confermid | H19: 0 | I19: 0 | J19: 0 | K19: 0 | L19: 7 | M19: 4 | N19: 5 | O19: 3 | P19: 2 | Q19: 6 | R19: 6 | S19: 3 | T19: 1 | U19: 3 | V19: 7 | W19: 2 | X19: 28 | Y19: 21
A20: Pulmonary , Clinically Diagnosed | H20: 0 | I20: 0 | J20: 0 | K20: 0 | L20: 1 | M20: 2 | N20: 1 | O20: 0 | P20: 1 | Q20: 0 | R20: 1 | S20: 0 | T20: 0 | U20: 0 | V20: 1 | W20: 2 | X20: 5 | Y20: 4
A21: Extra Pulmonary, Bacteriologically Confermid | H21: 0 | I21: 0 | J21: 0 | K21: 0 | L21: 0 | M21: 0 | N21: 0 | O21: 0 | P21: 0 | Q21: 0 | R21: 0 | S21: 0 | T21: 0 | U21: 0 | V21: 0 | W21: 0 | X21: 0 | Y21: 0
A22: Extra Pulmonary , Clinically Diagnosed | H22: 0 | I22: 0 | J22: 0 | K22: 0 | L22: 0 | M22: 1 | N22: 1 | O22: 0 | P22: 0 | Q22: 0 | R22: 0 | S22: 1 | T22: 0 | U22: 1 | V22: 0 | W22: 0 | X22: 1 | Y22: 3
A23: Total | H23: 0 | I23: 0 | J23: 0 | K23: 0 | L23: 8 | M23: 7 | N23: 7 | O23: 3 | P23: 3 | Q23: 6 | R23: 7 | S23: 4 | T23: 1 | U23: 4 | V23: 8 | W23: 4 | X23: 34 | Y23: 28
A25: Block 3: Presumptive TB Cases Identified Laboratory Diagnosis and use of WRD | M25: Block 4 : TB HIV Activities
A26: Total New OPD in Quarter | B26: No. of presumptive TB cases identified | C26: Presumptive Identified through Community Referrals (LHWs) | D26: No. of Presumptive TB Patients tested Using | F26: Among Presumptive TB cases tested number reported B+ | J26: Among all registered number of B+ TB Cases | K26: Amoung All (N+R+UK) number tested by Gene Xpert | M26: No. of TB patients tested for HIV | O26: TB Patients tested positive for HIV | Q26: HIV positive TB Patients put on ART
D27: AFB | E27: Xpert | F27: AFB | G27: Xpert | H27: AFB + Xpert | I27: G.Tot | M27: 0 | O27: 0 | Q27: 0
A28: 39519 | B28: 367 | C28: 0 | D28: 260 | E28: 94 | F28: 2 | G28: 1 | H28: 45 | I28: 48 | J28: 49 | K28: 53 | M28: HIV patient tested for TB | O28: HIV patients tested positive for TB | Q28: TB positive HIV patients put on TB Tx | T28: HIV positive TB -Ve patients on TPT
M29: 0 | O29: 0 | Q29: 0 | U29: 0-4 | W29: 5-14 | X29: 15 & above
T30: 6H | U30: 0 | W30: 0 | X30: 0
T31: 3HR | U31: 0 | W31: 0 | X31: 0
T32: 3 HP | U32: 0 | W32: 0 | X32: 0
A34: Block 5 : Bacteriologically Confermid TB Cases with DST Result | M34: Block 6 : Contact Tracing HH *
F35: Rifampicin | H35: Isoniazid | J35: Fluoroquninolone | M35: Total No. of HH of B+ PTB | O35: No. of HH contacts of B+ PTB Cases Screened | Q35: Amoung HH contact screened, No. of TB Cases diagnosed | S35: No. of HH Contacts Initiated on TPT | W35: HIV negative Immuno compromised on TPT
F36: Result | G36: Resistant | H36: Result | I36: Resistant | J36: Result | K36: Resistant | M36: <=5yrs | N36: >5yrs | O36: <=5yrs | P36: >5yrs | Q36: <=5yrs | R36: >5yrs | T36: 0-4 | U36: 5-14 | V36: 15+ | W36: 0-4 | X36: 5-14 | Y36: 15+
A37: New + UK | F37: 44 | G37: 0 | H37: 0 | I37: 0 | J37: 0 | K37: 0 | M37: 30 | N37: 189 | O37: 0 | P37: 31 | Q37: 0 | R37: 2 | S37: 6H | T37: 0 | U37: 0 | V37: 0 | W37: 0 | X37: 0 | Y37: 0
A38: Relapse | F38: 10 | G38: 0 | H38: 0 | I38: 0 | J38: 0 | K38: 0 | S38: 3HR | T38: 0 | U38: 0 | V38: 0 | W38: 0 | X38: 0 | Y38: 0
A39: Previously treated | F39: 1 | G39: 0 | H39: 0 | I39: 0 | J39: 0 | K39: 0 | S39: 3 HP | T39: 0 | U39: 0 | V39: 0 | W39: 0 | X39: 0 | Y39: 0
A40: Total | F40: 55 | G40: 0 | H40: 0 | I40: 0 | J40: 0 | K40: 0
A41: QUARTERLY REPORT ON TB CASES REGISTRATION
A42: INDIVIDUAL/CONSOLIDATED (TICK ONE) | U42: TB - 07
A43: Name of TB Care Facility (BMU) : | E43: SINDH | H43: District : | J43: 0 | L43: Central : | N43: CONSOLIDATED | Q43: Patients registered during | U43: 2nd Quarter | X43: of Year 2023
A45: Name of TB Coodinator/Facility incharge : | G45: ___________________________________________________ | Q45: Date of completion of this form : | V45: _______________________
A47: Block 1: | J47: New (N) | L47: Relapse ® | N47: Previous Treatment History Unknown (UK) | P47: N+R+UK | R47: Previously treated ( Excluding Relapse) | X47: Total
A48: All TB Cases Registered | R48: Treatment after failure | T48: Treatment after lost to follow-up | V48: Other previously treated
...

Sheet GILGIT -BALTISTAN
A2: QUARTERLY REPORT ON TB CASES REGISTRATION
A3: INDIVIDUAL/CONSOLIDATED (TICK ONE) | U3: TB - 07
A4: Name of TB Care Facility (BMU) : | E4: GILGIT BALTISTAN | H4: District : | L4: Central : | N4: CONSOLIDATED | Q4: Patients registered during | U4: 1st Quarter | X4: of Year 2023
A6: Name of TB Coodinator/Facility incharge : | G6: ___________________________________________________ | Q6: Date of completion of this form : | V6: _______________________
A8: Block 1: | J8: New (N) | L8: Relapse ® | N8: Previous Treatment History Unknown (UK) | P8: N+R+UK | R8: Previously treated ( Excluding Relapse) | X8: Total
A9: All TB Cases Registered | R9: Treatment after failure | T9: Treatment after lost to follow-up | V9: Other previously treated
A11: Pulmonary, Bacteriologically Confermid | J11: 117 | L11: 2 | N11: 0 | P11: 119 | R11: 0 | T11: 1 | V11: 0 | X11: 120
A12: Pulmonary , Clinically Diagnosed | J12: 442 | L12: 0 | N12: 0 | P12: 442 | R12: 0 | T12: 0 | V12: 0 | X12: 442
A13: Extra Pulmonary, Bacteriologically Confermid | J13: 1 | L13: 0 | N13: 0 | P13: 1 | R13: 0 | T13: 0 | V13: 0 | X13: 1
A14: Extra Pulmonary , Clinically Diagnosed | J14: 187 | L14: 0 | N14: 0 | P14: 187 | R14: 0 | T14: 0 | V14: 0 | X14: 187
A15: Total | J15: 747 | L15: 2 | N15: 0 | P15: 749 | R15: 0 | T15: 1 | V15: 0 | X15: 750
A16: Block 2: All New, Relapse and previous treatment history unknown Cases registered during the period by Age Group and Gender
H17: 0-4 | J17: 5-14 | L17: 15-24 | N17: 25-34 | P17: 35-44 | R17: 45-54 | T17: 55-64 | V17: 65 & Above | X17: Total
H18: M | I18: F | J18: M | K18: F | L18: M | M18: F | N18: M | O18: F | P18: M | Q18: F | R18: M | S18: F | T18: M | U18: F | V18: M | W18: F | X18: M | Y18: F
A19: Pulmonary, Bacteriologically Confermid | H19: 0 | I19: 0 | J19: 3 | K19: 8 | L19: 15 | M19: 21 | N19: 9 | O19: 15 | P19: 4 | Q19: 9 | R19: 2 | S19: 6 | T19: 7 | U19: 4 | V19: 6 | W19: 10 | X19: 46 | Y19: 73
A20: Pulmonary , Clinically Diagnosed | H20: 104 | I20: 106 | J20: 39 | K20: 31 | L20: 19 | M20: 18 | N20: 17 | O20: 18 | P20: 11 | Q20: 17 | R20: 9 | S20: 12 | T20: 4 | U20: 15 | V20: 16 | W20: 6 | X20: 219 | Y20: 223
A21: Extra Pulmonary, Bacteriologically Confermid | H21: 0 | I21: 0 | J21: 0 | K21: 1 | L21: 0 | M21: 0 | N21: 0 | O21: 0 | P21: 0 | Q21: 0 | R21: 0 | S21: 0 | T21: 0 | U21: 0 | V21: 0 | W21: 0 | X21: 0 | Y21: 1
A22: Extra Pulmonary , Clinically Diagnosed | H22: 18 | I22: 17 | J22: 18 | K22: 10 | L22: 21 | M22: 13 | N22: 12 | O22: 15 | P22: 10 | Q22: 15 | R22: 6 | S22: 5 | T22: 3 | U22: 7 | V22: 15 | W22: 2 | X22: 103 | Y22: 84
A23: Total | H23: 122 | I23: 123 | J23: 60 | K23: 50 | L23: 55 | M23: 52 | N23: 38 | O23: 48 | P23: 25 | Q23: 41 | R23: 17 | S23: 23 | T23: 14 | U23: 26 | V23: 37 | W23: 18 | X23: 368 | Y23: 381
A25: Block 3: Presumptive TB Cases Identified Laboratory Diagnosis and use of WRD | M25: Block 4 : TB HIV Activities
A26: Total New OPD in Quarter | B26: No. of presumptive TB cases identified | C26: Presumptive Identified through Community Referrals (LHWs) | D26: No. of Presumptive TB Patients tested Using | F26: Among Presumptive TB cases tested number reported B+ | J26: Among all registered number of B+ TB Cases | K26: Amoung All (N+R+UK) number tested by Gene Xpert | M26: No. of TB patients tested for HIV | O26: TB Patients tested positive for HIV | Q26: HIV positive TB Patients put on ART
D27: AFB | E27: Xpert | F27: AFB | G27: Xpert | H27: AFB + Xpert | I27: G.Tot | M27: 0 | O27: 0 | Q27: 0
A28: 179930 | B28: 3347 | D28: 2762 | E28: 0 | F28: 105 | G28: 0 | H28: 0 | I28: 105 | J28: 107 | K28: 124 | M28: HIV patient tested for TB | O28: HIV patients tested positive for TB | Q28: TB positive HIV patients put on TB Tx | T28: HIV positive TB -Ve patients on TPT
U29: 0-4 | W29: 5-14 | X29: 15 & above
T30: 6H
T31: 3HR
T32: 3 HP
A34: Block 5 : Bacteriologically Confermid TB Cases with DST Result | M34: Block 6 : Contact Tracing HH *
F35: Rifampicin | H35: Isoniazid | J35: Fluoroquninolone | M35: Total No. of HH of B+ PTB | O35: No. of HH contacts of B+ PTB Cases Screened | Q35: Amoung HH contact screened, No. of TB Cases diagnosed | S35: No. of HH Contacts Initiated on TPT | W35: HIV negative Immuno compromised on TPT
F36: Result | G36: Resistant | H36: Result | I36: Resistant | J36: Result | K36: Resistant | M36: <=5yrs | N36: >5yrs | O36: <=5yrs | P36: >5yrs | Q36: <=5yrs | R36: >5yrs | T36: 0-4 | U36: 5-14 | V36: 15+ | W36: 0-4 | X36: 5-14 | Y36: 15+
A37: New + UK | F37: 79 | G37: 1 | H37: 0 | I37: 0 | J37: 0 | K37: 0 | M37: 0 | N37: 57 | O37: 47 | P37: 99 | Q37: 0 | R37: 0 | S37: 6H | V37: 2
A38: Relapse | F38: 2 | G38: 0 | H38: 0 | I38: 0 | J38: 0 | K38: 0 | S38: 3HR
A39: Previously treated | F39: 0 | G39: 0 | H39: 0 | I39: 0 | J39: 0 | K39: 0 | S39: 3 HP
A40: Total | F40: 81 | G40: 1 | H40: 0 | I40: 0 | J40: 0 | K40: 0
A41: QUARTERLY REPORT ON TB CASES REGISTRATION
A42: INDIVIDUAL/CONSOLIDATED (TICK ONE) | U42: TB - 07
A43: Name of TB Care Facility (BMU) : | E43: GILGIT BALTISTAN | H43: District : | J43: 0 | L43: Central : | N43: CONSOLIDATED | Q43: Patients registered during | U43: 2nd Quarter | X43: of Year 2023
A45: Name of TB Coodinator/Facility incharge : | G45: ___________________________________________________ | Q45: Date of completion of this form : | V45: _______________________
A47: Block 1: | J47: New (N) | L47: Relapse ® | N47: Previous Treatment History Unknown (UK) | P47: N+R+UK | R47: Previously treated ( Excluding Relapse) | X47: Total
A48: All TB Cases Registered | R48: Treatment after failure | T48: Treatment after lost to follow-up | V48: Other previously treated
...

Sheet AZAD - KASHMIR
A2: QUARTERLY REPORT ON TB CASES REGISTRATION
A3: INDIVIDUAL/CONSOLIDATED (TICK ONE) | U3: TB - 07
A4: Name of TB Care Facility (BMU) : | E4: AZAD KASHMIR | H4: District : | L4: Central : | N4: CONSOLIDATED | Q4: Patients registered during | U4: 1st Quarter | X4: of Year 2023
A6: Name of TB Coodinator/Facility incharge : | G6: ___________________________________________________ | Q6: Date of completion of this form : | V6: _______________________
A8: Block 1: | J8: New (N) | L8: Relapse ® | N8: Previous Treatment History Unknown (UK) | P8: N+R+UK | R8: Previously treated ( Excluding Relapse) | X8: Total
A9: All TB Cases Registered | R9: Treatment after failure | T9: Treatment after lost to follow-up | V9: Other previously treated
A11: Pulmonary, Bacteriologically Confermid | J11: 704 | L11: 39 | N11: 0 | P11: 743 | R11: 1 | T11: 0 | V11: 3 | X11: 747
A12: Pulmonary , Clinically Diagnosed | J12: 408 | L12: 4 | N12: 2 | P12: 414 | R12: 0 | T12: 0 | V12: 1 | X12: 415
A13: Extra Pulmonary, Bacteriologically Confermid | J13: 3 | L13: 0 | N13: 0 | P13: 3 | R13: 0 | T13: 0 | V13: 0 | X13: 3
A14: Extra Pulmonary , Clinically Diagnosed | J14: 351 | L14: 1 | N14: 1 | P14: 353 | R14: 0 | T14: 0 | V14: 3 | X14: 356
A15: Total | J15: 1466 | L15: 44 | N15: 3 | P15: 1513 | R15: 1 | T15: 0 | V15: 7 | X15: 1521
A16: Block 2: All New, Relapse and previous treatment history unknown Cases registered during the period by Age Group and Gender
H17: 0-4 | J17: 5-14 | L17: 15-24 | N17: 25-34 | P17: 35-44 | R17: 45-54 | T17: 55-64 | V17: 65 & Above | X17: Total
H18: M | I18: F | J18: M | K18: F | L18: M | M18: F | N18: M | O18: F | P18: M | Q18: F | R18: M | S18: F | T18: M | U18: F | V18: M | W18: F | X18: M | Y18: F
A19: Pulmonary, Bacteriologically Confermid | H19: 0 | I19: 0 | J19: 1 | K19: 11 | L19: 63 | M19: 72 | N19: 54 | O19: 59 | P19: 49 | Q19: 32 | R19: 51 | S19: 44 | T19: 82 | U19: 54 | V19: 102 | W19: 69 | X19: 402 | Y19: 341 | Z19: 743 | AA19: 4
A20: Pulmonary , Clinically Diagnosed | H20: 3 | I20: 3 | J20: 6 | K20: 6 | L20: 25 | M20: 40 | N20: 25 | O20: 30 | P20: 24 | Q20: 33 | R20: 26 | S20: 31 | T20: 37 | U20: 28 | V20: 55 | W20: 42 | X20: 201 | Y20: 213
A21: Extra Pulmonary, Bacteriologically Confermid | H21: 0 | I21: 0 | J21: 1 | K21: 0 | L21: 1 | M21: 0 | N21: 0 | O21: 1 | P21: 0 | Q21: 0 | R21: 0 | S21: 0 | T21: 0 | U21: 0 | V21: 0 | W21: 0 | X21: 2 | Y21: 1
A22: Extra Pulmonary , Clinically Diagnosed | H22: 8 | I22: 4 | J22: 9 | K22: 5 | L22: 29 | M22: 35 | N22: 35 | O22: 33 | P22: 27 | Q22: 19 | R22: 23 | S22: 25 | T22: 26 | U22: 21 | V22: 33 | W22: 21 | X22: 190 | Y22: 163
A23: Total | H23: 11 | I23: 7 | J23: 17 | K23: 22 | L23: 118 | M23: 147 | N23: 114 | O23: 123 | P23: 100 | Q23: 84 | R23: 100 | S23: 100 | T23: 145 | U23: 103 | V23: 190 | W23: 132 | X23: 795 | Y23: 718 | Z23: 1513 | AA23: 8
A25: Block 3: Presumptive TB Cases Identified Laboratory Diagnosis and use of WRD | M25: Block 4 : TB HIV Activities
A26: Total New OPD in Quarter | B26: No. of presumptive TB cases identified | C26: Presumptive Identified through Community Referrals (LHWs) | D26: No. of Presumptive TB Patients tested Using | F26: Among Presumptive TB cases tested number reported B+ | J26: Among all registered number of B+ TB Cases | K26: Amoung All (N+R+UK) number tested by Gene Xpert | M26: No. of TB patients tested for HIV | O26: TB Patients tested positive for HIV | Q26: HIV positive TB Patients put on ART
D27: AFB | E27: Xpert | F27: AFB | G27: Xpert | H27: AFB + Xpert | I27: G.Tot | M27: 0 | O27: 0 | Q27: 0
A28: 237228 | B28: 8301 | C28: 0 | D28: 9252 | E28: 0 | F28: 0 | G28: 0 | H28: 261 | I28: 835 | J28: 716 | K28: 623 | M28: HIV patient tested for TB | O28: HIV patients tested positive for TB | Q28: TB positive HIV patients put on TB Tx | T28: HIV positive TB -Ve patients on TPT
M29: 0 | O29: 0 | Q29: 0 | U29: 0-4 | W29: 5-14 | X29: 15 & above
T30: 6H | U30: 0 | W30: 0 | X30: 0
T31: 3HR | U31: 0 | W31: 0 | X31: 0
T32: 3 HP | U32: 0 | W32: 0 | X32: 0
A34: Block 5 : Bacteriologically Confermid TB Cases with DST Result | M34: Block 6 : Contact Tracing HH *
F35: Rifampicin | H35: Isoniazid | J35: Fluoroquninolone | M35: Total No. of HH of B+ PTB | O35: No. of HH contacts of B+ PTB Cases Screened | Q35: Amoung HH contact screened, No. of TB Cases diagnosed | S35: No. of HH Contacts Initiated on TPT | W35: HIV negative Immuno compromised on TPT
F36: Result | G36: Resistant | H36: Result | I36: Resistant | J36: Result | K36: Resistant | M36: <=5yrs | N36: >5yrs | O36: <=5yrs | P36: >5yrs | Q36: <=5yrs | R36: >5yrs | T36: 0-4 | U36: 5-14 | V36: 15+ | W36: 0-4 | X36: 5-14 | Y36: 15+
A37: New + UK | F37: 708 | G37: 1 | H37: 1 | I37: 0 | J37: 0 | K37: 0 | M37: 1642 | N37: 113 | O37: 769 | P37: 3804 | Q37: 7 | R37: 148 | S37: 6H | T37: 0 | U37: 0 | V37: 0 | W37: 0 | X37: 0 | Y37: 0
A38: Relapse | F38: 13 | G38: 0 | H38: 0 | I38: 0 | J38: 0 | K38: 0 | S38: 3HR | T38: 0 | U38: 0 | V38: 0 | W38: 0 | X38: 0 | Y38: 0
A39: Previously treated | F39: 0 | G39: 0 | H39: 0 | I39: 0 | J39: 0 | K39: 0 | S39: 3 HP | T39: 0 | U39: 0 | V39: 0 | W39: 0 | X39: 0 | Y39: 0
A40: Total | F40: 721 | G40: 1 | H40: 1 | I40: 0 | J40: 0 | K40: 0
A41: QUARTERLY REPORT ON TB CASES REGISTRATION
A42: INDIVIDUAL/CONSOLIDATED (TICK ONE) | U42: TB - 07
A43: Name of TB Care Facility (BMU) : | E43: AZAD KASHMIR | H43: District : | J43: 0 | L43: Central : | N43: CONSOLIDATED | Q43: Patients registered during | U43: 2nd Quarter | X43: of Year 2023
A45: Name of TB Coodinator/Facility incharge : | G45: ___________________________________________________ | Q45: Date of completion of this form : | V45: _______________________
A47: Block 1: | J47: New (N) | L47: Relapse ® | N47: Previous Treatment History Unknown (UK) | P47: N+R+UK | R47: Previously treated ( Excluding Relapse) | X47: Total
A48: All TB Cases Registered | R48: Treatment after failure | T48: Treatment after lost to follow-up | V48: Other previously treated
...

Sheet KPK
A2: QUARTERLY REPORT ON TB CASES REGISTRATION
A3: INDIVIDUAL/CONSOLIDATED (TICK ONE) | U3: TB - 07
A4: Name of TB Care Facility (BMU) : | E4: Khyber Pukhtunkhwa | H4: District : | L4: Central : | N4: CONSOLIDATED | Q4: Patients registered during | U4: 1st Quarter | X4: of Year 2023
A6: Name of TB Coodinator/Facility incharge : | G6: ___________________________________________________ | Q6: Date of completion of this form : | V6: _______________________
A8: Block 1: | J8: New (N) | L8: Relapse ® | N8: Previous Treatment History Unknown (UK) | P8: N+R+UK | R8: Previously treated ( Excluding Relapse) | X8: Total
A9: All TB Cases Registered | R9: Treatment after failure | T9: Treatment after lost to follow-up | V9: Other previously treated
A11: Pulmonary, Bacteriologically Confermid | J11: 34 | L11: 3 | N11: 0 | P11: 37 | R11: 0 | T11: 0 | V11: 0 | X11: 37
A12: Pulmonary , Clinically Diagnosed | J12: 27 | L12: 0 | N12: 0 | P12: 27 | R12: 0 | T12: 0 | V12: 0 | X12: 27
A13: Extra Pulmonary, Bacteriologically Confermid | J13: 0 | L13: 0 | N13: 0 | P13: 0 | R13: 0 | T13: 0 | V13: 0 | X13: 0
A14: Extra Pulmonary , Clinically Diagnosed | J14: 27 | L14: 0 | N14: 0 | P14: 27 | R14: 0 | T14: 0 | V14: 0 | X14: 27
A15: Total | J15: 88 | L15: 3 | N15: 0 | P15: 91 | R15: 0 | T15: 0 | V15: 0 | X15: 91
A16: Block 2: All New, Relapse and previous treatment history unknown Cases registered during the period by Age Group and Gender
H17: 0-4 | J17: 5-14 | L17: 15-24 | N17: 25-34 | P17: 35-44 | R17: 45-54 | T17: 55-64 | V17: 65 & Above | X17: Total
H18: M | I18: F | J18: M | K18: F | L18: M | M18: F | N18: M | O18: F | P18: M | Q18: F | R18: M | S18: F | T18: M | U18: F | V18: M | W18: F | X18: M | Y18: F
A19: Pulmonary, Bacteriologically Confermid | H19: 0 | I19: 0 | J19: 0 | K19: 0 | L19: 4 | M19: 1 | N19: 7 | O19: 3 | P19: 4 | Q19: 5 | R19: 1 | S19: 2 | T19: 4 | U19: 3 | V19: 1 | W19: 2 | X19: 21 | Y19: 16
A20: Pulmonary , Clinically Diagnosed | H20: 0 | I20: 0 | J20: 0 | K20: 3 | L20: 0 | M20: 2 | N20: 2 | O20: 3 | P20: 8 | Q20: 1 | R20: 0 | S20: 1 | T20: 2 | U20: 0 | V20: 3 | W20: 2 | X20: 15 | Y20: 12
A21: Extra Pulmonary, Bacteriologically Confermid | H21: 0 | I21: 0 | J21: 0 | K21: 0 | L21: 0 | M21: 0 | N21: 0 | O21: 0 | P21: 0 | Q21: 0 | R21: 0 | S21: 0 | T21: 0 | U21: 0 | V21: 0 | W21: 0 | X21: 0 | Y21: 0
A22: Extra Pulmonary , Clinically Diagnosed | H22: 0 | I22: 0 | J22: 6 | K22: 1 | L22: 6 | M22: 4 | N22: 2 | O22: 0 | P22: 0 | Q22: 1 | R22: 2 | S22: 1 | T22: 2 | U22: 0 | V22: 2 | W22: 0 | X22: 20 | Y22: 7
A23: Total | H23: 0 | I23: 0 | J23: 6 | K23: 4 | L23: 10 | M23: 7 | N23: 11 | O23: 6 | P23: 12 | Q23: 7 | R23: 3 | S23: 4 | T23: 8 | U23: 3 | V23: 6 | W23: 4 | X23: 56 | Y23: 35
A25: Block 3: Presumptive TB Cases Identified Laboratory Diagnosis and use of WRD | M25: Block 4 : TB HIV Activities
A26: Total New OPD in Quarter | B26: No. of presumptive TB cases identified | C26: Presumptive Identified through Community Referrals (LHWs) | D26: No. of Presumptive TB Patients tested Using | F26: Among Presumptive TB cases tested number reported B+ | J26: Among all registered number of B+ TB Cases | K26: Amoung All (N+R+UK) number tested by Gene Xpert | M26: No. of TB patients tested for HIV | O26: TB Patients tested positive for HIV | Q26: HIV positive TB Patients put on ART
D27: AFB | E27: Xpert | F27: AFB | G27: Xpert | H27: AFB + Xpert | I27: G.Tot | M27: 0 | O27: 0 | Q27: 0
A28: 556 | B28: 208 | C28: 98 | D28: 123 | E28: 0 | F28: 24 | G28: 0 | H28: 0 | I28: 0 | J28: 23 | K28: 1 | M28: HIV patient tested for TB | O28: HIV patients tested positive for TB | Q28: TB positive HIV patients put on TB Tx | T28: HIV positive TB -Ve patients on TPT
M29: 0 | O29: 0 | Q29: 0 | U29: 0-4 | W29: 5-14 | X29: 15 & above
T30: 6H | U30: 0 | W30: 0 | X30: 0
T31: 3HR | U31: 0 | W31: 0 | X31: 0
T32: 3 HP | U32: 0 | W32: 0 | X32: 0
A34: Block 5 : Bacteriologically Confermid TB Cases with DST Result | M34: Block 6 : Contact Tracing HH *
F35: Rifampicin | H35: Isoniazid | J35: Fluoroquninolone | M35: Total No. of HH of B+ PTB | O35: No. of HH contacts of B+ PTB Cases Screened | Q35: Amoung HH contact screened, No. of TB Cases diagnosed | S35: No. of HH Contacts Initiated on TPT | W35: HIV negative Immuno compromised on TPT
F36: Result | G36: Resistant | H36: Result | I36: Resistant | J36: Result | K36: Resistant | M36: <=5yrs | N36: >5yrs | O36: <=5yrs | P36: >5yrs | Q36: <=5yrs | R36: >5yrs | T36: 0-4 | U36: 5-14 | V36: 15+ | W36: 0-4 | X36: 5-14 | Y36: 15+
A37: New + UK | F37: 0 | G37: 0 | H37: 0 | I37: 0 | J37: 0 | K37: 0 | M37: 0 | N37: 530 | O37: 0 | P37: 35 | Q37: 0 | R37: 12 | S37: 6H | T37: 0 | U37: 0 | V37: 0 | W37: 0 | X37: 0 | Y37: 0
A38: Relapse | F38: 0 | G38: 0 | H38: 0 | I38: 0 | J38: 0 | K38: 0 | S38: 3HR | T38: 0 | U38: 0 | V38: 0 | W38: 0 | X38: 0 | Y38: 0
A39: Previously treated | F39: 0 | G39: 0 | H39: 0 | I39: 0 | J39: 0 | K39: 0 | S39: 3 HP | T39: 0 | U39: 0 | V39: 0 | W39: 0 | X39: 0 | Y39: 0
A40: Total | F40: 0 | G40: 0 | H40: 0 | I40: 0 | J40: 0 | K40: 0
A41: QUARTERLY REPORT ON TB CASES REGISTRATION
A42: INDIVIDUAL/CONSOLIDATED (TICK ONE) | U42: TB - 07
A43: Name of TB Care Facility (BMU) : | E43: Khyber Pukhtunkhwa | H43: District : | J43: 0 | L43: Central : | N43: CONSOLIDATED | Q43: Patients registered during | U43: 2nd Quarter | X43: of Year 2023
A45: Name of TB Coodinator/Facility incharge : | G45: ___________________________________________________ | Q45: Date of completion of this form : | V45: _______________________
A47: Block 1: | J47: New (N) | L47: Relapse ® | N47: Previous Treatment History Unknown (UK) | P47: N+R+UK | R47: Previously treated ( Excluding Relapse) | X47: Total
A48: All TB Cases Registered | R48: Treatment after failure | T48: Treatment after lost to follow-up | V48: Other previously treated
...

Sheet All Project Total - 2023
A2: QUARTERLY REPORT ON TB CASES REGISTRATION
A3: INDIVIDUAL/CONSOLIDATED (TICK ONE) | U3: TB - 07
A4: Name of TB Care Facility (BMU) : | E4: All Project Total | H4: District : | L4: Central : | N4: CONSOLIDATED | Q4: Patients registered during | U4: 1st Quarter | X4: of Year 2023
A6: Name of TB Coodinator/Facility incharge : | G6: ___________________________________________________ | Q6: Date of completion of this form : | V6: _______________________
A8: Block 1: | J8: New (N) | L8: Relapse ® | N8: Previous Treatment History Unknown (UK) | P8: N+R+UK | R8: Previously treated ( Excluding Relapse) | X8: Total
A9: All TB Cases Registered | R9: Treatment after failure | T9: Treatment after lost to follow-up | V9: Other previously treated
A11: Pulmonary, Bacteriologically Confermid | J11: =MPR!J11+KARACHI!J11+SINDH!J11+'GILGIT -BALTISTAN'!J11+'AZAD - KASHMIR'!J11+KPK!J11 -> 1013 | L11: =MPR!L11+KARACHI!L11+SINDH!L11+'GILGIT -BALTISTAN'!L11+'AZAD - KASHMIR'!L11+KPK!L11 -> 65 | N11: =MPR!N11+KARACHI!N11+SINDH!N11+'GILGIT -BALTISTAN'!N11+'AZAD - KASHMIR'!N11+KPK!N11 -> 0 | P11: =SUM(J11+L11+N11) -> 1078 | R11: =MPR!R11+KARACHI!R11+SINDH!R11+'GILGIT -BALTISTAN'!R11+'AZAD - KASHMIR'!R11+KPK!R11 -> 1 | T11: =MPR!T11+KARACHI!T11+SINDH!T11+'GILGIT -BALTISTAN'!T11+'AZAD - KASHMIR'!T11+KPK!T11 -> 1 | V11: =MPR!V11+KARACHI!V11+SINDH!V11+'GILGIT -BALTISTAN'!V11+'AZAD - KASHMIR'!V11+KPK!V11 -> 5 | X11: =SUM(J11+L11+N11+R11+T11+V11) -> 1085
A12: Pulmonary , Clinically Diagnosed | J12: =MPR!J12+KARACHI!J12+SINDH!J12+'GILGIT -BALTISTAN'!J12+'AZAD - KASHMIR'!J12+KPK!J12 -> 981 | L12: =MPR!L12+KARACHI!L12+SINDH!L12+'GILGIT -BALTISTAN'!L12+'AZAD - KASHMIR'!L12+KPK!L12 -> 26 | N12: =MPR!N12+KARACHI!N12+SINDH!N12+'GILGIT -BALTISTAN'!N12+'AZAD - KASHMIR'!N12+KPK!N12 -> 3 | P12: =SUM(J12+L12+N12) -> 1010 | R12: =MPR!R12+KARACHI!R12+SINDH!R12+'GILGIT -BALTISTAN'!R12+'AZAD - KASHMIR'!R12+KPK!R12 -> 1 | T12: =MPR!T12+KARACHI!T12+SINDH!T12+'GILGIT -BALTISTAN'!T12+'AZAD - KASHMIR'!T12+KPK!T12 -> 1 | V12: =MPR!V12+KARACHI!V12+SINDH!V12+'GILGIT -BALTISTAN'!V12+'AZAD - KASHMIR'!V12+KPK!V12 -> 3 | X12: =SUM(J12+L12+N12+R12+T12+V12) -> 1015
A13: Extra Pulmonary, Bacteriologically Confermid | J13: =MPR!J13+KARACHI!J13+SINDH!J13+'GILGIT -BALTISTAN'!J13+'AZAD - KASHMIR'!J13+KPK!J13 -> 4 | L13: =MPR!L13+KARACHI!L13+SINDH!L13+'GILGIT -BALTISTAN'!L13+'AZAD - KASHMIR'!L13+KPK!L13 -> 0 | N13: =MPR!N13+KARACHI!N13+SINDH!N13+'GILGIT -BALTISTAN'!N13+'AZAD - KASHMIR'!N13+KPK!N13 -> 0 | P13: =SUM(J13+L13+N13) -> 4 | R13: =MPR!R13+KARACHI!R13+SINDH!R13+'GILGIT -BALTISTAN'!R13+'AZAD - KASHMIR'!R13+KPK!R13 -> 0 | T13: =MPR!T13+KARACHI!T13+SINDH!T13+'GILGIT -BALTISTAN'!T13+'AZAD - KASHMIR'!T13+KPK!T13 -> 0 | V13: =MPR!V13+KARACHI!V13+SINDH!V13+'GILGIT -BALTISTAN'!V13+'AZAD - KASHMIR'!V13+KPK!V13 -> 0 | X13: =SUM(J13+L13+N13+R13+T13+V13) -> 4
A14: Extra Pulmonary , Clinically Diagnosed | J14: =MPR!J14+KARACHI!J14+SINDH!J14+'GILGIT -BALTISTAN'!J14+'AZAD - KASHMIR'!J14+KPK!J14 -> 627 | L14: =MPR!L14+KARACHI!L14+SINDH!L14+'GILGIT -BALTISTAN'!L14+'AZAD - KASHMIR'!L14+KPK!L14 -> 5 | N14: =MPR!N14+KARACHI!N14+SINDH!N14+'GILGIT -BALTISTAN'!N14+'AZAD - KASHMIR'!N14+KPK!N14 -> 1 | P14: =SUM(J14+L14+N14) -> 633 | R14: =MPR!R14+KARACHI!R14+SINDH!R14+'GILGIT -BALTISTAN'!R14+'AZAD - KASHMIR'!R14+KPK!R14 -> 0 | T14: =MPR!T14+KARACHI!T14+SINDH!T14+'GILGIT -BALTISTAN'!T14+'AZAD - KASHMIR'!T14+KPK!T14 -> 0 | V14: =MPR!V14+KARACHI!V14+SINDH!V14+'GILGIT -BALTISTAN'!V14+'AZAD - KASHMIR'!V14+KPK!V14 -> 8 | X14: =SUM(J14+L14+N14+R14+T14+V14) -> 641
A15: Total | J15: =SUM(J11:K14) -> 2625 | L15: =SUM(L11:M14) -> 96 | N15: =SUM(N11:O14) -> 4 | P15: =SUM(J15+L15+N15) -> 2725 | R15: =SUM(R11:S14) -> 2 | T15: =SUM(T11:U14) -> 2 | V15: =SUM(V11:W14) -> 16 | X15: =SUM(J15+L15+N15+R15+T15+V15) -> 2745
A16: Block 2: All New, Relapse and previous treatment history unknown Cases registered during the period by Age Group and Gender
H17: 0-4 | J17: 5-14 | L17: 15-24 | N17: 25-34 | P17: 35-44 | R17: 45-54 | T17: 55-64 | V17: 65 & Above | X17: Total
H18: M | I18: F | J18: M | K18: F | L18: M | M18: F | N18: M | O18: F | P18: M | Q18: F | R18: M | S18: F | T18: M | U18: F | V18: M | W18: F | X18: M | Y18: F
A19: Pulmonary, Bacteriologically Confermid | H19: =MPR!H19+KARACHI!H19+SINDH!H19+'GILGIT -BALTISTAN'!H19+'AZAD - KASHMIR'!H19+KPK!H19 -> 0 | I19: =MPR!I19+KARACHI!I19+SINDH!I19+'GILGIT -BALTISTAN'!I19+'AZAD - KASHMIR'!I19+KPK!I19 -> 0 | J19: =MPR!J19+KARACHI!J19+SINDH!J19+'GILGIT -BALTISTAN'!J19+'AZAD - KASHMIR'!J19+KPK!J19 -> 4 | K19: =MPR!K19+KARACHI!K19+SINDH!K19+'GILGIT -BALTISTAN'!K19+'AZAD - KASHMIR'!K19+KPK!K19 -> 25 | L19: =MPR!L19+KARACHI!L19+SINDH!L19+'GILGIT -BALTISTAN'!L19+'AZAD - KASHMIR'!L19+KPK!L19 -> 104 | M19: =MPR!M19+KARACHI!M19+SINDH!M19+'GILGIT -BALTISTAN'!M19+'AZAD - KASHMIR'!M19+KPK!M19 -> 126 | N19: =MPR!N19+KARACHI!N19+SINDH!N19+'GILGIT -BALTISTAN'!N19+'AZAD - KASHMIR'!N19+KPK!N19 -> 88 | O19: =MPR!O19+KARACHI!O19+SINDH!O19+'GILGIT -BALTISTAN'!O19+'AZAD - KASHMIR'!O19+KPK!O19 -> 92 | ... W19: =MPR!W19+KARACHI!W19+SINDH!W19+'GILGIT -BALTISTAN'!W19+'AZAD - KASHMIR'!W19+KPK!W19 -> 85 | X19: =SUM(H19+J19+L19+N19+P19+R19+T19+V19) -> 564 | Y19: =SUM(I19+K19+M19+O19+Q19+S19+U19+W19) -> 514
A20: Pulmonary , Clinically Diagnosed | H20: =MPR!H20+KARACHI!H20+SINDH!H20+'GILGIT -BALTISTAN'!H20+'AZAD - KASHMIR'!H20+KPK!H20 -> 107 | I20: =MPR!I20+KARACHI!I20+SINDH!I20+'GILGIT -BALTISTAN'!I20+'AZAD - KASHMIR'!I20+KPK!I20 -> 109 | J20: =MPR!J20+KARACHI!J20+SINDH!J20+'GILGIT -BALTISTAN'!J20+'AZAD - KASHMIR'!J20+KPK!J20 -> 47 | K20: =MPR!K20+KARACHI!K20+SINDH!K20+'GILGIT -BALTISTAN'!K20+'AZAD - KASHMIR'!K20+KPK!K20 -> 42 | L20: =MPR!L20+KARACHI!L20+SINDH!L20+'GILGIT -BALTISTAN'!L20+'AZAD - KASHMIR'!L20+KPK!L20 -> 57 | M20: =MPR!M20+KARACHI!M20+SINDH!M20+'GILGIT -BALTISTAN'!M20+'AZAD - KASHMIR'!M20+KPK!M20 -> 77 | N20: =MPR!N20+KARACHI!N20+SINDH!N20+'GILGIT -BALTISTAN'!N20+'AZAD - KASHMIR'!N20+KPK!N20 -> 55 | O20: =MPR!O20+KARACHI!O20+SINDH!O20+'GILGIT -BALTISTAN'!O20+'AZAD - KASHMIR'!O20+KPK!O20 -> 60 | ... W20: =MPR!W20+KARACHI!W20+SINDH!W20+'GILGIT -BALTISTAN'!W20+'AZAD - KASHMIR'!W20+KPK!W20 -> 55 | X20: =SUM(H20+J20+L20+N20+P20+R20+T20+V20) -> 501 | Y20: =SUM(I20+K20+M20+O20+Q20+S20+U20+W20) -> 509
A21: Extra Pulmonary, Bacteriologically Confermid | H21: =MPR!H21+KARACHI!H21+SINDH!H21+'GILGIT -BALTISTAN'!H21+'AZAD - KASHMIR'!H21+KPK!H21 -> 0 | I21: =MPR!I21+KARACHI!I21+SINDH!I21+'GILGIT -BALTISTAN'!I21+'AZAD - KASHMIR'!I21+KPK!I21 -> 0 | J21: =MPR!J21+KARACHI!J21+SINDH!J21+'GILGIT -BALTISTAN'!J21+'AZAD - KASHMIR'!J21+KPK!J21 -> 1 | K21: =MPR!K21+KARACHI!K21+SINDH!K21+'GILGIT -BALTISTAN'!K21+'AZAD - KASHMIR'!K21+KPK!K21 -> 1 | L21: =MPR!L21+KARACHI!L21+SINDH!L21+'GILGIT -BALTISTAN'!L21+'AZAD - KASHMIR'!L21+KPK!L21 -> 1 | M21: =MPR!M21+KARACHI!M21+SINDH!M21+'GILGIT -BALTISTAN'!M21+'AZAD - KASHMIR'!M21+KPK!M21 -> 0 | N21: =MPR!N21+KARACHI!N21+SINDH!N21+'GILGIT -BALTISTAN'!N21+'AZAD - KASHMIR'!N21+KPK!N21 -> 0 | O21: =MPR!O21+KARACHI!O21+SINDH!O21+'GILGIT -BALTISTAN'!O21+'AZAD - KASHMIR'!O21+KPK!O21 -> 1 | ... W21: =MPR!W21+KARACHI!W21+SINDH!W21+'GILGIT -BALTISTAN'!W21+'AZAD - KASHMIR'!W21+KPK!W21 -> 0 | X21: =SUM(H21+J21+L21+N21+P21+R21+T21+V21) -> 2 | Y21: =SUM(I21+K21+M21+O21+Q21+S21+U21+W21) -> 2
A22: Extra Pulmonary , Clinically Diagnosed | H22: =MPR!H22+KARACHI!H22+SINDH!H22+'GILGIT -BALTISTAN'!H22+'AZAD - KASHMIR'!H22+KPK!H22 -> 26 | I22: =MPR!I22+KARACHI!I22+SINDH!I22+'GILGIT -BALTISTAN'!I22+'AZAD - KASHMIR'!I22+KPK!I22 -> 22 | J22: =MPR!J22+KARACHI!J22+SINDH!J22+'GILGIT -BALTISTAN'!J22+'AZAD - KASHMIR'!J22+KPK!J22 -> 37 | K22: =MPR!K22+KARACHI!K22+SINDH!K22+'GILGIT -BALTISTAN'!K22+'AZAD - KASHMIR'!K22+KPK!K22 -> 19 | L22: =MPR!L22+KARACHI!L22+SINDH!L22+'GILGIT -BALTISTAN'!L22+'AZAD - KASHMIR'!L22+KPK!L22 -> 64 | M22: =MPR!M22+KARACHI!M22+SINDH!M22+'GILGIT -BALTISTAN'!M22+'AZAD - KASHMIR'!M22+KPK!M22 -> 65 | N22: =MPR!N22+KARACHI!N22+SINDH!N22+'GILGIT -BALTISTAN'!N22+'AZAD - KASHMIR'!N22+KPK!N22 -> 55 | O22: =MPR!O22+KARACHI!O22+SINDH!O22+'GILGIT -BALTISTAN'!O22+'AZAD - KASHMIR'!O22+KPK!O22 -> 55 | ... W22: =MPR!W22+KARACHI!W22+SINDH!W22+'GILGIT -BALTISTAN'!W22+'AZAD - KASHMIR'!W22+KPK!W22 -> 24 | X22: =SUM(H22+J22+L22+N22+P22+R22+T22+V22) -> 342 | Y22: =SUM(I22+K22+M22+O22+Q22+S22+U22+W22) -> 291
A23: Total | H23: =SUM(H19:H22) -> 133 | I23: =SUM(I19:I22) -> 131 | J23: =SUM(J19:J22) -> 89 | K23: =SUM(K19:K22) -> 87 | L23: =SUM(L19:L22) -> 226 | M23: =SUM(M19:M22) -> 268 | N23: =SUM(N19:N22) -> 198 | O23: =SUM(O19:O22) -> 208 | ... Y23: =SUM(Y19:Y22) -> 1316
A25: Block 3: Presumptive TB Cases Identified Laboratory Diagnosis and use of WRD | M25: Block 4 : TB HIV Activities
A26: Total New OPD in Quarter | B26: No. of presumptive TB cases identified | C26: Presumptive Identified through Community Referrals (LHWs) | D26: No. of Presumptive TB Patients tested Using | F26: Among Presumptive TB cases tested number reported B+ | J26: Among all registered number of B+ TB Cases | K26: Amoung All (N+R+UK) number tested by Gene Xpert | M26: No. of TB patients tested for HIV | O26: TB Patients tested positive for HIV | Q26: HIV positive TB Patients put on ART
D27: AFB | E27: Xpert | F27: AFB | G27: Xpert | H27: AFB + Xpert | I27: G.Tot | M27: =MPR!M27+KARACHI!M27+SINDH!M27+'GILGIT -BALTISTAN'!M27:N27+'AZAD - KASHMIR'!M27:N27+KPK!M27 -> 68 | O27: =MPR!O27+KARACHI!O27+SINDH!O27+'GILGIT -BALTISTAN'!O27:P27+'AZAD - KASHMIR'!O27:P27+KPK!O27 -> 0 | Q27: =MPR!Q27+KARACHI!Q27+SINDH!Q27+'GILGIT -BALTISTAN'!Q27:Y27+'AZAD - KASHMIR'!Q27:Y27+KPK!Q27 -> 0
A28: =MPR!A28+KARACHI!A28+SINDH!A28+'GILGIT -BALTISTAN'!A28:A32+'AZAD - KASHMIR'!A28:A32+KPK!A28 -> 464971 | B28: =MPR!B28+KARACHI!B28+SINDH!B28+'GILGIT -BALTISTAN'!B28:B32+'AZAD - KASHMIR'!B28:B32+KPK!B28 -> 13180 | C28: =MPR!C28+KARACHI!C28+SINDH!C28+'GILGIT -BALTISTAN'!C28:C32+'AZAD - KASHMIR'!C28:C32+KPK!C28 -> 148 | D28: =MPR!D28+KARACHI!D28+SINDH!D28+'GILGIT -BALTISTAN'!D28:D32+'AZAD - KASHMIR'!D28:D32+KPK!D28 -> 12869 | E28: =MPR!E28+KARACHI!E28+SINDH!E28+'GILGIT -BALTISTAN'!E28:E32+'AZAD - KASHMIR'!E28:E32+KPK!E28 -> 567 | F28: =MPR!F28+KARACHI!F28+SINDH!F28+'GILGIT -BALTISTAN'!F28:F32+'AZAD - KASHMIR'!F28:F32+KPK!F28 -> 157 | G28: =MPR!G28+KARACHI!G28+SINDH!G28+'GILGIT -BALTISTAN'!G28:G32+'AZAD - KASHMIR'!G28:G32+KPK!G28 -> 40 | H28: =MPR!H28+KARACHI!H28+SINDH!H28+'GILGIT -BALTISTAN'!H28:H32+'AZAD - KASHMIR'!H28:H32+KPK!H28 -> 341 | I28: =SUM(F28:H32) -> 538 | J28: =MPR!J28+KARACHI!J28+SINDH!J28+'GILGIT -BALTISTAN'!J28:J32+'AZAD - KASHMIR'!J28:J32+KPK!J28 -> 1020 | K28: =MPR!K28+KARACHI!K28+SINDH!K28+'GILGIT -BALTISTAN'!K28:K32+'AZAD - KASHMIR'!K28:K32+KPK!K28 -> 1038 | M28: HIV patient tested for TB | O28: HIV patients tested positive for TB | Q28: TB positive HIV patients put on TB Tx | T28: HIV positive TB -Ve patients on TPT
M29: =MPR!M29+KARACHI!M29+SINDH!M29+'GILGIT -BALTISTAN'!M29:N32+'AZAD - KASHMIR'!M29:N32+KPK!M29 -> 1 | O29: =MPR!O29+KARACHI!O29+SINDH!O29+'GILGIT -BALTISTAN'!O29:P32+'AZAD - KASHMIR'!O29:P32+KPK!O29 -> 0 | Q29: =MPR!Q29+KARACHI!Q29+SINDH!Q29+'GILGIT -BALTISTAN'!Q29:S32+'AZAD - KASHMIR'!Q29:S32+KPK!Q29 -> 0 | U29: 0-4 | W29: 5-14 | X29: 15 & above
T30: 6H | U30: =MPR!U30+KARACHI!U30+SINDH!U30+'GILGIT -BALTISTAN'!U30:V30+'AZAD - KASHMIR'!U30:V30+KPK!U30 -> 0 | W30: =MPR!W30+KARACHI!W30+SINDH!W30+'GILGIT -BALTISTAN'!W30+'AZAD - KASHMIR'!W30+KPK!W30 -> 0 | X30: =MPR!X30+KARACHI!X30+SINDH!X30+'GILGIT -BALTISTAN'!X30:Y30+'AZAD - KASHMIR'!X30:Y30+KPK!X30 -> 0
T31: 3HR | U31: =MPR!U31+KARACHI!U31+SINDH!U31+'GILGIT -BALTISTAN'!U31:V31+'AZAD - KASHMIR'!U31:V31+KPK!U31 -> 0 | W31: =MPR!W31+KARACHI!W31+SINDH!W31+'GILGIT -BALTISTAN'!W31+'AZAD - KASHMIR'!W31+KPK!W31 -> 0 | X31: =MPR!X31+KARACHI!X31+SINDH!X31+'GILGIT -BALTISTAN'!X31:Y31+'AZAD - KASHMIR'!X31:Y31+KPK!X31 -> 0
T32: 3 HP | U32: =MPR!U32+KARACHI!U32+SINDH!U32+'GILGIT -BALTISTAN'!U32:V32+'AZAD - KASHMIR'!U32:V32+KPK!U32 -> 0 | W32: =MPR!W32+KARACHI!W32+SINDH!W32+'GILGIT -BALTISTAN'!W32+'AZAD - KASHMIR'!W32+KPK!W32 -> 0 | X32: =MPR!X32+KARACHI!X32+SINDH!X32+'GILGIT -BALTISTAN'!X32:Y32+'AZAD - KASHMIR'!X32:Y32+KPK!X32 -> 0
A34: Block 5 : Bacteriologically Confermid TB Cases with DST Result | M34: Block 6 : Contact Tracing HH *
F35: Rifampicin | H35: Isoniazid | J35: Fluoroquninolone | M35: Total No. of HH of B+ PTB | O35: No. of HH contacts of B+ PTB Cases Screened | Q35: Amoung HH contact screened, No. of TB Cases diagnosed | S35: No. of HH Contacts Initiated on TPT | W35: HIV negative Immuno compromised on TPT
F36: Result | G36: Resistant | H36: Result | I36: Resistant | J36: Result | K36: Resistant | M36: <=5yrs | N36: >5yrs | O36: <=5yrs | P36: >5yrs | Q36: <=5yrs | R36: >5yrs | T36: 0-4 | U36: 5-14 | V36: 15+ | W36: 0-4 | X36: 5-14 | Y36: 15+
A37: New + UK | F37: =MPR!F37+KARACHI!F37+SINDH!F37+'GILGIT -BALTISTAN'!F37+'AZAD - KASHMIR'!F37+KPK!F37 -> 936 | G37: =MPR!G37+KARACHI!G37+SINDH!G37+'GILGIT -BALTISTAN'!G37+'AZAD - KASHMIR'!G37+KPK!G37 -> 5 | H37: =MPR!H37+KARACHI!H37+SINDH!H37+'GILGIT -BALTISTAN'!H37+'AZAD - KASHMIR'!H37+KPK!H37 -> 1 | I37: =MPR!I37+KARACHI!I37+SINDH!I37+'GILGIT -BALTISTAN'!I37+'AZAD - KASHMIR'!I37+KPK!I37 -> 0 | J37: =MPR!J37+KARACHI!J37+SINDH!J37+'GILGIT -BALTISTAN'!J37+'AZAD - KASHMIR'!J37+KPK!J37 -> 0 | K37: =MPR!K37+KARACHI!K37+SINDH!K37+'GILGIT -BALTISTAN'!K37+'AZAD - KASHMIR'!K37+KPK!K37 -> 0 | M37: =MPR!M37+KARACHI!M37+SINDH!M37+'GILGIT -BALTISTAN'!M37:M40+'AZAD - KASHMIR'!M37:M40+KPK!M37 -> 1794 | N37: =MPR!N37+KARACHI!N37+SINDH!N37+'GILGIT -BALTISTAN'!N37:N40+'AZAD - KASHMIR'!N37:N40+KPK!N37 -> 1329 | O37: =MPR!O37+KARACHI!O37+SINDH!O37+'GILGIT -BALTISTAN'!O37:O40+'AZAD - KASHMIR'!O37:O40+KPK!O37 -> 858 | P37: =MPR!P37+KARACHI!P37+SINDH!P37+'GILGIT -BALTISTAN'!P37:P40+'AZAD - KASHMIR'!P37:P40+KPK!P37 -> 4238 | Q37: =MPR!Q37+KARACHI!Q37+SINDH!Q37+'GILGIT -BALTISTAN'!Q37:Q40+'AZAD - KASHMIR'!Q37:Q40+KPK!Q37 -> 7 | R37: =MPR!R37+KARACHI!R37+SINDH!R37+'GILGIT -BALTISTAN'!R37:R40+'AZAD - KASHMIR'!R37:R40+KPK!R37 -> 175 | S37: 6H | T37: =MPR!T37+KARACHI!T37+SINDH!T37+'GILGIT -BALTISTAN'!T37+'AZAD - KASHMIR'!T37+KPK!T37 -> 0 | U37: =MPR!U37+KARACHI!U37+SINDH!U37+'GILGIT -BALTISTAN'!U37+'AZAD - KASHMIR'!U37+KPK!U37 -> 0 | V37: =MPR!V37+KARACHI!V37+SINDH!V37+'GILGIT -BALTISTAN'!V37+'AZAD - KASHMIR'!V37+KPK!V37 -> 2 | W37: =MPR!W37+KARACHI!W37+SINDH!W37+'GILGIT -BALTISTAN'!W37+'AZAD - KASHMIR'!W37+KPK!W37 -> 0 | X37: =MPR!X37+KARACHI!X37+SINDH!X37+'GILGIT -BALTISTAN'!X37+'AZAD - KASHMIR'!X37+KPK!X37 -> 0 | Y37: =MPR!Y37+KARACHI!Y37+SINDH!Y37+'GILGIT -BALTISTAN'!Y37+'AZAD - KASHMIR'!Y37+KPK!Y37 -> 0
A38: Relapse | F38: =MPR!F38+KARACHI!F38+SINDH!F38+'GILGIT -BALTISTAN'!F38+'AZAD - KASHMIR'!F38+KPK!F38 -> 37 | G38: =MPR!G38+KARACHI!G38+SINDH!G38+'GILGIT -BALTISTAN'!G38+'AZAD - KASHMIR'!G38+KPK!G38 -> 0 | H38: =MPR!H38+KARACHI!H38+SINDH!H38+'GILGIT -BALTISTAN'!H38+'AZAD - KASHMIR'!H38+KPK!H38 -> 0 | I38: =MPR!I38+KARACHI!I38+SINDH!I38+'GILGIT -BALTISTAN'!I38+'AZAD - KASHMIR'!I38+KPK!I38 -> 0 | J38: =MPR!J38+KARACHI!J38+SINDH!J38+'GILGIT -BALTISTAN'!J38+'AZAD - KASHMIR'!J38+KPK!J38 -> 0 | K38: =MPR!K38+KARACHI!K38+SINDH!K38+'GILGIT -BALTISTAN'!K38+'AZAD - KASHMIR'!K38+KPK!K38 -> 0 | S38: 3HR | T38: =MPR!T38+KARACHI!T38+SINDH!T38+'GILGIT -BALTISTAN'!T38+'AZAD - KASHMIR'!T38+KPK!T38 -> 0 | U38: =MPR!U38+KARACHI!U38+SINDH!U38+'GILGIT -BALTISTAN'!U38+'AZAD - KASHMIR'!U38+KPK!U38 -> 0 | V38: =MPR!V38+KARACHI!V38+SINDH!V38+'GILGIT -BALTISTAN'!V38+'AZAD - KASHMIR'!V38+KPK!V38 -> 0 | W38: =MPR!W38+KARACHI!W38+SINDH!W38+'GILGIT -BALTISTAN'!W38+'AZAD - KASHMIR'!W38+KPK!W38 -> 0 | X38: =MPR!X38+KARACHI!X38+SINDH!X38+'GILGIT -BALTISTAN'!X38+'AZAD - KASHMIR'!X38+KPK!X38 -> 0 | Y38: =MPR!Y38+KARACHI!Y38+SINDH!Y38+'GILGIT -BALTISTAN'!Y38+'AZAD - KASHMIR'!Y38+KPK!Y38 -> 0
A39: Previously treated | F39: =MPR!F39+KARACHI!F39+SINDH!F39+'GILGIT -BALTISTAN'!F39+'AZAD - KASHMIR'!F39+KPK!F39 -> 1 | G39: =MPR!G39+KARACHI!G39+SINDH!G39+'GILGIT -BALTISTAN'!G39+'AZAD - KASHMIR'!G39+KPK!G39 -> 0 | H39: =MPR!H39+KARACHI!H39+SINDH!H39+'GILGIT -BALTISTAN'!H39+'AZAD - KASHMIR'!H39+KPK!H39 -> 0 | I39: =MPR!I39+KARACHI!I39+SINDH!I39+'GILGIT -BALTISTAN'!I39+'AZAD - KASHMIR'!I39+KPK!I39 -> 0 | J39: =MPR!J39+KARACHI!J39+SINDH!J39+'GILGIT -BALTISTAN'!J39+'AZAD - KASHMIR'!J39+KPK!J39 -> 0 | K39: =MPR!K39+KARACHI!K39+SINDH!K39+'GILGIT -BALTISTAN'!K39+'AZAD - KASHMIR'!K39+KPK!K39 -> 0 | S39: 3 HP | T39: =MPR!T39+KARACHI!T39+SINDH!T39+'GILGIT -BALTISTAN'!T39:T40+'AZAD - KASHMIR'!T39:T40+KPK!T39 -> 0 | U39: =MPR!U39+KARACHI!U39+SINDH!U39+'GILGIT -BALTISTAN'!U39:U40+'AZAD - KASHMIR'!U39:U40+KPK!U39 -> 0 | V39: =MPR!V39+KARACHI!V39+SINDH!V39+'GILGIT -BALTISTAN'!V39:V40+'AZAD - KASHMIR'!V39:V40+KPK!V39 -> 0 | W39: =MPR!W39+KARACHI!W39+SINDH!W39+'GILGIT -BALTISTAN'!W39:W40+'AZAD - KASHMIR'!W39:W40+KPK!W39 -> 0 | X39: =MPR!X39+KARACHI!X39+SINDH!X39+'GILGIT -BALTISTAN'!X39:X40+'AZAD - KASHMIR'!X39:X40+KPK!X39 -> 0 | Y39: =MPR!Y39+KARACHI!Y39+SINDH!Y39+'GILGIT -BALTISTAN'!Y39:Y40+'AZAD - KASHMIR'!Y39:Y40+KPK!Y39 -> 0
A40: Total | F40: =SUM(F37:F39) -> 974 | G40: =SUM(G37:G39) -> 5 | H40: =SUM(H37:H39) -> 1 | I40: =SUM(I37:I39) -> 0 | J40: =SUM(J37:J39) -> 0 | K40: =SUM(K37:K39) -> 0
A41: QUARTERLY REPORT ON TB CASES REGISTRATION
A42: INDIVIDUAL/CONSOLIDATED (TICK ONE) | U42: TB - 07
A43: Name of TB Care Facility (BMU) : | E43: =E4 -> All Project Total | H43: District : | J43: =J4 -> 0 | L43: Central : | N43: =N4 -> CONSOLIDATED | Q43: Patients registered during | U43: 2nd Quarter | X43: =X4 -> of Year 2023
A45: Name of TB Coodinator/Facility incharge : | G45: ___________________________________________________ | Q45: Date of completion of this form : | V45: _______________________
A47: Block 1: | J47: New (N) | L47: Relapse ® | N47: Previous Treatment History Unknown (UK) | P47: N+R+UK | R47: Previously treated ( Excluding Relapse) | X47: Total
A48: All TB Cases Registered | R48: Treatment after failure | T48: Treatment after lost to follow-up | V48: Other previously treated
...
